Workbook

Sheet Index
B2: Directive Financial Model
B4: Tab | C4: Summary | N4: Gold text means the values are actuals and should be updated after close
B5: Slides | C5: Slides for Trimester presentation linked to rest of Model | N5: Blue text are inputs
B6: Summary | C6: Full P&L view for Directive and broken out by Product line | N6: Green text links to output from other sheet
B7: % of Revenue | C7: Summary view for trends on areas as a % of revenue | N7: Red texts are manual inputs to override any formula trends
B8: IS Proforma | C8: Detailed P&L view | N8: Black texts are formulas and should not be edited
B9: Headcount | C9: Headcount forecast by role/department with related GL accounts and drivers
B10: Expenses | C10: All other GL expense accounts and drivers
B11: New Biz Sales | C11: Sales Funnel to get towards Bookings
B12: Portfolio Sales | C12: Bookings from Client Services
B13: Retention | C13: Convers Bookings from New Biz and Portfolio into GAAP Revenue less churn from pior months
B14: Revenue | C14: Growth assumptions for each Product and related hourly rate to get capacity hours needed
B15: Capacity | C15: Convert Revenue to capacity hours needed to support growth and when headcount needs are required
B16: Ops Departments | C16: Breakout COGS into Product P&Ls
B17: Opex Departments | C17: Breakout OPEX into Department P&Ls
N18: Summary | Q18: Slides
I22: Headcount
G24: Capacity
B25: New Biz Sales
E26: Retention | I26: Revenue | L26: IS Proforma | O26: Opex Departments | R26: Ops Departments
B27: Portfolio Sales
I30: Expenses
B34: Commentary
B36: Tab | C36: Notes
B37: Slides | C37: Aggregated tab that pulls in relevant data for any Financial Reporting that is weekly or monthly. You should have all your data linked here so that when you make any edits, it's an easy copy/paste to update a PowerPoint slide
B38: Summary | C38: IS Proforma tab into bucketized groups for a simplified P&L view that is exec-friendly for those important expenses areas. You can customize your buckets from Column B and the sumif formula will update. Need to make sure both tabs have the same label for each GL code
B39: % of Revenue | C39: Easiest way for CFO to make sure trends in future periods make sense and follow the overall strategy of the company. Expenses and Revenue should be trending toward a target number by a certain period and allow you to spot any discrepancies if an expense is decreasing over a period and then spikes up in a random year, something is wrong or should be explained
B40: IS Proforma | C40: Drop in actuals from QBO or whatever ERP for current months. This pulls in data from Headcount and Expenses tab to push to Summary tab
B41: Headcount | C41: Brings in incremental headcount adds from Capacity tab and allows you to adjust all headcount related expenses. You can adjust average base salary for all new heads and then forecast any merit increases during the period for the existing employee base. All various benefits are here and you can adjust the % to base for each related GL line item tied to payroll. Commissions and Bonus are also here and can be edited to fit your specific needs or try out various scenarios.
B42: Expenses | C42: All other expenses, so non-headcount sit here. Most should either be tied to headcount or revenue and you can sync them to any specific department
B43: New Biz Sales | C43: This is where the bottoms-up model begins from a forecasting standpoint. You need to build out your Sales Funnel in all it's different stages for the various product lines and establish what the target SQLs are with associated conversion rates to get to Deals Closed and AOV.
B44: Portfolio Sales | C44: If you have a Client Services or Portfolio division, this is where the inputs would go. This can be fairly unique to any organization so could probably use some tweaks to make it more relevant to your org.
B45: Retention | C45: Converts Bookings from New Biz and Portfolio tabs to GAAP Revenue. This tab takes the existing revenue from product lines and churns out revenue from the existing client base and then adds in new revenue from New Biz and Portfolio Bookings that got converted into GAAP Revenue. Churn is a very important metric that needs to properly be accounted for and forecasted to scale a business.
B46: Revenue | C46: Converts Revenue into an hourly rate to be able to understand how many hours are needed to support each service line. Each revenue line item can have it's own unique rate to service that specific deliverable
B47: Capacity | C47: This is where incremental headcount is forecasted for a Just-In-Time-Labor delivery model. You should know how many hours of labor are needed to support forecasted revenue in a Services organization. We've broken out from Specialist->Strategist/Contractor->Associate Director but you could adjust this to fit your specific needs. Also includes various triggers for the other departments whether it's tied to Bookings goals (Sales) or opex triggers for HR or Finance.
... B49: Opex Departments | C49: Drop in actuals from QBO or whatever ERP for current months and then pushes to Slides tab for Financial Reporting
S64: =1740/3 -> 580

Sheet Slides
B4: Paid Media | E4: 44562 | F4: 44593 | G4: 44621 | H4: 44652 | I4: 44682 | J4: 44713 | K4: 44743 | L4: 44774 | M4: 44805 | N4: 44835 | O4: 44866 | P4: 44896 | Q4: 44927 | R4: 44958 | S4: 44986 | T4: 45017 | U4: 45047 | V4: 45078 | W4: 45108 | X4: 45139 | Y4: 45170 | Z4: 45200 | AA4: 45231 | AB4: 45261 | AE4: T3 2022 | AF4: T1 2023 | AG4: Fav/(Unfav) | AH4: % Growth | AL4: T1 2022 | AM4: T2 2022 | AN4: T3 2022 | AO4: T1 2023 | AP4: T2 2023 | AQ4: T3 2023
D6: Recurring | E6: =Revenue!O28 -> 186157 | F6: =Revenue!P28 -> 153018 | G6: =Revenue!Q28 -> 178634 | H6: =Revenue!R28 -> 157636 | I6: =Revenue!S28 -> 223831 | J6: =Revenue!T28 -> 145513 | K6: =Revenue!U28 -> 216724 | L6: =Revenue!V28 -> 221974 | ... AB6: =Revenue!AL28 -> 1145641.8 | AD6: =D6 -> Recurring | AE6: =SUM(M6:P6) -> 895540.14 | AF6: =SUM(Q6:T6) -> 1979499.4 | AG6: =AF6-AE6 -> 1083959.3 | AH6: =AF6/AE6-1 -> 1.2103972 | AK6: Recurring | AL6: =SUM(E6:H6) -> 675445 | AM6: =SUM(I6:L6) -> 808042 | AN6: =SUM(M6:P6) -> 895540.14 | AO6: =SUM(Q6:T6) -> 1979499.4 | AP6: =SUM(U6:X6) -> 3065798.8 | AQ6: =SUM(Y6:AB6) -> 4165284.3
D7: Project | E7: =Revenue!O39 -> 25102 | F7: =Revenue!P39 -> 31006 | G7: =Revenue!Q39 -> 33227 | H7: =Revenue!R39 -> 36474 | I7: =Revenue!S39 -> 38396 | J7: =Revenue!T39 -> 27096 | K7: =Revenue!U39 -> 39103 | L7: =Revenue!V39 -> 37913 | ... AB7: =Revenue!AL39 -> 79987.404 | AD7: =D7 -> Project | AE7: =SUM(M7:P7) -> 161130.45 | AF7: =SUM(Q7:T7) -> 314912.87 | AG7: =AF7-AE7 -> 153782.42 | AH7: =AF7/AE7-1 -> 0.95439703 | AK7: Project | AL7: =SUM(E7:H7) -> 125809 | AM7: =SUM(I7:L7) -> 142508 | AN7: =SUM(M7:P7) -> 161130.45 | AO7: =SUM(Q7:T7) -> 314912.87 | AP7: =SUM(U7:X7) -> 331307.24 | AQ7: =SUM(Y7:AB7) -> 323822.08
D8: Variable | E8: =Revenue!O34 -> 13909 | F8: =Revenue!P34 -> 18960 | G8: =Revenue!Q34 -> 18276 | H8: =Revenue!R34 -> 21600 | I8: =Revenue!S34 -> 13658 | J8: =Revenue!T34 -> 23740 | K8: =Revenue!U34 -> 19142 | L8: =Revenue!V34 -> 10213 | ... AB8: =Revenue!AL34 -> 114564.18 | AD8: Variable | AE8: =SUM(M8:P8) -> 95408.771 | AF8: =SUM(Q8:T8) -> 178154.95 | AG8: =AF8-AE8 -> 82746.177 | AH8: =AF8/AE8-1 -> 0.86728061 | AK8: Variable | AL8: =SUM(E8:H8) -> 72745 | AM8: =SUM(I8:L8) -> 66753 | AN8: =SUM(M8:P8) -> 95408.771 | AO8: =SUM(Q8:T8) -> 178154.95 | AP8: =SUM(U8:X8) -> 306579.88 | AQ8: =SUM(Y8:AB8) -> 416528.43
D9: =CONCATENATE(B4," Revenue") -> Paid Media Revenue | E9: ='Ops Departments'!P8 -> 225168 | F9: ='Ops Departments'!Q8 -> 202984 | G9: ='Ops Departments'!R8 -> 230137 | H9: ='Ops Departments'!S8 -> 215710 | I9: ='Ops Departments'!T8 -> 275885 | J9: ='Ops Departments'!U8 -> 196349 | K9: ='Ops Departments'!V8 -> 274969 | L9: ='Ops Departments'!W8 -> 1046775 | ... AB9: ='Ops Departments'!AM8 -> 1340193.4 | AD9: =D9 -> Paid Media Revenue | AE9: =SUM(M9:P9) -> 3570029 | AF9: =SUM(Q9:T9) -> 2472567.2 | AG9: =AF9-AE9 -> -1097461.8 | AH9: =AF9/AE9-1 -> -0.30740976 | AK9: Paid Media Revenue | AL9: =SUM(E9:H9) -> 873999 | AM9: =SUM(I9:L9) -> 1793978 | AN9: =SUM(M9:P9) -> 3570029 | AO9: =SUM(Q9:T9) -> 2472567.2 | AP9: =SUM(U9:X9) -> 3703685.9 | AQ9: =SUM(Y9:AB9) -> 4905634.8
D10: NNR | E10: ='Ops Departments'!L8-'Ops Departments'!K8 -> 51610 | F10: ='Ops Departments'!M8-'Ops Departments'!L8 -> 27945 | G10: ='Ops Departments'!N8-'Ops Departments'!M8 -> -8146 | H10: ='Ops Departments'!O8-'Ops Departments'!N8 -> -33555 | I10: ='Ops Departments'!P8-'Ops Departments'!O8 -> 23998 | J10: ='Ops Departments'!Q8-'Ops Departments'!P8 -> -22184 | K10: ='Ops Departments'!R8-'Ops Departments'!Q8 -> 27153 | L10: ='Ops Departments'!S8-'Ops Departments'!R8 -> -14427 | ... AB10: ='Ops Departments'!AI8-'Ops Departments'!AH8 -> 74742.444 | AD10: =D10 -> NNR | AE10: =Summary!DE7-Summary!DD7 -> 134776.36 | AF10: =AF9-AE9 -> -1097461.8 | AG10: =AF10-AE10 -> -1232238.1 | AH10: =AF10/AE10-1 -> -9.1428358 | AK10: NNR | AL10: =SUM(E10:H10) -> 37854 | AM10: =AM9-AL9 -> 919979 | AN10: =AN9-AM9 -> 1776051 | AO10: =AO9-AN9 -> -1097461.8 | AP10: =AP9-AO9 -> 1231118.6 | AQ10: =AQ9-AP9 -> 1201948.9
D11: % Growth MoM | E11: =E9/H9-1 -> 0.043845904 | F11: =F9/I9-1 -> -0.26424416 | G11: =G9/J9-1 -> 0.17208134 | H11: =H9/K9-1 -> -0.21551157 | I11: =I9/L9-1 -> -0.73644288 | J11: =J9/M9-1 -> -0.80693927 | K11: =K9/N9-1 -> -0.7326703 | L11: =L9/O9-1 -> -0.048716718 | M11: =M9/P9-1 -> 1.3984442 | N11: =N9/M9-1 -> 0.011350652 | O11: =O9/N9-1 -> 0.069810756 | P11: =P9/O9-1 -> -0.61464441 | Q11: =Q9/P9-1 -> 0.18914133 | R11: =R9/Q9-1 -> 0.15581169 | S11: =S9/R9-1 -> 0.12596085 | T11: =T9/S9-1 -> 0.1113635 | U11: =U9/T9-1 -> 0.11191389 | ... AB11: =AB9/AA9-1 -> 0.061787594 | AD11: % Growth ToT | AE11: =AN9/AM9-1 -> 0.99000712 | AF11: =AF9/AE9-1 -> -0.30740976 | AK11: % Growth ToT | AL11: =SUM(E11:H11) -> -0.26382848 | AM11: =AM9/AL9-1 -> 1.0526088 | AN11: =AN9/AM9-1 -> 0.99000712 | AO11: =AO9/AN9-1 -> -0.30740976 | AP11: =AP9/AO9-1 -> 0.49791108 | AQ11: =AQ9/AP9-1 -> 0.32452777
A13: Paid Media | B13: COGS Payroll | D13: Payroll & Related | E13: =SUMIFS('Ops Departments'!P:P,'Ops Departments'!$B:$B,$B13,'Ops Departments'!$A:$A,$A13) -> 21879 | F13: =SUMIFS('Ops Departments'!Q:Q,'Ops Departments'!$B:$B,$B13,'Ops Departments'!$A:$A,$A13) -> 17920 | G13: =SUMIFS('Ops Departments'!R:R,'Ops Departments'!$B:$B,$B13,'Ops Departments'!$A:$A,$A13) -> 11831 | H13: =SUMIFS('Ops Departments'!S:S,'Ops Departments'!$B:$B,$B13,'Ops Departments'!$A:$A,$A13) -> 22409 | I13: =SUMIFS('Ops Departments'!T:T,'Ops Departments'!$B:$B,$B13,'Ops Departments'!$A:$A,$A13) -> 19981 | J13: =SUMIFS('Ops Departments'!U:U,'Ops Departments'!$B:$B,$B13,'Ops Departments'!$A:$A,$A13) -> 20334 | K13: =SUMIFS('Ops Departments'!V:V,'Ops Departments'!$B:$B,$B13,'Ops Departments'!$A:$A,$A13) -> 21656 | L13: =SUMIFS('Ops Departments'!W:W,'Ops Departments'!$B:$B,$B13,'Ops Departments'!$A:$A,$A13) -> 14938 | M13: =SUMIFS('Ops Departments'!X:X,'Ops Departments'!$B:$B,$B13,'Ops Departments'!$A:$A,$A13) -> 23778 | N13: =SUMIFS('Ops Departments'!Y:Y,'Ops Departments'!$B:$B,$B13,'Ops Departments'!$A:$A,$A13) -> 18989 | O13: =SUMIFS('Ops Departments'!Z:Z,'Ops Departments'!$B:$B,$B13,'Ops Departments'!$A:$A,$A13) -> 24501 | P13: =SUMIFS('Ops Departments'!AA:AA,'Ops Departments'!$B:$B,$B13,'Ops Departments'!$A:$A,$A13) -> 105714.4 | Q13: =SUMIFS('Ops Departments'!AB:AB,'Ops Departments'!$B:$B,$B13,'Ops Departments'!$A:$A,$A13) -> 136168.65 | R13: =SUMIFS('Ops Departments'!AC:AC,'Ops Departments'!$B:$B,$B13,'Ops Departments'!$A:$A,$A13) -> 142933.53 | S13: =SUMIFS('Ops Departments'!AD:AD,'Ops Departments'!$B:$B,$B13,'Ops Departments'!$A:$A,$A13) -> 150188.08 | T13: =SUMIFS('Ops Departments'!AE:AE,'Ops Departments'!$B:$B,$B13,'Ops Departments'!$A:$A,$A13) -> 150650.62 | U13: =SUMIFS('Ops Departments'!AF:AF,'Ops Departments'!$B:$B,$B13,'Ops Departments'!$A:$A,$A13) -> 156590.43 | V13: =SUMIFS('Ops Departments'!AG:AG,'Ops Departments'!$B:$B,$B13,'Ops Departments'!$A:$A,$A13) -> 157253.52 | W13: =SUMIFS('Ops Departments'!AH:AH,'Ops Departments'!$B:$B,$B13,'Ops Departments'!$A:$A,$A13) -> 164225.44 | X13: =SUMIFS('Ops Departments'!AI:AI,'Ops Departments'!$B:$B,$B13,'Ops Departments'!$A:$A,$A13) -> 164934.18 | Y13: =SUMIFS('Ops Departments'!AJ:AJ,'Ops Departments'!$B:$B,$B13,'Ops Departments'!$A:$A,$A13) -> 171098.93 | Z13: =SUMIFS('Ops Departments'!AK:AK,'Ops Departments'!$B:$B,$B13,'Ops Departments'!$A:$A,$A13) -> 171837.83 | AA13: =SUMIFS('Ops Departments'!AL:AL,'Ops Departments'!$B:$B,$B13,'Ops Departments'!$A:$A,$A13) -> 172599.1 | AB13: =SUMIFS('Ops Departments'!AM:AM,'Ops Departments'!$B:$B,$B13,'Ops Departments'!$A:$A,$A13) -> 187106.25 | AD13: =D13 -> Payroll & Related | AE13: =SUM(M13:P13) -> 172982.4 | AF13: =SUM(Q13:T13) -> 579940.89 | AG13: =AE13-AF13 -> -406958.49 | AH13: =AF13/AE13-1 -> 2.3526005 | AK13: Payroll & Related | AL13: =SUM(E13:H13) -> 74039 | AM13: =SUM(I13:L13) -> 76909 | AN13: =SUM(M13:P13) -> 172982.4 | AO13: =SUM(Q13:T13) -> 579940.89 | AP13: =SUM(U13:X13) -> 643003.58 | AQ13: =SUM(Y13:AB13) -> 702642.11
A14: Paid Media | B14: COGS Contractors | D14: Contractors | E14: =SUMIFS('Ops Departments'!P:P,'Ops Departments'!$B:$B,$B14,'Ops Departments'!$A:$A,$A14) -> 3187 | F14: =SUMIFS('Ops Departments'!Q:Q,'Ops Departments'!$B:$B,$B14,'Ops Departments'!$A:$A,$A14) -> 4807 | G14: =SUMIFS('Ops Departments'!R:R,'Ops Departments'!$B:$B,$B14,'Ops Departments'!$A:$A,$A14) -> 2946 | H14: =SUMIFS('Ops Departments'!S:S,'Ops Departments'!$B:$B,$B14,'Ops Departments'!$A:$A,$A14) -> 3197 | I14: =SUMIFS('Ops Departments'!T:T,'Ops Departments'!$B:$B,$B14,'Ops Departments'!$A:$A,$A14) -> 2908 | J14: =SUMIFS('Ops Departments'!U:U,'Ops Departments'!$B:$B,$B14,'Ops Departments'!$A:$A,$A14) -> 2933 | K14: =SUMIFS('Ops Departments'!V:V,'Ops Departments'!$B:$B,$B14,'Ops Departments'!$A:$A,$A14) -> 4086 | L14: =SUMIFS('Ops Departments'!W:W,'Ops Departments'!$B:$B,$B14,'Ops Departments'!$A:$A,$A14) -> 3199 | M14: =SUMIFS('Ops Departments'!X:X,'Ops Departments'!$B:$B,$B14,'Ops Departments'!$A:$A,$A14) -> 4864 | N14: =SUMIFS('Ops Departments'!Y:Y,'Ops Departments'!$B:$B,$B14,'Ops Departments'!$A:$A,$A14) -> 1247 | O14: =SUMIFS('Ops Departments'!Z:Z,'Ops Departments'!$B:$B,$B14,'Ops Departments'!$A:$A,$A14) -> 3570 | P14: =SUMIFS('Ops Departments'!AA:AA,'Ops Departments'!$B:$B,$B14,'Ops Departments'!$A:$A,$A14) -> 799.22016 | Q14: =SUMIFS('Ops Departments'!AB:AB,'Ops Departments'!$B:$B,$B14,'Ops Departments'!$A:$A,$A14) -> 647.11552 | R14: =SUMIFS('Ops Departments'!AC:AC,'Ops Departments'!$B:$B,$B14,'Ops Departments'!$A:$A,$A14) -> 748.81677 | S14: =SUMIFS('Ops Departments'!AD:AD,'Ops Departments'!$B:$B,$B14,'Ops Departments'!$A:$A,$A14) -> 846.05152 | T14: =SUMIFS('Ops Departments'!AE:AE,'Ops Departments'!$B:$B,$B14,'Ops Departments'!$A:$A,$A14) -> 943.20323 | U14: =SUMIFS('Ops Departments'!AF:AF,'Ops Departments'!$B:$B,$B14,'Ops Departments'!$A:$A,$A14) -> 1614.1461 | V14: =SUMIFS('Ops Departments'!AG:AG,'Ops Departments'!$B:$B,$B14,'Ops Departments'!$A:$A,$A14) -> 1772.9015 | W14: =SUMIFS('Ops Departments'!AH:AH,'Ops Departments'!$B:$B,$B14,'Ops Departments'!$A:$A,$A14) -> 1927.5476 | X14: =SUMIFS('Ops Departments'!AI:AI,'Ops Departments'!$B:$B,$B14,'Ops Departments'!$A:$A,$A14) -> 2080.4128 | Y14: =SUMIFS('Ops Departments'!AJ:AJ,'Ops Departments'!$B:$B,$B14,'Ops Departments'!$A:$A,$A14) -> 2237.449 | Z14: =SUMIFS('Ops Departments'!AK:AK,'Ops Departments'!$B:$B,$B14,'Ops Departments'!$A:$A,$A14) -> 2384.3803 | AA14: =SUMIFS('Ops Departments'!AL:AL,'Ops Departments'!$B:$B,$B14,'Ops Departments'!$A:$A,$A14) -> 2538.1183 | AB14: =SUMIFS('Ops Departments'!AM:AM,'Ops Departments'!$B:$B,$B14,'Ops Departments'!$A:$A,$A14) -> 2697.6752 | AD14: =D14 -> Contractors | AE14: =SUM(M14:P14) -> 10480.22 | AF14: =SUM(Q14:T14) -> 3185.187 | AG14: =AE14-AF14 -> 7295.0331 | AH14: =AF14/AE14-1 -> -0.69607632 | AK14: Contractors | AL14: =SUM(E14:H14) -> 14137 | AM14: =SUM(I14:L14) -> 13126 | AN14: =SUM(M14:P14) -> 10480.22 | AO14: =SUM(Q14:T14) -> 3185.187 | AP14: =SUM(U14:X14) -> 7395.0081 | AQ14: =SUM(Y14:AB14) -> 9857.6228
A15: Paid Media | B15: COGS Travel | D15: T&E | E15: =SUMIFS('Ops Departments'!P:P,'Ops Departments'!$B:$B,$B15,'Ops Departments'!$A:$A,$A15) -> 9828 | F15: =SUMIFS('Ops Departments'!Q:Q,'Ops Departments'!$B:$B,$B15,'Ops Departments'!$A:$A,$A15) -> 7932 | G15: =SUMIFS('Ops Departments'!R:R,'Ops Departments'!$B:$B,$B15,'Ops Departments'!$A:$A,$A15) -> 5824 | H15: =SUMIFS('Ops Departments'!S:S,'Ops Departments'!$B:$B,$B15,'Ops Departments'!$A:$A,$A15) -> 4180 | I15: =SUMIFS('Ops Departments'!T:T,'Ops Departments'!$B:$B,$B15,'Ops Departments'!$A:$A,$A15) -> 4970 | J15: =SUMIFS('Ops Departments'!U:U,'Ops Departments'!$B:$B,$B15,'Ops Departments'!$A:$A,$A15) -> 8210 | K15: =SUMIFS('Ops Departments'!V:V,'Ops Departments'!$B:$B,$B15,'Ops Departments'!$A:$A,$A15) -> 9606 | L15: =SUMIFS('Ops Departments'!W:W,'Ops Departments'!$B:$B,$B15,'Ops Departments'!$A:$A,$A15) -> 10376 | M15: =SUMIFS('Ops Departments'!X:X,'Ops Departments'!$B:$B,$B15,'Ops Departments'!$A:$A,$A15) -> 4041 | N15: =SUMIFS('Ops Departments'!Y:Y,'Ops Departments'!$B:$B,$B15,'Ops Departments'!$A:$A,$A15) -> 8507 | O15: =SUMIFS('Ops Departments'!Z:Z,'Ops Departments'!$B:$B,$B15,'Ops Departments'!$A:$A,$A15) -> 6169 | P15: =SUMIFS('Ops Departments'!AA:AA,'Ops Departments'!$B:$B,$B15,'Ops Departments'!$A:$A,$A15) -> 6274.014 | Q15: =SUMIFS('Ops Departments'!AB:AB,'Ops Departments'!$B:$B,$B15,'Ops Departments'!$A:$A,$A15) -> 6901.4154 | R15: =SUMIFS('Ops Departments'!AC:AC,'Ops Departments'!$B:$B,$B15,'Ops Departments'!$A:$A,$A15) -> 6970.4296 | S15: =SUMIFS('Ops Departments'!AD:AD,'Ops Departments'!$B:$B,$B15,'Ops Departments'!$A:$A,$A15) -> 7040.1339 | T15: =SUMIFS('Ops Departments'!AE:AE,'Ops Departments'!$B:$B,$B15,'Ops Departments'!$A:$A,$A15) -> 7110.5352 | U15: =SUMIFS('Ops Departments'!AF:AF,'Ops Departments'!$B:$B,$B15,'Ops Departments'!$A:$A,$A15) -> 7181.6405 | V15: =SUMIFS('Ops Departments'!AG:AG,'Ops Departments'!$B:$B,$B15,'Ops Departments'!$A:$A,$A15) -> 7253.4569 | W15: =SUMIFS('Ops Departments'!AH:AH,'Ops Departments'!$B:$B,$B15,'Ops Departments'!$A:$A,$A15) -> 7325.9915 | X15: =SUMIFS('Ops Departments'!AI:AI,'Ops Departments'!$B:$B,$B15,'Ops Departments'!$A:$A,$A15) -> 7399.2514 | Y15: =SUMIFS('Ops Departments'!AJ:AJ,'Ops Departments'!$B:$B,$B15,'Ops Departments'!$A:$A,$A15) -> 7473.2439 | Z15: =SUMIFS('Ops Departments'!AK:AK,'Ops Departments'!$B:$B,$B15,'Ops Departments'!$A:$A,$A15) -> 7547.9764 | AA15: =SUMIFS('Ops Departments'!AL:AL,'Ops Departments'!$B:$B,$B15,'Ops Departments'!$A:$A,$A15) -> 7623.4561 | AB15: =SUMIFS('Ops Departments'!AM:AM,'Ops Departments'!$B:$B,$B15,'Ops Departments'!$A:$A,$A15) -> 7699.6907 | AD15: =D15 -> T&E | AE15: =SUM(M15:P15) -> 24991.014 | AF15: =SUM(Q15:T15) -> 28022.514 | AG15: =AE15-AF15 -> -3031.5 | AH15: =AF15/AE15-1 -> 0.1213036 | AK15: T&E | AL15: =SUM(E15:H15) -> 27764 | AM15: =SUM(I15:L15) -> 33162 | AN15: =SUM(M15:P15) -> 24991.014 | AO15: =SUM(Q15:T15) -> 28022.514 | AP15: =SUM(U15:X15) -> 29160.34 | AQ15: =SUM(Y15:AB15) -> 30344.367
A16: Paid Media | B16: COGS Software | D16: Software | E16: =SUMIFS('Ops Departments'!P:P,'Ops Departments'!$B:$B,$B16,'Ops Departments'!$A:$A,$A16) -> 2355 | F16: =SUMIFS('Ops Departments'!Q:Q,'Ops Departments'!$B:$B,$B16,'Ops Departments'!$A:$A,$A16) -> 1746 | G16: =SUMIFS('Ops Departments'!R:R,'Ops Departments'!$B:$B,$B16,'Ops Departments'!$A:$A,$A16) -> 1810 | H16: =SUMIFS('Ops Departments'!S:S,'Ops Departments'!$B:$B,$B16,'Ops Departments'!$A:$A,$A16) -> 715 | I16: =SUMIFS('Ops Departments'!T:T,'Ops Departments'!$B:$B,$B16,'Ops Departments'!$A:$A,$A16) -> 4215 | J16: =SUMIFS('Ops Departments'!U:U,'Ops Departments'!$B:$B,$B16,'Ops Departments'!$A:$A,$A16) -> 3449 | K16: =SUMIFS('Ops Departments'!V:V,'Ops Departments'!$B:$B,$B16,'Ops Departments'!$A:$A,$A16) -> 1835 | L16: =SUMIFS('Ops Departments'!W:W,'Ops Departments'!$B:$B,$B16,'Ops Departments'!$A:$A,$A16) -> 1693 | M16: =SUMIFS('Ops Departments'!X:X,'Ops Departments'!$B:$B,$B16,'Ops Departments'!$A:$A,$A16) -> 2494 | N16: =SUMIFS('Ops Departments'!Y:Y,'Ops Departments'!$B:$B,$B16,'Ops Departments'!$A:$A,$A16) -> 3890 | O16: =SUMIFS('Ops Departments'!Z:Z,'Ops Departments'!$B:$B,$B16,'Ops Departments'!$A:$A,$A16) -> 2906 | P16: =SUMIFS('Ops Departments'!AA:AA,'Ops Departments'!$B:$B,$B16,'Ops Departments'!$A:$A,$A16) -> 631.864 | Q16: =SUMIFS('Ops Departments'!AB:AB,'Ops Departments'!$B:$B,$B16,'Ops Departments'!$A:$A,$A16) -> 1391.864 | R16: =SUMIFS('Ops Departments'!AC:AC,'Ops Departments'!$B:$B,$B16,'Ops Departments'!$A:$A,$A16) -> 1391.864 | S16: =SUMIFS('Ops Departments'!AD:AD,'Ops Departments'!$B:$B,$B16,'Ops Departments'!$A:$A,$A16) -> 1391.864 | T16: =SUMIFS('Ops Departments'!AE:AE,'Ops Departments'!$B:$B,$B16,'Ops Departments'!$A:$A,$A16) -> 1391.864 | U16: =SUMIFS('Ops Departments'!AF:AF,'Ops Departments'!$B:$B,$B16,'Ops Departments'!$A:$A,$A16) -> 2151.864 | V16: =SUMIFS('Ops Departments'!AG:AG,'Ops Departments'!$B:$B,$B16,'Ops Departments'!$A:$A,$A16) -> 2151.864 | W16: =SUMIFS('Ops Departments'!AH:AH,'Ops Departments'!$B:$B,$B16,'Ops Departments'!$A:$A,$A16) -> 2151.864 | X16: =SUMIFS('Ops Departments'!AI:AI,'Ops Departments'!$B:$B,$B16,'Ops Departments'!$A:$A,$A16) -> 2151.864 | Y16: =SUMIFS('Ops Departments'!AJ:AJ,'Ops Departments'!$B:$B,$B16,'Ops Departments'!$A:$A,$A16) -> 2911.864 | Z16: =SUMIFS('Ops Departments'!AK:AK,'Ops Departments'!$B:$B,$B16,'Ops Departments'!$A:$A,$A16) -> 2911.864 | AA16: =SUMIFS('Ops Departments'!AL:AL,'Ops Departments'!$B:$B,$B16,'Ops Departments'!$A:$A,$A16) -> 2911.864 | AB16: =SUMIFS('Ops Departments'!AM:AM,'Ops Departments'!$B:$B,$B16,'Ops Departments'!$A:$A,$A16) -> 2911.864 | AD16: =D16 -> Software | AE16: =SUM(M16:P16) -> 9921.864 | AF16: =SUM(Q16:T16) -> 5567.456 | AG16: =AE16-AF16 -> 4354.408 | AH16: =AF16/AE16-1 -> -0.43886995 | AK16: Software | AL16: =SUM(E16:H16) -> 6626 | AM16: =SUM(I16:L16) -> 11192 | AN16: =SUM(M16:P16) -> 9921.864 | AO16: =SUM(Q16:T16) -> 5567.456 | AP16: =SUM(U16:X16) -> 8607.456 | AQ16: =SUM(Y16:AB16) -> 11647.456
A17: Paid Media | B17: COGS Other | D17: Other | E17: =SUMIFS('Ops Departments'!P:P,'Ops Departments'!$B:$B,$B17,'Ops Departments'!$A:$A,$A17) -> 0 | F17: =SUMIFS('Ops Departments'!Q:Q,'Ops Departments'!$B:$B,$B17,'Ops Departments'!$A:$A,$A17) -> 0 | G17: =SUMIFS('Ops Departments'!R:R,'Ops Departments'!$B:$B,$B17,'Ops Departments'!$A:$A,$A17) -> 0 | H17: =SUMIFS('Ops Departments'!S:S,'Ops Departments'!$B:$B,$B17,'Ops Departments'!$A:$A,$A17) -> 0 | I17: =SUMIFS('Ops Departments'!T:T,'Ops Departments'!$B:$B,$B17,'Ops Departments'!$A:$A,$A17) -> 0 | J17: =SUMIFS('Ops Departments'!U:U,'Ops Departments'!$B:$B,$B17,'Ops Departments'!$A:$A,$A17) -> 0 | K17: =SUMIFS('Ops Departments'!V:V,'Ops Departments'!$B:$B,$B17,'Ops Departments'!$A:$A,$A17) -> 0 | L17: =SUMIFS('Ops Departments'!W:W,'Ops Departments'!$B:$B,$B17,'Ops Departments'!$A:$A,$A17) -> 0 | M17: =SUMIFS('Ops Departments'!X:X,'Ops Departments'!$B:$B,$B17,'Ops Departments'!$A:$A,$A17) -> 0 | N17: =SUMIFS('Ops Departments'!Y:Y,'Ops Departments'!$B:$B,$B17,'Ops Departments'!$A:$A,$A17) -> 0 | O17: =SUMIFS('Ops Departments'!Z:Z,'Ops Departments'!$B:$B,$B17,'Ops Departments'!$A:$A,$A17) -> 0 | P17: =SUMIFS('Ops Departments'!AA:AA,'Ops Departments'!$B:$B,$B17,'Ops Departments'!$A:$A,$A17) -> 0 | Q17: =SUMIFS('Ops Departments'!AB:AB,'Ops Departments'!$B:$B,$B17,'Ops Departments'!$A:$A,$A17) -> 0 | R17: =SUMIFS('Ops Departments'!AC:AC,'Ops Departments'!$B:$B,$B17,'Ops Departments'!$A:$A,$A17) -> 0 | S17: =SUMIFS('Ops Departments'!AD:AD,'Ops Departments'!$B:$B,$B17,'Ops Departments'!$A:$A,$A17) -> 0 | T17: =SUMIFS('Ops Departments'!AE:AE,'Ops Departments'!$B:$B,$B17,'Ops Departments'!$A:$A,$A17) -> 0 | U17: =SUMIFS('Ops Departments'!AF:AF,'Ops Departments'!$B:$B,$B17,'Ops Departments'!$A:$A,$A17) -> 0 | V17: =SUMIFS('Ops Departments'!AG:AG,'Ops Departments'!$B:$B,$B17,'Ops Departments'!$A:$A,$A17) -> 0 | W17: =SUMIFS('Ops Departments'!AH:AH,'Ops Departments'!$B:$B,$B17,'Ops Departments'!$A:$A,$A17) -> 0 | X17: =SUMIFS('Ops Departments'!AI:AI,'Ops Departments'!$B:$B,$B17,'Ops Departments'!$A:$A,$A17) -> 0 | Y17: =SUMIFS('Ops Departments'!AJ:AJ,'Ops Departments'!$B:$B,$B17,'Ops Departments'!$A:$A,$A17) -> 0 | Z17: =SUMIFS('Ops Departments'!AK:AK,'Ops Departments'!$B:$B,$B17,'Ops Departments'!$A:$A,$A17) -> 0 | AA17: =SUMIFS('Ops Departments'!AL:AL,'Ops Departments'!$B:$B,$B17,'Ops Departments'!$A:$A,$A17) -> 0 | AB17: =SUMIFS('Ops Departments'!AM:AM,'Ops Departments'!$B:$B,$B17,'Ops Departments'!$A:$A,$A17) -> 0 | AD17: =D17 -> Other | AE17: =SUM(M17:P17) -> 0 | AF17: =SUM(Q17:T17) -> 0 | AG17: =AE17-AF17 -> 0 | AH17: =AF17/AE17-1 -> #DIV/0! | AK17: Other | AL17: =SUM(E17:H17) -> 0 | AM17: =SUM(I17:L17) -> 0 | AN17: =SUM(M17:P17) -> 0 | AO17: =SUM(Q17:T17) -> 0 | AP17: =SUM(U17:X17) -> 0 | AQ17: =SUM(Y17:AB17) -> 0
D18: Total COGS | E18: =SUM(E13:E17) -> 37249 | F18: =SUM(F13:F17) -> 32405 | G18: =SUM(G13:G17) -> 22411 | H18: =SUM(H13:H17) -> 30501 | I18: =SUM(I13:I17) -> 32074 | J18: =SUM(J13:J17) -> 34926 | K18: =SUM(K13:K17) -> 37183 | L18: =SUM(L13:L17) -> 30206 | ... AB18: =SUM(AB13:AB17) -> 200415.48 | AD18: =D18 -> Total COGS | AE18: =SUM(M18:P18) -> 218375.5 | AF18: =SUM(Q18:T18) -> 616716.05 | AG18: =AE18-AF18 -> -398340.55 | AH18: =AF18/AE18-1 -> 1.8241082 | AK18: Total COGS | AL18: =SUM(E18:H18) -> 122566 | AM18: =SUM(I18:L18) -> 134389 | AN18: =SUM(M18:P18) -> 218375.5 | AO18: =SUM(Q18:T18) -> 616716.05 | AP18: =SUM(U18:X18) -> 688166.38 | AQ18: =SUM(Y18:AB18) -> 754491.56
D20: =CONCATENATE(B4," Gross Profit") -> Paid Media Gross Profit | E20: =E9-E18 -> 187919 | F20: =F9-F18 -> 170579 | G20: =G9-G18 -> 207726 | H20: =H9-H18 -> 185209 | I20: =I9-I18 -> 243811 | J20: =J9-J18 -> 161423 | K20: =K9-K18 -> 237786 | L20: =L9-L18 -> 1016569 | ... AB20: =AB9-AB18 -> 1139777.9 | AD20: =D20 -> Paid Media Gross Profit | AE20: =AE9-AE18 -> 3351653.5 | AF20: =AF9-AF18 -> 1855851.2 | AG20: =AF20-AE20 -> -1495802.3 | AH20: =AF20/AE20-1 -> -0.44628787 | AK20: Paid Media Gross Profit | AL20: =SUM(E20:H20) -> 751433 | AM20: =SUM(I20:L20) -> 1659589 | AN20: =SUM(M20:P20) -> 3351653.5 | AO20: =SUM(Q20:T20) -> 1855851.2 | AP20: =SUM(U20:X20) -> 3015519.5 | AQ20: =SUM(Y20:AB20) -> 4151143.3
D21: Gross Margin | E21: =E20/E9 -> 0.83457241 | F21: =F20/F9 -> 0.84035688 | G21: =G20/G9 -> 0.90261887 | H21: =H20/H9 -> 0.85860183 | I21: =I20/I9 -> 0.88374141 | J21: =J20/J9 -> 0.82212285 | K21: =K20/K9 -> 0.86477385 | L21: =L20/L9 -> 0.97114375 | ... AB21: =AB20/AB9 -> 0.85045779 | AD21: =D21 -> Gross Margin | AE21: =AE20/AE9 -> 0.93883089 | AF21: =AF20/AF9 -> 0.75057663 | AG21: =AF21-AE21 -> -0.18825426 | AK21: Gross Margin | AL21: =AL20/AL9 -> 0.85976414 | AM21: =AM20/AM9 -> 0.92508882 | AN21: =AN20/AN9 -> 0.93883089 | AO21: =AO20/AO9 -> 0.75057663 | AP21: =AP20/AP9 -> 0.81419418 | AQ21: =AQ20/AQ9 -> 0.846199
D23: Headcount | E23: =Headcount!H10 -> 20 | F23: =Headcount!I10 -> 20 | G23: =Headcount!J10 -> 20 | H23: =Headcount!K10 -> 20 | I23: =Headcount!L10 -> 20 | J23: =Headcount!M10 -> 20 | K23: =Headcount!N10 -> 20 | L23: =Headcount!O10 -> 20 | M23: =Headcount!P10 -> 20 | N23: =Headcount!Q10+Headcount!Q11 -> 40 | O23: =Headcount!R10+Headcount!R11 -> 40 | P23: =Headcount!S10+Headcount!S11 -> 48 | Q23: =Headcount!T10+Headcount!T11 -> 51 | R23: =Headcount!U10+Headcount!U11 -> 52 | S23: =Headcount!V10+Headcount!V11 -> 53 | T23: =Headcount!W10+Headcount!W11 -> 53 | U23: =Headcount!X10+Headcount!X11 -> 53 | ... AB23: =Headcount!AE10+Headcount!AE11 -> 54 | AD23: =D23 -> Headcount | AE23: =P23 -> 48 | AF23: =T23 -> 53 | AG23: =AF23-AE23 -> 5 | AH23: =AF23/AE23-1 -> 0.10416667 | AK23: Headcount | AL23: =H23 -> 20 | AM23: =L23 -> 20 | AN23: =P23 -> 48 | AO23: =T23 -> 53 | AP23: =X23 -> 53 | AQ23: =AB23 -> 54
D24: Revenue/Strategist | E24: =E9/Capacity!O34 -> 11258.4 | F24: =F9/Capacity!P34 -> 10149.2 | G24: =G9/Capacity!Q34 -> 11506.85 | H24: =H9/Capacity!R34 -> 10785.5 | I24: =I9/Capacity!S34 -> 13794.25 | J24: =J9/Capacity!T34 -> 9817.45 | K24: =K9/Capacity!U34 -> 13748.45 | L24: =L9/Capacity!V34 -> 52338.75 | ... AB24: =AB9/Capacity!AL34 -> 58269.278 | AD24: =D24 -> Revenue/Strategist | AE24: =AVERAGE(M24:P24) -> 44372.959 | AF24: =AVERAGE(Q24:T24) -> 28097.355 | AG24: =AF24-AE24 -> -16275.604 | AH24: =AF24/AE24-1 -> -0.36679104 | AK24: Revenue/Strategist | AL24: =AVERAGE(E24:H24) -> 10924.987 | AM24: =AVERAGE(I24:L24) -> 22424.725 | AN24: =AVERAGE(M24:P24) -> 44372.959 | AO24: =AVERAGE(Q24:T24) -> 28097.355 | AP24: =AVERAGE(U24:X24) -> 42087.34 | AQ24: =AVERAGE(Y24:AB24) -> 55083.699
D25: # of Product Opportunities | E25: =SUM('New Biz Sales'!O39) -> 30 | F25: =SUM('New Biz Sales'!P39) -> 30 | G25: =SUM('New Biz Sales'!Q39) -> 30 | H25: =SUM('New Biz Sales'!R39) -> 30 | I25: =SUM('New Biz Sales'!S39) -> 30 | J25: =SUM('New Biz Sales'!T39) -> 30 | K25: =SUM('New Biz Sales'!U39) -> 30 | L25: =SUM('New Biz Sales'!V39) -> 30 | ... AB25: =SUM('New Biz Sales'!AL39) -> 22.28688 | AD25: =D25 -> # of Product Opportunities | AE25: =SUM(M25:P25) -> 123 | AF25: =SUM(Q25:T25) -> 132 | AG25: =AF25-AE25 -> 9 | AH25: =AF25/AE25-1 -> 0.073170732 | AK25: # of Product Opportunities | AL25: =SUM(E25:H25) -> 120 | AM25: =SUM(I25:L25) -> 120 | AN25: =SUM(M25:P25) -> 123 | AO25: =SUM(Q25:T25) -> 132 | AP25: =SUM(U25:X25) -> 130.68 | AQ25: =SUM(Y25:AB25) -> 117.48528
D26: Product Deals Closed | E26: ='New Biz Sales'!O88+'Portfolio Sales'!E81 -> 6 | F26: ='New Biz Sales'!P88+'Portfolio Sales'!F81 -> 6 | G26: ='New Biz Sales'!Q88+'Portfolio Sales'!G81 -> 8 | H26: ='New Biz Sales'!R88+'Portfolio Sales'!H81 -> 9 | I26: ='New Biz Sales'!S88+'Portfolio Sales'!I81 -> 8 | J26: ='New Biz Sales'!T88+'Portfolio Sales'!J81 -> 7 | K26: ='New Biz Sales'!U88+'Portfolio Sales'!K81 -> 8 | L26: ='New Biz Sales'!V88+'Portfolio Sales'!L81 -> 13 | ... AB26: ='New Biz Sales'!AL88+'Portfolio Sales'!AB81 -> 8.5718376 | AD26: =D26 -> Product Deals Closed | AE26: =SUM(M26:P26) -> 28.38979 | AF26: =SUM(Q26:T26) -> 28.229798 | AG26: =AF26-AE26 -> -0.15999263 | AH26: =AF26/AE26-1 -> -0.0056355692 | AK26: Product Deals Closed | AL26: =SUM(E26:H26) -> 29 | AM26: =SUM(I26:L26) -> 36 | AN26: =SUM(M26:P26) -> 28.38979 | AO26: =SUM(Q26:T26) -> 28.229798 | AP26: =SUM(U26:X26) -> 32.349158 | AQ26: =SUM(Y26:AB26) -> 33.638768
D27: New Client AOV | E27: ='New Biz Sales'!O96 -> 479498 | F27: ='New Biz Sales'!P96 -> 206807 | G27: ='New Biz Sales'!Q96 -> 328227 | H27: ='New Biz Sales'!R96 -> 439553 | I27: ='New Biz Sales'!S96 -> 149004 | J27: ='New Biz Sales'!T96 -> 298345 | K27: ='New Biz Sales'!U96 -> 108101 | L27: ='New Biz Sales'!V96 -> 262590 | ... AB27: ='New Biz Sales'!AL96 -> 171666 | AD27: =D27 -> New Client AOV | AE27: =IFERROR(__xludf.DUMMYFUNCTION("AVERAGE.WEIGHTED(M28:P28,M27:P27)"),0.9739712089332521) -> 0.97397121 | AF27: =IFERROR(__xludf.DUMMYFUNCTION("AVERAGE.WEIGHTED(Q28:T28,Q27:T27)"),0.9435440261092015) -> 0.94354403 | AG27: =AF27-AE27 -> -0.030427183 | AH27: =AF27/AE27-1 -> -0.031240331 | AK27: New Client AOV | AL27: =AVERAGE(E27:H27) -> 363521.25 | AM27: =AVERAGE(I27:L27) -> 204510 | AN27: =AVERAGE(M27:P27) -> 382222.75 | AO27: =AVERAGE(Q27:T27) -> 168300 | AP27: =AVERAGE(U27:X27) -> 170824.5 | AQ27: =AVERAGE(Y27:AB27) -> 171666
D28: TTM Retention Rate | E28: =1--SUM(Retention!O77)/AVERAGE(Retention!O40) -> 0.98427396 | F28: =1--SUM(Retention!P77)/AVERAGE(Retention!P40) -> 0.98909274 | G28: =1--SUM(Retention!Q77)/AVERAGE(Retention!Q40) -> 0.97412845 | H28: =1--SUM(Retention!R77)/AVERAGE(Retention!R40) -> 0.96470261 | I28: =1--SUM(Retention!S77)/AVERAGE(Retention!S40) -> 0.99574098 | J28: =1--SUM(Retention!T77)/AVERAGE(Retention!T40) -> 0.99592562 | K28: =1--SUM(Retention!U77)/AVERAGE(Retention!U40) -> 0.988726 | L28: =1--SUM(Retention!V77)/AVERAGE(Retention!V40) -> 0.97087375 | ... AB28: =1--SUM(Retention!AL77)/AVERAGE(Retention!AL40) -> 0.96313409 | AD28: Monthly Retention Rate | AE28: =P28 -> 0.94264058 | AF28: =T28 -> 0.94595367 | AG28: =AF28-AE28 -> 0.0033130929 | AH28: =AF28/AE28-1 -> 0.0035146936 | AK28: Average Monthly Retention | AL28: =AVERAGE(E28:H28) -> 0.97804944 | AM28: =AVERAGE(I28:L28) -> 0.98781659 | AN28: =AVERAGE(M28:P28) -> 0.9688024 | AO28: =AVERAGE(Q28:T28) -> 0.94354403 | AP28: =AVERAGE(U28:X28) -> 0.95078705 | AQ28: =AVERAGE(Y28:AB28) -> 0.95955605
D29: New Client LTV | E29: =Retention!O167 -> 35052.041 | F29: =Retention!P167 -> 53208.596 | G29: =Retention!Q167 -> 120258.92 | H29: =Retention!R167 -> 31610.857 | I29: =Retention!S167 -> 80155.346 | J29: =Retention!T167 -> 107218.52 | K29: =Retention!U167 -> 132483.35 | L29: =Retention!V167 -> 144538.56 | ... AB29: =Retention!AL167 -> 285759.81 | AD29: =D29 -> New Client LTV | AE29: =((AE27/12)*AE21)/(1-AE28) -> 1.3284569 | AF29: =((AF27/12)*AF21)/(1-AF28) -> 1.0919676 | AG29: =AF29-AE29 -> -0.23648931 | AH29: =AF29/AE29-1 -> -0.17801804 | AK29: New Client LTV | AL29: =AVERAGE(F29:H29) -> 68359.458 | AM29: =AVERAGE(I29:L29) -> 116098.95 | AN29: =AVERAGE(M29:P29) -> 121645.43 | AO29: =AVERAGE(Q29:T29) -> 149490.19 | AP29: =AVERAGE(U29:X29) -> 198171.22 | AQ29: =AVERAGE(Y29:AB29) -> 259026.06
D32: Check | M32: =M20-'Ops Departments'!X29 -> 0 | N32: =N20-'Ops Departments'!Y29 -> 0 | O32: =O20-'Ops Departments'!Z29 -> 0 | P32: =P20-'Ops Departments'!AA29 -> 0 | Q32: =Q20-'Ops Departments'!AB29 -> 0 | R32: =R20-'Ops Departments'!AC29 -> 0 | S32: =S20-'Ops Departments'!AD29 -> 0 | T32: =T20-'Ops Departments'!AE29 -> 0 | ... AB32: =AB20-'Ops Departments'!AM29 -> 0
B34: SEO | E34: 44562 | F34: 44593 | G34: 44621 | H34: 44652 | I34: 44682 | J34: 44713 | K34: 44743 | L34: 44774 | M34: 44805 | N34: 44835 | O34: 44866 | P34: 44896 | Q34: 44927 | R34: 44958 | S34: 44986 | T34: 45017 | U34: 45047 | V34: 45078 | W34: 45108 | X34: 45139 | Y34: 45170 | Z34: 45200 | AA34: 45231 | AB34: 45261 | AE34: T3 2022 | AF34: T1 2023 | AG34: Fav/(Unfav) | AH34: % Growth | AL34: T1 2022 | AM34: T2 2022 | AN34: T3 2022 | AO34: T1 2023 | AP34: T2 2023 | AQ34: T3 2023
D36: Recurring | E36: =Revenue!O60 -> 204056 | F36: =Revenue!P60 -> 188586 | G36: =Revenue!Q60 -> 105100 | H36: =Revenue!R60 -> 150167 | I36: =Revenue!S60 -> 139600 | J36: =Revenue!T60 -> 150378 | K36: =Revenue!U60 -> 103141 | L36: =Revenue!V60 -> 237175 | ... AB36: =Revenue!AL60 -> 870122.79 | AD36: =D36 -> Recurring | AE36: =SUM(M36:P36) -> 753863.35 | AF36: =SUM(Q36:T36) -> 1465423.3 | AG36: =AF36-AE36 -> 711559.91 | AH36: =AF36/AE36-1 -> 0.94388447 | AL36: =SUM(E36:H36) -> 647909 | AM36: =SUM(I36:L36) -> 630294 | AN36: =SUM(M36:P36) -> 753863.35 | AO36: =SUM(Q36:T36) -> 1465423.3 | AP36: =SUM(U36:X36) -> 2392605.3 | AQ36: =SUM(Y36:AB36) -> 3200057
D37: Project | E37: =Revenue!O66 -> 27285 | F37: =Revenue!P66 -> 31191 | G37: =Revenue!Q66 -> 35431 | H37: =Revenue!R66 -> 22355 | I37: =Revenue!S66 -> 28353 | J37: =Revenue!T66 -> 33063 | K37: =Revenue!U66 -> 25401 | L37: =Revenue!V66 -> 23793 | ... AB37: =Revenue!AL66 -> 59967.523 | AD37: =D37 -> Project | AE37: =SUM(M37:P37) -> 148400.55 | AF37: =SUM(Q37:T37) -> 238884.58 | AG37: =AF37-AE37 -> 90484.028 | AH37: =AF37/AE37-1 -> 0.60972839 | AL37: =SUM(E37:H37) -> 116262 | AM37: =SUM(I37:L37) -> 110610 | AN37: =SUM(M37:P37) -> 148400.55 | AO37: =SUM(Q37:T37) -> 238884.58 | AP37: =SUM(U37:X37) -> 250990.49 | AQ37: =SUM(Y37:AB37) -> 243537.38
D38: =CONCATENATE(B34," Revenue") -> SEO Revenue | E38: ='Ops Departments'!P40 -> 231341 | F38: ='Ops Departments'!Q40 -> 219777 | G38: ='Ops Departments'!R40 -> 140531 | H38: ='Ops Departments'!S40 -> 172522 | I38: ='Ops Departments'!T40 -> 167953 | J38: ='Ops Departments'!U40 -> 183441 | K38: ='Ops Departments'!V40 -> 128542 | L38: ='Ops Departments'!W40 -> 533767 | ... AB38: ='Ops Departments'!AM40 -> 930090.31 | AD38: =D38 -> SEO Revenue | AE38: =SUM(M38:P38) -> 1515886.9 | AF38: =SUM(Q38:T38) -> 1704307.8 | AG38: =AF38-AE38 -> 188420.94 | AH38: =AF38/AE38-1 -> 0.12429749 | AL38: =SUM(E38:H38) -> 764171 | AM38: =SUM(I38:L38) -> 1013703 | AN38: =SUM(M38:P38) -> 1515886.9 | AO38: =SUM(Q38:T38) -> 1704307.8 | AP38: =SUM(U38:X38) -> 2643595.8 | AQ38: =SUM(Y38:AB38) -> 3443594.4
D39: NNR | E39: ='Ops Departments'!L40-'Ops Departments'!K40 -> 61637 | F39: ='Ops Departments'!M40-'Ops Departments'!L40 -> 31826 | G39: ='Ops Departments'!N40-'Ops Departments'!M40 -> -24535 | H39: ='Ops Departments'!O40-'Ops Departments'!N40 -> 31287 | I39: ='Ops Departments'!P40-'Ops Departments'!O40 -> -34417 | J39: ='Ops Departments'!Q40-'Ops Departments'!P40 -> -11564 | K39: ='Ops Departments'!R40-'Ops Departments'!Q40 -> -79246 | L39: ='Ops Departments'!S40-'Ops Departments'!R40 -> 31991 | ... AB39: ='Ops Departments'!AI40-'Ops Departments'!AH40 -> 52143.186 | AD39: =D39 -> NNR | AE39: =Summary!DE8-Summary!DD8 -> 161359.9 | AF39: =AF38-AE38 -> 188420.94 | AG39: =AF39-AE39 -> 27061.035 | AL39: =SUM(E39:H39) -> 100215 | AM39: =AM38-AL38 -> 249532 | AN39: =AN38-AM38 -> 502183.9 | AO39: =AO38-AN38 -> 188420.94 | AP39: =AP38-AO38 -> 939287.98 | AQ39: =AQ38-AP38 -> 799998.59
D40: % Growth MoM | E40: ='Ops Departments'!L40/'Ops Departments'!K40-1 -> 0.37233226 | F40: ='Ops Departments'!M40/'Ops Departments'!L40-1 -> 0.14009156 | G40: ='Ops Departments'!N40/'Ops Departments'!M40-1 -> -0.094727535 | H40: ='Ops Departments'!O40/'Ops Departments'!N40-1 -> 0.13343654 | I40: ='Ops Departments'!P40/'Ops Departments'!O40-1 -> -0.12950504 | J40: ='Ops Departments'!Q40/'Ops Departments'!P40-1 -> -0.049986816 | K40: ='Ops Departments'!R40/'Ops Departments'!Q40-1 -> -0.36057458 | L40: ='Ops Departments'!S40/'Ops Departments'!R40-1 -> 0.22764372 | ... AB40: ='Ops Departments'!AI40/'Ops Departments'!AH40-1 -> 0.075596091 | AD40: % Growth ToT | AE40: =AN38/AM38-1 -> 0.4953955 | AF40: =AF38/AE38-1 -> 0.12429749 | AL40: =SUM(E40:H40) -> 0.55113283 | AM40: =AM38/AL38-1 -> 0.32653948 | AN40: =AN38/AM38-1 -> 0.4953955 | AO40: =AO38/AN38-1 -> 0.12429749 | AP40: =AP38/AO38-1 -> 0.55112577 | AQ40: =AQ38/AP38-1 -> 0.30261759
A42: SEO | B42: COGS Payroll | D42: Payroll & Related | E42: =SUMIFS('Ops Departments'!P:P,'Ops Departments'!$B:$B,$B42,'Ops Departments'!$A:$A,$A42) -> 16830 | F42: =SUMIFS('Ops Departments'!Q:Q,'Ops Departments'!$B:$B,$B42,'Ops Departments'!$A:$A,$A42) -> 12580 | G42: =SUMIFS('Ops Departments'!R:R,'Ops Departments'!$B:$B,$B42,'Ops Departments'!$A:$A,$A42) -> 19498 | H42: =SUMIFS('Ops Departments'!S:S,'Ops Departments'!$B:$B,$B42,'Ops Departments'!$A:$A,$A42) -> 14549 | I42: =SUMIFS('Ops Departments'!T:T,'Ops Departments'!$B:$B,$B42,'Ops Departments'!$A:$A,$A42) -> 18154 | J42: =SUMIFS('Ops Departments'!U:U,'Ops Departments'!$B:$B,$B42,'Ops Departments'!$A:$A,$A42) -> 15999 | K42: =SUMIFS('Ops Departments'!V:V,'Ops Departments'!$B:$B,$B42,'Ops Departments'!$A:$A,$A42) -> 22254 | L42: =SUMIFS('Ops Departments'!W:W,'Ops Departments'!$B:$B,$B42,'Ops Departments'!$A:$A,$A42) -> 20326 | M42: =SUMIFS('Ops Departments'!X:X,'Ops Departments'!$B:$B,$B42,'Ops Departments'!$A:$A,$A42) -> 18769 | N42: =SUMIFS('Ops Departments'!Y:Y,'Ops Departments'!$B:$B,$B42,'Ops Departments'!$A:$A,$A42) -> 16751 | O42: =SUMIFS('Ops Departments'!Z:Z,'Ops Departments'!$B:$B,$B42,'Ops Departments'!$A:$A,$A42) -> 19973 | P42: =SUMIFS('Ops Departments'!AA:AA,'Ops Departments'!$B:$B,$B42,'Ops Departments'!$A:$A,$A42) -> 39685.864 | Q42: =SUMIFS('Ops Departments'!AB:AB,'Ops Departments'!$B:$B,$B42,'Ops Departments'!$A:$A,$A42) -> 74084.545 | R42: =SUMIFS('Ops Departments'!AC:AC,'Ops Departments'!$B:$B,$B42,'Ops Departments'!$A:$A,$A42) -> 80941.656 | S42: =SUMIFS('Ops Departments'!AD:AD,'Ops Departments'!$B:$B,$B42,'Ops Departments'!$A:$A,$A42) -> 88153.975 | T42: =SUMIFS('Ops Departments'!AE:AE,'Ops Departments'!$B:$B,$B42,'Ops Departments'!$A:$A,$A42) -> 95282.45 | U42: =SUMIFS('Ops Departments'!AF:AF,'Ops Departments'!$B:$B,$B42,'Ops Departments'!$A:$A,$A42) -> 98708.491 | V42: =SUMIFS('Ops Departments'!AG:AG,'Ops Departments'!$B:$B,$B42,'Ops Departments'!$A:$A,$A42) -> 99195.537 | W42: =SUMIFS('Ops Departments'!AH:AH,'Ops Departments'!$B:$B,$B42,'Ops Departments'!$A:$A,$A42) -> 106020.6 | X42: =SUMIFS('Ops Departments'!AI:AI,'Ops Departments'!$B:$B,$B42,'Ops Departments'!$A:$A,$A42) -> 106521.66 | Y42: =SUMIFS('Ops Departments'!AJ:AJ,'Ops Departments'!$B:$B,$B42,'Ops Departments'!$A:$A,$A42) -> 110125.6 | Z42: =SUMIFS('Ops Departments'!AK:AK,'Ops Departments'!$B:$B,$B42,'Ops Departments'!$A:$A,$A42) -> 110589.16 | AA42: =SUMIFS('Ops Departments'!AL:AL,'Ops Departments'!$B:$B,$B42,'Ops Departments'!$A:$A,$A42) -> 111048.66 | AB42: =SUMIFS('Ops Departments'!AM:AM,'Ops Departments'!$B:$B,$B42,'Ops Departments'!$A:$A,$A42) -> 111520.45 | AD42: =D42 -> Payroll & Related | AE42: =SUM(M42:P42) -> 95178.864 | AF42: =SUM(Q42:T42) -> 338462.63 | AG42: =AE42-AF42 -> -243283.76 | AH42: =AF42/AE42-1 -> 2.5560692 | AL42: =SUM(E42:H42) -> 63457 | AM42: =SUM(I42:L42) -> 76733 | AN42: =SUM(M42:P42) -> 95178.864 | AO42: =SUM(Q42:T42) -> 338462.63 | AP42: =SUM(U42:X42) -> 410446.28 | AQ42: =SUM(Y42:AB42) -> 443283.87
A43: SEO | B43: COGS Contractors | D43: Contractors | E43: =SUMIFS('Ops Departments'!P:P,'Ops Departments'!$B:$B,$B43,'Ops Departments'!$A:$A,$A43) -> 3243 | F43: =SUMIFS('Ops Departments'!Q:Q,'Ops Departments'!$B:$B,$B43,'Ops Departments'!$A:$A,$A43) -> 2624 | G43: =SUMIFS('Ops Departments'!R:R,'Ops Departments'!$B:$B,$B43,'Ops Departments'!$A:$A,$A43) -> 1810 | H43: =SUMIFS('Ops Departments'!S:S,'Ops Departments'!$B:$B,$B43,'Ops Departments'!$A:$A,$A43) -> 1991 | I43: =SUMIFS('Ops Departments'!T:T,'Ops Departments'!$B:$B,$B43,'Ops Departments'!$A:$A,$A43) -> 4873 | J43: =SUMIFS('Ops Departments'!U:U,'Ops Departments'!$B:$B,$B43,'Ops Departments'!$A:$A,$A43) -> 4213 | K43: =SUMIFS('Ops Departments'!V:V,'Ops Departments'!$B:$B,$B43,'Ops Departments'!$A:$A,$A43) -> 342 | L43: =SUMIFS('Ops Departments'!W:W,'Ops Departments'!$B:$B,$B43,'Ops Departments'!$A:$A,$A43) -> 4878 | M43: =SUMIFS('Ops Departments'!X:X,'Ops Departments'!$B:$B,$B43,'Ops Departments'!$A:$A,$A43) -> 4073 | N43: =SUMIFS('Ops Departments'!Y:Y,'Ops Departments'!$B:$B,$B43,'Ops Departments'!$A:$A,$A43) -> 523 | O43: =SUMIFS('Ops Departments'!Z:Z,'Ops Departments'!$B:$B,$B43,'Ops Departments'!$A:$A,$A43) -> 4191 | P43: =SUMIFS('Ops Departments'!AA:AA,'Ops Departments'!$B:$B,$B43,'Ops Departments'!$A:$A,$A43) -> 1914.3593 | Q43: =SUMIFS('Ops Departments'!AB:AB,'Ops Departments'!$B:$B,$B43,'Ops Departments'!$A:$A,$A43) -> 834.43884 | R43: =SUMIFS('Ops Departments'!AC:AC,'Ops Departments'!$B:$B,$B43,'Ops Departments'!$A:$A,$A43) -> 992.12652 | S43: =SUMIFS('Ops Departments'!AD:AD,'Ops Departments'!$B:$B,$B43,'Ops Departments'!$A:$A,$A43) -> 1141.8882 | T43: =SUMIFS('Ops Departments'!AE:AE,'Ops Departments'!$B:$B,$B43,'Ops Departments'!$A:$A,$A43) -> 1292.316 | U43: =SUMIFS('Ops Departments'!AF:AF,'Ops Departments'!$B:$B,$B43,'Ops Departments'!$A:$A,$A43) -> 864.87043 | V43: =SUMIFS('Ops Departments'!AG:AG,'Ops Departments'!$B:$B,$B43,'Ops Departments'!$A:$A,$A43) -> 953.02747 | W43: =SUMIFS('Ops Departments'!AH:AH,'Ops Departments'!$B:$B,$B43,'Ops Departments'!$A:$A,$A43) -> 1034.6405 | X43: =SUMIFS('Ops Departments'!AI:AI,'Ops Departments'!$B:$B,$B43,'Ops Departments'!$A:$A,$A43) -> 1112.8553 | Y43: =SUMIFS('Ops Departments'!AJ:AJ,'Ops Departments'!$B:$B,$B43,'Ops Departments'!$A:$A,$A43) -> 1188.9785 | Z43: =SUMIFS('Ops Departments'!AK:AK,'Ops Departments'!$B:$B,$B43,'Ops Departments'!$A:$A,$A43) -> 1255.7401 | AA43: =SUMIFS('Ops Departments'!AL:AL,'Ops Departments'!$B:$B,$B43,'Ops Departments'!$A:$A,$A43) -> 1325.5376 | AB43: =SUMIFS('Ops Departments'!AM:AM,'Ops Departments'!$B:$B,$B43,'Ops Departments'!$A:$A,$A43) -> 1395.1355 | AD43: =D43 -> Contractors | AE43: =SUM(M43:P43) -> 10701.359 | AF43: =SUM(Q43:T43) -> 4260.7696 | AG43: =AE43-AF43 -> 6440.5897 | AH43: =AF43/AE43-1 -> -0.60184781 | AL43: =SUM(E43:H43) -> 9668 | AM43: =SUM(I43:L43) -> 14306 | AN43: =SUM(M43:P43) -> 10701.359 | AO43: =SUM(Q43:T43) -> 4260.7696 | AP43: =SUM(U43:X43) -> 3965.3937 | AQ43: =SUM(Y43:AB43) -> 5165.3916
A44: SEO | B44: COGS Travel | D44: T&E | E44: =SUMIFS('Ops Departments'!P:P,'Ops Departments'!$B:$B,$B44,'Ops Departments'!$A:$A,$A44) -> 6097 | F44: =SUMIFS('Ops Departments'!Q:Q,'Ops Departments'!$B:$B,$B44,'Ops Departments'!$A:$A,$A44) -> 6543 | G44: =SUMIFS('Ops Departments'!R:R,'Ops Departments'!$B:$B,$B44,'Ops Departments'!$A:$A,$A44) -> 9439 | H44: =SUMIFS('Ops Departments'!S:S,'Ops Departments'!$B:$B,$B44,'Ops Departments'!$A:$A,$A44) -> 5164 | I44: =SUMIFS('Ops Departments'!T:T,'Ops Departments'!$B:$B,$B44,'Ops Departments'!$A:$A,$A44) -> 9496 | J44: =SUMIFS('Ops Departments'!U:U,'Ops Departments'!$B:$B,$B44,'Ops Departments'!$A:$A,$A44) -> 9712 | K44: =SUMIFS('Ops Departments'!V:V,'Ops Departments'!$B:$B,$B44,'Ops Departments'!$A:$A,$A44) -> 4613 | L44: =SUMIFS('Ops Departments'!W:W,'Ops Departments'!$B:$B,$B44,'Ops Departments'!$A:$A,$A44) -> 7737 | M44: =SUMIFS('Ops Departments'!X:X,'Ops Departments'!$B:$B,$B44,'Ops Departments'!$A:$A,$A44) -> 8367 | N44: =SUMIFS('Ops Departments'!Y:Y,'Ops Departments'!$B:$B,$B44,'Ops Departments'!$A:$A,$A44) -> 7815 | O44: =SUMIFS('Ops Departments'!Z:Z,'Ops Departments'!$B:$B,$B44,'Ops Departments'!$A:$A,$A44) -> 14491 | P44: =SUMIFS('Ops Departments'!AA:AA,'Ops Departments'!$B:$B,$B44,'Ops Departments'!$A:$A,$A44) -> 3921.2587 | Q44: =SUMIFS('Ops Departments'!AB:AB,'Ops Departments'!$B:$B,$B44,'Ops Departments'!$A:$A,$A44) -> 4313.3846 | R44: =SUMIFS('Ops Departments'!AC:AC,'Ops Departments'!$B:$B,$B44,'Ops Departments'!$A:$A,$A44) -> 4356.5185 | S44: =SUMIFS('Ops Departments'!AD:AD,'Ops Departments'!$B:$B,$B44,'Ops Departments'!$A:$A,$A44) -> 4400.0837 | T44: =SUMIFS('Ops Departments'!AE:AE,'Ops Departments'!$B:$B,$B44,'Ops Departments'!$A:$A,$A44) -> 4444.0845 | U44: =SUMIFS('Ops Departments'!AF:AF,'Ops Departments'!$B:$B,$B44,'Ops Departments'!$A:$A,$A44) -> 4488.5253 | V44: =SUMIFS('Ops Departments'!AG:AG,'Ops Departments'!$B:$B,$B44,'Ops Departments'!$A:$A,$A44) -> 4533.4106 | W44: =SUMIFS('Ops Departments'!AH:AH,'Ops Departments'!$B:$B,$B44,'Ops Departments'!$A:$A,$A44) -> 4578.7447 | X44: =SUMIFS('Ops Departments'!AI:AI,'Ops Departments'!$B:$B,$B44,'Ops Departments'!$A:$A,$A44) -> 4624.5321 | Y44: =SUMIFS('Ops Departments'!AJ:AJ,'Ops Departments'!$B:$B,$B44,'Ops Departments'!$A:$A,$A44) -> 4670.7775 | Z44: =SUMIFS('Ops Departments'!AK:AK,'Ops Departments'!$B:$B,$B44,'Ops Departments'!$A:$A,$A44) -> 4717.4852 | AA44: =SUMIFS('Ops Departments'!AL:AL,'Ops Departments'!$B:$B,$B44,'Ops Departments'!$A:$A,$A44) -> 4764.6601 | AB44: =SUMIFS('Ops Departments'!AM:AM,'Ops Departments'!$B:$B,$B44,'Ops Departments'!$A:$A,$A44) -> 4812.3067 | AD44: =D44 -> T&E | AE44: =SUM(M44:P44) -> 34594.259 | AF44: =SUM(Q44:T44) -> 17514.071 | AG44: =AE44-AF44 -> 17080.188 | AH44: =AF44/AE44-1 -> -0.49372896 | AL44: =SUM(E44:H44) -> 27243 | AM44: =SUM(I44:L44) -> 31558 | AN44: =SUM(M44:P44) -> 34594.259 | AO44: =SUM(Q44:T44) -> 17514.071 | AP44: =SUM(U44:X44) -> 18225.213 | AQ44: =SUM(Y44:AB44) -> 18965.229
A45: SEO | B45: COGS Software | D45: Software | E45: =SUMIFS('Ops Departments'!P:P,'Ops Departments'!$B:$B,$B45,'Ops Departments'!$A:$A,$A45) -> 4354 | F45: =SUMIFS('Ops Departments'!Q:Q,'Ops Departments'!$B:$B,$B45,'Ops Departments'!$A:$A,$A45) -> 252 | G45: =SUMIFS('Ops Departments'!R:R,'Ops Departments'!$B:$B,$B45,'Ops Departments'!$A:$A,$A45) -> 4069 | H45: =SUMIFS('Ops Departments'!S:S,'Ops Departments'!$B:$B,$B45,'Ops Departments'!$A:$A,$A45) -> 4894 | I45: =SUMIFS('Ops Departments'!T:T,'Ops Departments'!$B:$B,$B45,'Ops Departments'!$A:$A,$A45) -> 3654 | J45: =SUMIFS('Ops Departments'!U:U,'Ops Departments'!$B:$B,$B45,'Ops Departments'!$A:$A,$A45) -> 772 | K45: =SUMIFS('Ops Departments'!V:V,'Ops Departments'!$B:$B,$B45,'Ops Departments'!$A:$A,$A45) -> 3916 | L45: =SUMIFS('Ops Departments'!W:W,'Ops Departments'!$B:$B,$B45,'Ops Departments'!$A:$A,$A45) -> 2522 | M45: =SUMIFS('Ops Departments'!X:X,'Ops Departments'!$B:$B,$B45,'Ops Departments'!$A:$A,$A45) -> 2135 | N45: =SUMIFS('Ops Departments'!Y:Y,'Ops Departments'!$B:$B,$B45,'Ops Departments'!$A:$A,$A45) -> 2754 | O45: =SUMIFS('Ops Departments'!Z:Z,'Ops Departments'!$B:$B,$B45,'Ops Departments'!$A:$A,$A45) -> 1715 | P45: =SUMIFS('Ops Departments'!AA:AA,'Ops Departments'!$B:$B,$B45,'Ops Departments'!$A:$A,$A45) -> 266.048 | Q45: =SUMIFS('Ops Departments'!AB:AB,'Ops Departments'!$B:$B,$B45,'Ops Departments'!$A:$A,$A45) -> 586.048 | R45: =SUMIFS('Ops Departments'!AC:AC,'Ops Departments'!$B:$B,$B45,'Ops Departments'!$A:$A,$A45) -> 586.048 | S45: =SUMIFS('Ops Departments'!AD:AD,'Ops Departments'!$B:$B,$B45,'Ops Departments'!$A:$A,$A45) -> 586.048 | T45: =SUMIFS('Ops Departments'!AE:AE,'Ops Departments'!$B:$B,$B45,'Ops Departments'!$A:$A,$A45) -> 586.048 | U45: =SUMIFS('Ops Departments'!AF:AF,'Ops Departments'!$B:$B,$B45,'Ops Departments'!$A:$A,$A45) -> 906.048 | V45: =SUMIFS('Ops Departments'!AG:AG,'Ops Departments'!$B:$B,$B45,'Ops Departments'!$A:$A,$A45) -> 906.048 | W45: =SUMIFS('Ops Departments'!AH:AH,'Ops Departments'!$B:$B,$B45,'Ops Departments'!$A:$A,$A45) -> 906.048 | X45: =SUMIFS('Ops Departments'!AI:AI,'Ops Departments'!$B:$B,$B45,'Ops Departments'!$A:$A,$A45) -> 906.048 | Y45: =SUMIFS('Ops Departments'!AJ:AJ,'Ops Departments'!$B:$B,$B45,'Ops Departments'!$A:$A,$A45) -> 1226.048 | Z45: =SUMIFS('Ops Departments'!AK:AK,'Ops Departments'!$B:$B,$B45,'Ops Departments'!$A:$A,$A45) -> 1226.048 | AA45: =SUMIFS('Ops Departments'!AL:AL,'Ops Departments'!$B:$B,$B45,'Ops Departments'!$A:$A,$A45) -> 1226.048 | AB45: =SUMIFS('Ops Departments'!AM:AM,'Ops Departments'!$B:$B,$B45,'Ops Departments'!$A:$A,$A45) -> 1226.048 | AD45: =D45 -> Software | AE45: =SUM(M45:P45) -> 6870.048 | AF45: =SUM(Q45:T45) -> 2344.192 | AG45: =AE45-AF45 -> 4525.856 | AH45: =AF45/AE45-1 -> -0.65878084 | AL45: =SUM(E45:H45) -> 13569 | AM45: =SUM(I45:L45) -> 10864 | AN45: =SUM(M45:P45) -> 6870.048 | AO45: =SUM(Q45:T45) -> 2344.192 | AP45: =SUM(U45:X45) -> 3624.192 | AQ45: =SUM(Y45:AB45) -> 4904.192
A46: SEO | B46: COGS Other | D46: Other | E46: =SUMIFS('Ops Departments'!P:P,'Ops Departments'!$B:$B,$B46,'Ops Departments'!$A:$A,$A46) -> 0 | F46: =SUMIFS('Ops Departments'!Q:Q,'Ops Departments'!$B:$B,$B46,'Ops Departments'!$A:$A,$A46) -> 0 | G46: =SUMIFS('Ops Departments'!R:R,'Ops Departments'!$B:$B,$B46,'Ops Departments'!$A:$A,$A46) -> 0 | H46: =SUMIFS('Ops Departments'!S:S,'Ops Departments'!$B:$B,$B46,'Ops Departments'!$A:$A,$A46) -> 0 | I46: =SUMIFS('Ops Departments'!T:T,'Ops Departments'!$B:$B,$B46,'Ops Departments'!$A:$A,$A46) -> 0 | J46: =SUMIFS('Ops Departments'!U:U,'Ops Departments'!$B:$B,$B46,'Ops Departments'!$A:$A,$A46) -> 0 | K46: =SUMIFS('Ops Departments'!V:V,'Ops Departments'!$B:$B,$B46,'Ops Departments'!$A:$A,$A46) -> 0 | L46: =SUMIFS('Ops Departments'!W:W,'Ops Departments'!$B:$B,$B46,'Ops Departments'!$A:$A,$A46) -> 0 | M46: =SUMIFS('Ops Departments'!X:X,'Ops Departments'!$B:$B,$B46,'Ops Departments'!$A:$A,$A46) -> 0 | N46: =SUMIFS('Ops Departments'!Y:Y,'Ops Departments'!$B:$B,$B46,'Ops Departments'!$A:$A,$A46) -> 0 | O46: =SUMIFS('Ops Departments'!Z:Z,'Ops Departments'!$B:$B,$B46,'Ops Departments'!$A:$A,$A46) -> 0 | P46: =SUMIFS('Ops Departments'!AA:AA,'Ops Departments'!$B:$B,$B46,'Ops Departments'!$A:$A,$A46) -> 35360.561 | Q46: =SUMIFS('Ops Departments'!AB:AB,'Ops Departments'!$B:$B,$B46,'Ops Departments'!$A:$A,$A46) -> 41308.387 | R46: =SUMIFS('Ops Departments'!AC:AC,'Ops Departments'!$B:$B,$B46,'Ops Departments'!$A:$A,$A46) -> 41599.47 | S46: =SUMIFS('Ops Departments'!AD:AD,'Ops Departments'!$B:$B,$B46,'Ops Departments'!$A:$A,$A46) -> 41560.514 | T46: =SUMIFS('Ops Departments'!AE:AE,'Ops Departments'!$B:$B,$B46,'Ops Departments'!$A:$A,$A46) -> 44705.699 | U46: =SUMIFS('Ops Departments'!AF:AF,'Ops Departments'!$B:$B,$B46,'Ops Departments'!$A:$A,$A46) -> 49843.724 | V46: =SUMIFS('Ops Departments'!AG:AG,'Ops Departments'!$B:$B,$B46,'Ops Departments'!$A:$A,$A46) -> 49423.151 | W46: =SUMIFS('Ops Departments'!AH:AH,'Ops Departments'!$B:$B,$B46,'Ops Departments'!$A:$A,$A46) -> 48457.523 | X46: =SUMIFS('Ops Departments'!AI:AI,'Ops Departments'!$B:$B,$B46,'Ops Departments'!$A:$A,$A46) -> 52164.022 | Y46: =SUMIFS('Ops Departments'!AJ:AJ,'Ops Departments'!$B:$B,$B46,'Ops Departments'!$A:$A,$A46) -> 57241.393 | Z46: =SUMIFS('Ops Departments'!AK:AK,'Ops Departments'!$B:$B,$B46,'Ops Departments'!$A:$A,$A46) -> 60276.575 | AA46: =SUMIFS('Ops Departments'!AL:AL,'Ops Departments'!$B:$B,$B46,'Ops Departments'!$A:$A,$A46) -> 59054.517 | AB46: =SUMIFS('Ops Departments'!AM:AM,'Ops Departments'!$B:$B,$B46,'Ops Departments'!$A:$A,$A46) -> 62167.418 | AD46: =D46 -> Other | AE46: =SUM(M46:P46) -> 35360.561 | AF46: =SUM(Q46:T46) -> 169174.07 | AG46: =AE46-AF46 -> -133813.51 | AH46: =AF46/AE46-1 -> 3.7842586 | AL46: =SUM(E46:H46) -> 0 | AM46: =SUM(I46:L46) -> 0 | AN46: =SUM(M46:P46) -> 35360.561 | AO46: =SUM(Q46:T46) -> 169174.07 | AP46: =SUM(U46:X46) -> 199888.42 | AQ46: =SUM(Y46:AB46) -> 238739.9
D47: Total COGS | E47: =SUM(E42:E46) -> 30524 | F47: =SUM(F42:F46) -> 21999 | G47: =SUM(G42:G46) -> 34816 | H47: =SUM(H42:H46) -> 26598 | I47: =SUM(I42:I46) -> 36177 | J47: =SUM(J42:J46) -> 30696 | K47: =SUM(K42:K46) -> 31125 | L47: =SUM(L42:L46) -> 35463 | ... AB47: =SUM(AB42:AB46) -> 181121.36 | AD47: =D47 -> Total COGS | AE47: =SUM(M47:P47) -> 182705.09 | AF47: =SUM(Q47:T47) -> 531755.73 | AG47: =AE47-AF47 -> -349050.64 | AH47: =AF47/AE47-1 -> 1.9104593 | AL47: =SUM(E47:H47) -> 113937 | AM47: =SUM(I47:L47) -> 133461 | AN47: =SUM(M47:P47) -> 182705.09 | AO47: =SUM(Q47:T47) -> 531755.73 | AP47: =SUM(U47:X47) -> 636149.5 | AQ47: =SUM(Y47:AB47) -> 711058.59
D49: =CONCATENATE(B34," Gross Profit") -> SEO Gross Profit | E49: =E38-E47 -> 200817 | F49: =F38-F47 -> 197778 | G49: =G38-G47 -> 105715 | H49: =H38-H47 -> 145924 | I49: =I38-I47 -> 131776 | J49: =J38-J47 -> 152745 | K49: =K38-K47 -> 97417 | L49: =L38-L47 -> 498304 | ... AB49: =AB38-AB47 -> 748968.95 | AD49: =D49 -> SEO Gross Profit | AE49: =AE38-AE47 -> 1333181.8 | AF49: =AF38-AF47 -> 1172552.1 | AG49: =AF49-AE49 -> -160629.7 | AH49: =AF49/AE49-1 -> -0.12048597 | AL49: =SUM(E49:H49) -> 650234 | AM49: =SUM(I49:L49) -> 880242 | AN49: =SUM(M49:P49) -> 1333181.8 | AO49: =SUM(Q49:T49) -> 1172552.1 | AP49: =SUM(U49:X49) -> 2007446.3 | AQ49: =SUM(Y49:AB49) -> 2732535.8
D50: Gross Margin | E50: =E49/E38 -> 0.86805625 | F50: =F49/F38 -> 0.89990308 | G50: =G49/G38 -> 0.75225395 | H50: =H49/H38 -> 0.84582836 | I50: =I49/I38 -> 0.78460045 | J50: =J49/J38 -> 0.83266554 | K50: =K49/K38 -> 0.75786124 | L50: =L49/L38 -> 0.9335609 | ... AB50: =AB49/AB38 -> 0.80526476 | AD50: =D50 -> Gross Margin | AE50: =AE49/AE38 -> 0.87947314 | AF50: =AF49/AF38 -> 0.68799315 | AG50: =AF50-AE50 -> -0.19147999 | AL50: =AL49/AL38 -> 0.85090117 | AM50: =AM49/AM38 -> 0.86834309 | AN50: =AN49/AN38 -> 0.87947314 | AO50: =AO49/AO38 -> 0.68799315 | AP50: =AP49/AP38 -> 0.75936204 | AQ50: =AQ49/AQ38 -> 0.79351268
D52: Headcount | E52: =Headcount!H13 -> 20 | F52: =Headcount!I13 -> 20 | G52: =Headcount!J13 -> 20 | H52: =Headcount!K13 -> 20 | I52: =Headcount!L13 -> 20 | J52: =Headcount!M13 -> 20 | K52: =Headcount!N13 -> 20 | L52: =Headcount!O13 -> 20 | ... N52: =Headcount!Q13 -> 20 | O52: =Headcount!R13+Headcount!R14 -> 40 | P52: =Headcount!S13+Headcount!S14 -> 42 | Q52: =Headcount!T13+Headcount!T14 -> 46 | R52: =Headcount!U13+Headcount!U14 -> 47 | S52: =Headcount!V13+Headcount!V14 -> 48 | T52: =Headcount!W13+Headcount!W14 -> 49 | U52: =Headcount!X13+Headcount!X14 -> 49 | V52: =Headcount!Y13+Headcount!Y14 -> 49 | ... AB52: =Headcount!AE13+Headcount!AE14 -> 49 | AD52: =D52 -> Headcount | AE52: =P52 -> 42 | AF52: =T52 -> 49 | AG52: =AF52-AE52 -> 7 | AH52: =AF52/AE52-1 -> 0.16666667 | AK52: Headcount | AL52: =H52 -> 20 | AM52: =L52 -> 20 | AN52: =P52 -> 42 | AO52: =T52 -> 49 | AP52: =X52 -> 49 | AQ52: =AB52 -> 49
D53: Revenue/Strategist | E53: =E38/Capacity!O71 -> 12852.278 | F53: =F38/Capacity!P71 -> 12209.833 | G53: =G38/Capacity!Q71 -> 7807.2778 | H53: =H38/Capacity!R71 -> 9584.5556 | I53: =I38/Capacity!S71 -> 9330.7222 | J53: =J38/Capacity!T71 -> 10191.167 | K53: =K38/Capacity!U71 -> 7141.2222 | L53: =L38/Capacity!V71 -> 29653.722 | ... AB53: =AB38/Capacity!AL71 -> 48952.122 | AD53: =D53 -> Revenue/Strategist | AE53: =AVERAGE(M53:P53) -> 20854.073 | AF53: =AVERAGE(Q53:T53) -> 22425.103 | AG53: =AF53-AE53 -> 1571.0306 | AH53: =AF53/AE53-1 -> 0.075334476 | AK53: Revenue/Strategist | AL53: =AVERAGE(E53:H53) -> 10613.486 | AM53: =AVERAGE(I53:L53) -> 14079.208 | AN53: =AVERAGE(M53:P53) -> 20854.073 | AO53: =AVERAGE(Q53:T53) -> 22425.103 | AP53: =AVERAGE(U53:X53) -> 34784.156 | AQ53: =AVERAGE(Y53:AB53) -> 45310.453
D54: # of Product Opportunities | E54: =SUM('New Biz Sales'!O40) -> 30 | F54: =SUM('New Biz Sales'!P40) -> 30 | G54: =SUM('New Biz Sales'!Q40) -> 30 | H54: =SUM('New Biz Sales'!R40) -> 30 | I54: =SUM('New Biz Sales'!S40) -> 30 | J54: =SUM('New Biz Sales'!T40) -> 30 | K54: =SUM('New Biz Sales'!U40) -> 30 | L54: =SUM('New Biz Sales'!V40) -> 30 | ... AB54: =SUM('New Biz Sales'!AL40) -> 22.054725 | AD54: =D54 -> # of Product Opportunities | AE54: =SUM(M54:P54) -> 123 | AF54: =SUM(Q54:T54) -> 132 | AG54: =AF54-AE54 -> 9 | AH54: =AF54/AE54-1 -> 0.073170732 | AK54: # of Product Opportunities | AL54: =SUM(E54:H54) -> 120 | AM54: =SUM(I54:L54) -> 120 | AN54: =SUM(M54:P54) -> 123 | AO54: =SUM(Q54:T54) -> 132 | AP54: =SUM(U54:X54) -> 130.35 | AQ54: =SUM(Y54:AB54) -> 116.26148
...

Sheet Summary
D4: 43831 | E4: 43862 | F4: 43891 | G4: 43922 | H4: 43952 | I4: 43983 | J4: 44013 | K4: 44044 | L4: 44075 | M4: 44105 | N4: 44136 | O4: 44166 | P4: 44197 | Q4: 44228 | R4: 44256 | S4: 44287 | T4: 44317 | U4: 44348 | V4: 44378 | W4: 44409 | X4: 44440 | Y4: 44470 | Z4: 44501 | AA4: 44531 | AB4: 44562 | AC4: 44593 | AD4: 44621 | AE4: 44652 | AF4: 44682 | AG4: 44713 | AH4: 44743 | AI4: 44774 | AJ4: 44805 | AK4: 44835 | AL4: 44866 | AM4: 44896 | AN4: 44927 | AO4: 44958 | AP4: 44986 | AQ4: 45017 | AR4: 45047 | AS4: 45078 | AT4: 45108 | AU4: 45139 | AV4: 45170 | AW4: 45200 | AX4: 45231 | AY4: 45261 | AZ4: 45292 | BA4: 45323 | BB4: 45352 | BC4: 45383 | BD4: 45413 | BE4: 45444 | BF4: 45474 | BG4: 45505 | BH4: 45536 | BI4: 45566 | BJ4: 45597 | BK4: 45627 | BL4: 45658 | BM4: 45689 | BN4: 45717 | BO4: 45748 | BP4: 45778 | BQ4: 45809 | BR4: 45839 | BS4: 45870 | BT4: 45901 | BU4: 45931 | BV4: 45962 | BW4: 45992 | BX4: 46023 | BY4: 46054 | BZ4: 46082 | CA4: 46113 | CB4: 46143 | CC4: 46174 | CD4: 46204 | CE4: 46235 | CF4: 46266 | CG4: 46296 | CH4: 46327 | CI4: 46357 | CJ4: 46388 | CK4: 46419 | CL4: 46447 | CM4: 46478 | CN4: 46508 | CO4: 46539 | CP4: 46569 | CQ4: 46600 | CR4: 46631 | CS4: 46661 | CT4: 46692 | CU4: 46722 | CW4: T1 2020 | CX4: T2 2020 | CY4: T3 2020 | CZ4: T1 2021 | DA4: T2 2021 | DB4: T3 2021 | DC4: T1 2022 | DD4: T2 2022 | DE4: T3 2022 | DF4: T1 2023 | DG4: T2 2023 | DH4: T3 2023 | DI4: T1 2024 | DJ4: T2 2024 | DK4: T3 2024 | DL4: T1 2025 | DM4: T2 2025 | DN4: T3 2025 | DO4: T1 2026 | DP4: T2 2026 | DQ4: T3 2026 | DR4: T1 2027 | DS4: T2 2027 | DT4: T3 2027 | DV4: 2020 | DW4: 2021 | DX4: 2022 | DY4: 2023 | DZ4: 2024 | EA4: 2025 | EB4: 2026 | EC4: 2027
