Workbook

Sheet Summary
B1: 44986
B2: Growth | G2: Retention | L2: Financials | Q2: Operations
C3: Previous | D3: Current | E3: Goal | H3: Previous | I3: Current | J3: Goal | M3: Previous | N3: Current | O3: Goal | R3: Previous | S3: Current | T3: Goal
B4: New Biz N. America | C4: =Detail!H7 -> 1.047619 | D4: =Detail!K7 -> 0.90909091 | E4: 1 | G4: Contract Renewal Rate | H4: =Detail!D42 -> 0.4 | I4: =Detail!E42 -> 0.66666667 | J4: =Detail!H42 -> 0.65 | L4: Gross Margin | M4: =Detail!F88 -> 0.55555556 | N4: =Detail!I88 -> 0.5 | O4: =Detail!G88 -> 0.53766234 | Q4: PM Utilization | R4: =Detail!D116 -> 0.893 | S4: =Detail!E116 -> 0.912 | T4: =Detail!G116 -> 0.8
B5: New Biz International | C5: =Detail!H8 -> 0.4 | D5: =Detail!K8 -> 1.1 | E5: 1 | G5: Bookings Renewal Rate | H5: =Detail!D47 -> 0.5 | I5: =Detail!E47 -> 0.66917608 | J5: =Detail!H47 -> 0.65 | L5: EBITDA Margin | M5: =Detail!F90 -> 0.19444444 | N5: =Detail!I90 -> 0.20394737 | O5: =Detail!G90 -> 0.22077922 | Q5: SEO Utilization | R5: =Detail!D117 -> 0.675 | S5: =Detail!E117 -> 0.836 | T5: =Detail!G117 -> 0.8
B6: Client Partnerships | C6: =Detail!H9 -> 0.96774194 | D6: =Detail!K9 -> 1.125 | E6: 1 | G6: Opt-Out Contract Retained Rate | H6: =Detail!D51 -> 0.5 | I6: N/A | J6: =Detail!H51 -> 0.8 | Q6: Creative Utilization | R6: =Detail!D118 -> 0.883 | S6: =Detail!E118 -> 0.723 | T6: =Detail!G118 -> 0.8
B7: Total Bookings | C7: =Detail!H10 -> 0.93975904 | D7: =Detail!K10 -> 1.0116279 | E7: 1 | G7: Opt-Out Bookings Retained Rate | H7: =Detail!D54 -> 0.5 | I7: N/A | J7: =Detail!H54 -> 0.8 | L7: TTM Revenue/FTE | M7: =Detail!D99 -> 200617.28 | N7: =Detail!E99 -> 196987.95 | O7: =Detail!G99 -> 200000 | Q7: Rev Ops Utilizaiton | R7: =Detail!D119 -> 0.731 | S7: =Detail!E119 -> 0.569 | T7: =Detail!G119 -> 0.8
Q8: Strategy Utilization | R8: =Detail!D120 -> 0.865 | S8: =Detail!E120 -> 0.59 | T8: =Detail!G120 -> 0.8
B9: Pod 1 | C9: =Detail!H16 -> 1.2571429 | D9: =Detail!K16 -> 1.0909091 | E9: 1 | G9: PM Monthly Rev Retention | H9: =Detail!D62 -> 0.98095238 | I9: =Detail!E62 -> 0.97272727 | J9: =Detail!G62 -> 0.96 | L9: Operations % of Rev | M9: =Detail!D103 -> 0.44444444 | N9: =Detail!E103 -> 0.5 | O9: =Detail!G103 -> 0.45432099 | Q9: Total Directive | R9: =Detail!D121 -> 0.8094 | S9: =Detail!E121 -> 0.733 | T9: =Detail!G121 -> 0.8
B10: Pod 2 | C10: =Detail!H17 -> 1.1 | D10: =Detail!K17 -> 0.95454545 | E10: 1 | G10: SEO Monthly Rev Retention | H10: =Detail!D67 -> 0.96315789 | I10: =Detail!E67 -> 0.94444444 | J10: =Detail!G67 -> 0.96 | L10: Sales % of Rev | M10: =Detail!D104 -> 0.116 | N10: =Detail!E104 -> 0.091 | O10: =Detail!G104 -> 0.099 | R10: =Detail!C122
B11: Pod 3 | C11: =Detail!H18 -> 0.78571429 | D11: =Detail!K18 -> 0.68181818 | E11: 1 | G11: Design Monthly Rev Retention | H11: =Detail!D72 -> 0.92857143 | I11: =Detail!E72 -> 0.9 | J11: =Detail!G72 -> 0.96 | L11: Marketing % of Rev | M11: =Detail!D105 -> 0.127 | N11: =Detail!E105 -> 0.11 | O11: =Detail!G105 -> 0.11 | Q11: Paid Media NSM | R11: N/A | S11: =Detail!C126 -> 0.88 | T11: =Detail!D126 -> 1
B12: Pod 4 | C12: =Detail!H19 -> 0.4 | D12: =Detail!K19 -> 1.1 | E12: 1 | G12: Directive Monthly Rev Retention | H12: =Detail!D77 -> 0.95737705 | I12: =Detail!E77 -> 0.94 | J12: =Detail!G77 -> 0.96 | L12: Finance % of Rev | M12: =Detail!D106 -> 0.024 | N12: =Detail!E106 -> 0.023 | O12: =Detail!G106 -> 0.02 | Q12: SEO NSM | R12: N/A | S12: =Detail!C133 -> 0.75 | T12: =Detail!D133 -> 1
B13: Total New Biz | C13: =Detail!H20 -> 0.92307692 | D13: =Detail!K20 -> 0.94444444 | E13: 1 | L13: People Ops % of Rev | M13: =Detail!D107 -> 0.055 | N13: =Detail!E107 -> 0.042 | O13: =Detail!G107 -> 0.05
L14: General OH % of Rev | M14: =Detail!D108 -> 0.04 | N14: =Detail!E108 -> 0.03 | O14: =Detail!G108 -> 0.04
B15: Intro Close Rate (T3Mo) | C15: =Detail!D25 -> 0.057692308 | D15: =Detail!E25 -> 0.083333333 | E15: =Detail!G25 -> 0.07
B16: Proposal Close Rate (T3Mo) | C16: =Detail!D27 -> 0.25 | D16: =Detail!E27 -> 0.28571429 | E16: =Detail!G27 -> 0.3
B17: LTV | C17: =Detail!D30 -> 130000 | D17: =Detail!E30 -> 125000 | E17: 90000
B18: CAC | C18: =Detail!D31 -> 50000 | D18: =Detail!E31 -> 55000 | E18: =Detail!G31 -> 30000
B19: LTV:CAC | C19: =Detail!D32 -> 2.6 | D19: =Detail!E32 -> 2.2727273 | E19: =Detail!G32 -> 3

Sheet Detail
B2: GROWTH
B4: Bookings
C5: January | F5: February | I5: March | L5: April | O5: T1
C6: Actuals | D6: Goal | E6: % to Goal | F6: Actuals | G6: Goal | H6: % to Goal | I6: Actuals | J6: Goal | K6: % to Goal | L6: Actuals | M6: Goal | N6: % to Goal | O6: Actuals | P6: Goal | Q6: % to Goal
B7: New Biz N. America | C7: 950000 | D7: 1000000 | E7: =C7/D7 -> 0.95 | F7: 1100000 | G7: =D7+50000 -> 1050000 | H7: =F7/G7 -> 1.047619 | I7: 1000000 | J7: =G7+50000 -> 1100000 | K7: =I7/J7 -> 0.90909091 | M7: =J7+50000 -> 1150000 | N7: =L7/M7 -> 0 | O7: =SUM(L7,I7,F7,C7) -> 3050000 | P7: =SUM(M7,J7,G7,D7) -> 4300000 | Q7: =O7/P7 -> 0.70930233
B8: New Biz International | C8: 325000 | D8: 250000 | E8: =C8/D8 -> 1.3 | F8: 100000 | G8: =D8 -> 250000 | H8: =F8/G8 -> 0.4 | I8: 275000 | J8: =G8 -> 250000 | K8: =I8/J8 -> 1.1 | M8: =J8 -> 250000 | N8: =L8/M8 -> 0 | O8: =SUM(L8,I8,F8,C8) -> 700000 | P8: =SUM(M8,J8,G8,D8) -> 1000000 | Q8: =O8/P8 -> 0.7
B9: Client Partnerships | C9: 780000 | D9: 750000 | E9: =C9/D9 -> 1.04 | F9: 750000 | G9: =D9+25000 -> 775000 | H9: =F9/G9 -> 0.96774194 | I9: 900000 | J9: =G9+25000 -> 800000 | K9: =I9/J9 -> 1.125 | M9: =J9+25000 -> 825000 | N9: =L9/M9 -> 0 | O9: =SUM(L9,I9,F9,C9) -> 2430000 | P9: =SUM(M9,J9,G9,D9) -> 3150000 | Q9: =O9/P9 -> 0.77142857
B10: Total Bookings | C10: =sum(C7:C9) -> 2055000 | D10: =sum(D7:D9) -> 2000000 | E10: =C10/D10 -> 1.0275 | F10: =sum(F7:F9) -> 1950000 | G10: =sum(G7:G9) -> 2075000 | H10: =F10/G10 -> 0.93975904 | I10: =sum(I7:I9) -> 2175000 | J10: =sum(J7:J9) -> 2150000 | K10: =I10/J10 -> 1.0116279 | L10: =sum(L7:L9) -> 0 | M10: =sum(M7:M9) -> 2225000 | N10: =L10/M10 -> 0 | O10: =sum(O7:O9) -> 6180000 | P10: =sum(P7:P9) -> 8450000 | Q10: =O10/P10 -> 0.73136095
B13: Pods (New Biz only)
C14: January | F14: February | I14: March | L14: April | O14: T1
C15: Actuals | D15: Goal | E15: % to Goal | F15: Actuals | G15: Goal | H15: % to Goal | I15: Actuals | J15: Goal | K15: % to Goal | L15: Actuals | M15: Goal | N15: % to Goal | O15: Actuals | P15: Goal | Q15: % to Goal
B16: Pod 1 | C16: =C7*0.4 -> 380000 | D16: =D7/3 -> 333333.33 | E16: =C16/D16 -> 1.14 | F16: =F7*0.4 -> 440000 | G16: =G7/3 -> 350000 | H16: =F16/G16 -> 1.2571429 | I16: =I7*0.4 -> 400000 | J16: =J7/3 -> 366666.67 | K16: =I16/J16 -> 1.0909091 | M16: =M7/3 -> 383333.33 | N16: =L16/M16 -> 0 | O16: =SUM(L16,I16,F16,C16) -> 1220000 | P16: =SUM(M16,J16,G16,D16) -> 1433333.3 | Q16: =O16/P16 -> 0.85116279
B17: Pod 2 | C17: =C7*0.35 -> 332500 | D17: =D16 -> 333333.33 | E17: =C17/D17 -> 0.9975 | F17: =F7*0.35 -> 385000 | G17: =G16 -> 350000 | H17: =F17/G17 -> 1.1 | I17: =I7*0.35 -> 350000 | J17: =J16 -> 366666.67 | K17: =I17/J17 -> 0.95454545 | M17: =M16 -> 383333.33 | N17: =L17/M17 -> 0 | O17: =SUM(L17,I17,F17,C17) -> 1067500 | P17: =SUM(M17,J17,G17,D17) -> 1433333.3 | Q17: =O17/P17 -> 0.74476744
B18: Pod 3 | C18: =C7*0.25 -> 237500 | D18: =D17 -> 333333.33 | E18: =C18/D18 -> 0.7125 | F18: =F7*0.25 -> 275000 | G18: =G17 -> 350000 | H18: =F18/G18 -> 0.78571429 | I18: =I7*0.25 -> 250000 | J18: =J17 -> 366666.67 | K18: =I18/J18 -> 0.68181818 | M18: =M17 -> 383333.33 | N18: =L18/M18 -> 0 | O18: =SUM(L18,I18,F18,C18) -> 762500 | P18: =SUM(M18,J18,G18,D18) -> 1433333.3 | Q18: =O18/P18 -> 0.53197674
B19: Pod 4 (International) | C19: =C8 -> 325000 | D19: =D8 -> 250000 | E19: =C19/D19 -> 1.3 | F19: =F8 -> 100000 | G19: =G8 -> 250000 | H19: =F19/G19 -> 0.4 | I19: =I8 -> 275000 | J19: =J8 -> 250000 | K19: =I19/J19 -> 1.1 | M19: =M8 -> 250000 | N19: =L19/M19 -> 0 | O19: =SUM(L19,I19,F19,C19) -> 700000 | P19: =SUM(M19,J19,G19,D19) -> 1000000 | Q19: =O19/P19 -> 0.7
B20: Total Bookings (New Biz) | C20: =sum(C16:C19) -> 1275000 | D20: =sum(D16:D19) -> 1250000 | E20: =C20/D20 -> 1.02 | F20: =sum(F16:F19) -> 1200000 | G20: =sum(G16:G19) -> 1300000 | H20: =F20/G20 -> 0.92307692 | I20: =sum(I16:I19) -> 1275000 | J20: =sum(J16:J19) -> 1350000 | K20: =I20/J20 -> 0.94444444 | L20: =sum(L16:L19) -> 0 | M20: =sum(M16:M19) -> 1400000 | N20: =L20/M20 -> 0 | O20: =sum(O16:O19) -> 3750000 | P20: =sum(P16:P19) -> 5300000 | Q20: =O20/P20 -> 0.70754717
C23: January | D23: February | E23: March | F23: April | G23: Goal
B24: Intro Calls (Client Count) | C24: 250 | D24: 260 | E24: 240
B25: Intro Close Rate (Trailing 3 mo) | C25: =C28/C24 -> 0.048 | D25: =D28/D24 -> 0.057692308 | E25: =E28/E24 -> 0.083333333 | F25: =F28/F24 -> #DIV/0! | G25: 0.07
B26: Proposals (Client Count) | C26: 80 | D26: 60 | E26: 70
B27: Proposal Close Rate (Trailing 3 mo) | C27: =C28/C26 -> 0.15 | D27: =D28/D26 -> 0.25 | E27: =E28/E26 -> 0.28571429 | F27: =F28/F26 -> #DIV/0! | G27: 0.3
B28: Deals Closed | C28: 12 | D28: 15 | E28: 20
B30: LTV | C30: 120000 | D30: 130000 | E30: 125000 | G30: 90000
B31: CAC | C31: 45000 | D31: 50000 | E31: 55000 | G31: 30000
B32: LTV:CAC ratio | C32: =C30/C31 -> 2.6666667 | D32: =D30/D31 -> 2.6 | E32: =E30/E31 -> 2.2727273 | F32: =F30/F31 -> #DIV/0! | G32: 3
B33: CAC Payback period (Months) | C33: =C31/(C30/(C79*12)) -> 6.9551777 | D33: =D31/(D30/(D79*12)) -> 6.8650671 | E33: =E31/(E30/(E79*12)) -> 7.8536368 | F33: =F31/(F30/(F79*12)) -> #DIV/0!
B36: RETENTION
B38: Renewals & Opt-Outs
C39: January | D39: February | E39: March | F39: April | G39: T1 | H39: Goal
B40: Contracts Up for Renewal | C40: 10 | D40: 5 | E40: 15 | F40: 20 | G40: =SUM(C40:F40) -> 50
B41: Contracts Renewed | C41: 8 | D41: 2 | E41: 10 | G41: =SUM(C41:F41) -> 20
B42: Contract Renewal Rate | C42: =C41/C40 -> 0.8 | D42: =D41/D40 -> 0.4 | E42: =E41/E40 -> 0.66666667 | F42: =F41/F40 -> 0 | G42: =G41/G40 -> 0.4 | H42: 0.65
B43: Bookings Up for Renewal | C43: 1279500 | D43: 500000 | E43: 1195500 | F43: 2000000 | G43: =SUM(C43:F43) -> 4975000
B44: Existing Bookings Renewed | C44: 1000000 | D44: 250000 | E44: 800000 | G44: =SUM(C44:F44) -> 2050000
B45: Additional Bookings Renewed | C45: 60000 | D45: 0 | E45: 0 | G45: =SUM(C45:F45) -> 60000
B46: Churned Bookings | C46: =C43-C44 -> 279500 | D46: =D43-D44 -> 250000 | E46: =E43-E44 -> 395500 | G46: =SUM(C46:F46) -> 925000
B47: Bookings Renewal Rate | C47: =SUM(C44:C45)/C43 -> 0.82844861 | D47: =SUM(D44:D45)/D43 -> 0.5 | E47: =SUM(E44:E45)/E43 -> 0.66917608 | F47: =SUM(F44:F45)/F43 -> 0 | G47: =SUM(G44:G45)/G43 -> 0.4241206 | H47: 0.65
B49: Opt-Out Contracts At Risk | C49: 8 | D49: 2 | E49: 0 | F49: 5 | G49: =SUM(C49:F49) -> 15
B50: Opt-Out Contracts Retained | C50: 7 | D50: 1 | E50: 0 | G50: =SUM(C50:F50) -> 8
B51: Opt-Out Contract Retained Rate | C51: =C50/C49 -> 0.875 | D51: =D50/D49 -> 0.5 | E51: =E50/E49 -> #DIV/0! | F51: =F50/F49 -> 0 | G51: =G50/G49 -> 0.53333333 | H51: 0.8
...
