Workbook

Sheet Paid Media
B1: Labor Supply Model for Paid Media @ Directive | CW1: https://goo.gl/4UV8Cz
K2: =C5 -> Sales- Drew or Derek | BA2: Hiring | CQ2: Learning
B3: TASK ID | C3: Function | D3: Triggers | E3: TASK OWNER | F3: Historical Days | G3: March | H3: April | I3: Target Days | J3: PCT TO TARGET | K3: WEEK 1 | R3: WEEK 2 | Y3: WEEK 3 | AF3: WEEK 4 | AM3: WEEK 5 | AT3: WEEK 6 | BA3: WEEK 7 | BH3: WEEK 8 | BO3: WEEK 9 | BV3: WEEK 10 | CC3: WEEK 11 | CJ3: WEEK 12 | CQ3: WEEK 13 | CX3: WEEK 14 | DE3: WEEK 15
K4: 1 | L4: =K4+1 -> 2 | M4: =L4+1 -> 3 | N4: =M4+1 -> 4 | O4: =N4+1 -> 5 | P4: =O4+1 -> 6 | Q4: =P4+1 -> 7 | R4: =Q4+1 -> 8 | S4: =R4+1 -> 9 | ... CP4: =CO4+1 -> 84 | CQ4: =BU4+1 -> 64 | CR4: =CQ4+1 -> 65 | CS4: =CR4+1 -> 66 | CT4: =CS4+1 -> 67 | CU4: =CT4+1 -> 68 | CV4: =CU4+1 -> 69 | CW4: =CV4+1 -> 70 | CX4: =CW4+1 -> 71 | CY4: =CX4+1 -> 72 | ... DK4: =DJ4+1 -> 84
B5: 1 | C5: Sales- Drew or Derek | F5: =SUM(F6:F11) -> 76.8 | G5: =SUM(G6:G11) -> 67 | I5: =SUM(I6:I11) -> 50
B6: 1.1 | C6: Intro Call Held (22 > 1) | D6: Leading (req created) | E6: Sales Team | F6: 5 | G6: 5 | H6: 4 | I6: 5 | J6: =I6/F6 -> 1
B7: 1.1.1 | C7: Strategy Call Held (6>1) | E7: Sales Team | F7: 10 | G7: 8 | H7: 8 | I7: 4 | J7: =I7/F7 -> 0.4
B8: 1.2 | C8: Proposal Held | E8: Sales Team | F8: 11 | G8: 10 | H8: 8 | I8: 5 | J8: =I8/F8 -> 0.45454545
B9: 1.3 | C9: SOW Held (3 > 1) | D9: Closing (offer out) | E9: Sales Team | F9: 13 | G9: 7 | H9: 5.2 | I9: 5 | J9: =I9/F9 -> 0.38461538
B10: 1.4 | C10: Closed Won | E10: Sales Team | F10: 21.8 | G10: 24 | H10: 31.5 | I10: 21 | J10: =I10/F10 -> 0.96330275
B11: 1.5 | C11: Kickoff Call | E11: Sales Team | F11: 16 | G11: 13 | I11: 10 | J11: =I11/F11 -> 0.625
B12: 2 | C12: Hiring- Haley | F12: =SUM(F13:F19) -> 60 | G12: 25 | H12: 25 | I12: 25
B13: 2.1 | C13: Req Created | E13: Talent Aquisition | F13: 1 | G13: 1 | H13: 1 | I13: 1 | J13: =I13/F13 -> 1
B14: 2.2 | C14: Screen Interview (32 > 1) "want 22>1" | E14: Talent Aquisition | F14: 21 | G14: 14 | H14: 14 | I14: 1 | J14: =I14/F14 -> 0.047619048
B15: 2.3 | C15: Who Interview | E15: Hiring Manager | F15: 4 | G15: 3 | H15: 3 | I15: 3 | J15: =I15/F15 -> 0.75
B16: 2.4 | C16: Presentation/Focused | E16: Hiring Manager | F16: 5 | G16: 4 | H16: 4 | I16: 4 | J16: =I16/F16 -> 0.8
B17: 2.5 | C17: Offer Letter Sent | E17: Talent Aquisition | F17: 1 | G17: 1 | H17: 1 | I17: 1 | J17: =I17/F17 -> 1
B18: 2.6 | C18: Omnipresent Onboarding | E18: Omnipresent | F18: 14 | G18: 14 | H18: 14 | I18: 14 | J18: =I18/F18 -> 1
B19: 2.7 | C19: Start Date | E19: Candidate | F19: 14 | G19: 14 | H19: 14 | I19: 1 | J19: =I19/F19 -> 0.071428571
B20: 3 | C20: Learning- Gus | F20: =SUM(F21:F28) -> 32 | G20: =SUM(G21:G28) -> 29 | I20: =SUM(I21:I28) -> 22
B21: 3.1 | C21: Directive Foundations | E21: L&D | F21: 5 | G21: 5 | I21: 5 | J21: =I21/F21 -> 1
B22: 3.2 | C22: Who Presentation | F22: 6 | G22: 5 | I22: 3 | J22: =I22/F22 -> 0.5
B23: 3.3 | C23: Account Audit | F23: 2 | G23: 2 | I23: 2 | J23: =I23/F23 -> 1
B24: 3.4 | C24: LTV:CAC | E24: L&D | F24: 6 | G24: 2 | I24: 3 | J24: =I24/F24 -> 0.5
B25: 3.5 | C25: NSM Setting | E25: L&D | F25: 2 | G25: 2 | I25: 2 | J25: =I25/F25 -> 1
B26: 3.6 | C26: Growth Assessment | E26: L&D | F26: 4 | G26: 5 | I26: 2 | J26: =I26/F26 -> 0.5
B27: 3.7 | C27: Mock Strategy Presentation | E27: L&D | F27: 4 | G27: 5 | I27: 2 | J27: =I27/F27 -> 0.5
B28: 3.8 | C28: 1st Client Assigned | E28: Director | F28: 3 | G28: 3 | I28: 3 | J28: =I28/F28 -> 1
B29: 4 | C29: Development- Gus | F29: =SUM(F30:F33) -> 115 | G29: =SUM(G30:G33) -> 107 | I29: =SUM(I30:I33) -> 93
B30: 4.1 | C30: Complete 30-Day Onboarding Checklist | E30: AsD | F30: 34 | G30: 32 | I30: 30 | J30: =I30/F30 -> 0.88235294
B31: 4.2 | C31: Complete 60-Day Onboarding Checklist | E31: AsD | F31: 40 | G31: 38 | I31: 30 | J31: =I31/F31 -> 0.75
B32: 4.3 | C32: Complete 90-Day Onboarding Checklist | E32: AsD | F32: 38 | G32: 34 | I32: 30 | J32: =I32/F32 -> 0.78947368
B33: 4.4 | C33: Get 2nd Client | E33: Director | F33: 3 | G33: 3 | I33: 3 | J33: =I33/F33 -> 1
C35: Operational Rep- Paulina & Jacob

Sheet SEO
B1: Labor Supply Model for SEO @ Directive | CY1: https://goo.gl/4UV8Cz
M2: =C5 -> Sales | BC2: Hiring | CS2: Learning
B3: TASK ID | C3: Function | D3: Triggers | E3: TASK OWNER | F3: Historical Days | G3: March | H3: April | I3: May | J3: June | K3: Target Days | L3: PCT TO TARGET | M3: WEEK 1 | T3: WEEK 2 | AA3: WEEK 3 | AH3: WEEK 4 | AO3: WEEK 5 | AV3: WEEK 6 | BC3: WEEK 7 | BJ3: WEEK 8 | BQ3: WEEK 9 | BX3: WEEK 10 | CE3: WEEK 11 | CL3: WEEK 12 | CS3: WEEK 13 | CZ3: WEEK 14 | DG3: WEEK 15
M4: 1 | N4: =M4+1 -> 2 | O4: =N4+1 -> 3 | P4: =O4+1 -> 4 | Q4: =P4+1 -> 5 | R4: =Q4+1 -> 6 | S4: =R4+1 -> 7 | T4: =S4+1 -> 8 | U4: =T4+1 -> 9 | ... CR4: =CQ4+1 -> 84 | CS4: =BW4+1 -> 64 | CT4: =CS4+1 -> 65 | CU4: =CT4+1 -> 66 | CV4: =CU4+1 -> 67 | CW4: =CV4+1 -> 68 | CX4: =CW4+1 -> 69 | CY4: =CX4+1 -> 70 | CZ4: =CY4+1 -> 71 | DA4: =CZ4+1 -> 72 | ... DM4: =DL4+1 -> 84
B5: 1 | C5: Sales | F5: =SUM(F6:F11) -> 92 | G5: =SUM(G6:G11) -> 65.5 | K5: =SUM(K6:K11) -> 50
B6: 1.1 | C6: Intro Call Held (22 > 1) | D6: Leading (req created) | F6: 6 | G6: 7 | H6: 4 | K6: 5 | L6: =K6/F6 -> 0.83333333
B7: 1.1.1 | C7: Strategy Call Held | F7: 11.8 | G7: 7 | H7: 6 | K7: 4 | L7: =K7/F7 -> 0.33898305
B8: 1.2 | C8: Proposal Held | F8: 11.9 | G8: 14 | H8: 7 | K8: 5 | L8: =K8/F8 -> 0.42016807
B9: 1.3 | C9: SOW Held (6 > 1) | D9: Closing (offer out) | F9: 12.7 | G9: 11 | H9: 5.7 | K9: 5 | L9: =K9/F9 -> 0.39370079
B10: 1.4 | C10: Closed Won | F10: 33.6 | G10: 13.5 | H10: 16 | K10: 21 | L10: =K10/F10 -> 0.625
B11: 1.5 | C11: Kickoff Call | F11: 16 | G11: 13 | K11: 10 | L11: =K11/F11 -> 0.625
B12: 2 | C12: Hiring | F12: =SUM(F13:F19) -> 47 | G12: 38 | H12: 38 | K12: 25
B13: 2.1 | C13: Req Created | E13: Haley | F13: 1 | G13: 1 | H13: 1 | K13: 1 | L13: =K13/F13 -> 1
B14: 2.2 | C14: Screen Interview (32 > 1) "want 22>1" | E14: Haley | F14: 21 | G14: 14 | H14: 14 | K14: 1 | L14: =K14/F14 -> 0.047619048
B15: 2.3 | C15: Who Interview | E15: Director/AD | F15: 4 | G15: 3 | H15: 3 | K15: 3 | L15: =K15/F15 -> 0.75
B16: 2.4 | C16: Presentation/Focused | E16: Jesse/Director | F16: 5 | G16: 4 | H16: 4 | K16: 4 | L16: =K16/F16 -> 0.8
B17: 2.5 | C17: Offer Letter Sent | E17: Recruiter | F17: 1 | G17: 1 | H17: 1 | K17: 1 | L17: =K17/F17 -> 1
B18: 2.6 | C18: Omnipresent Onboarding | E18: Candidate | F18: 1 | G18: 1 | H18: 1 | K18: 14 | L18: =K18/F18 -> 14
B19: 2.7 | C19: Start Date | E19: Candidate | F19: 14 | G19: 14 | H19: 14 | K19: 1 | L19: =K19/F19 -> 0.071428571
B20: 3 | C20: Learning | F20: =SUM(F21:F26) -> 20 | G20: =SUM(G21:G26) -> 20 | K20: =SUM(K21:K26) -> 12
B21: 3.1 | C21: Who Presentation | E21: L&D | F21: 5 | G21: 5 | K21: 1 | L21: =K21/F21 -> 0.2
B22: 3.2 | C22: KWR Phase 1 & 2 | E22: L&D | F22: 5 | G22: 5 | K22: 2 | L22: =K22/F22 -> 0.4
B23: 3.3 | C23: Core Page Audit | E23: L&D | F23: 4 | G23: 4 | K23: 2 | L23: =K23/F23 -> 0.5
B24: 3.4 | C24: Content Audit | E24: L&D | F24: 4 | G24: 4 | K24: 2 | L24: =K24/F24 -> 0.5
B25: 3.5 | C25: Mock Strategy Presentation | E25: L&D | F25: 2 | G25: 2 | K25: 2 | L25: =K25/F25 -> 1
B26: 3.6 | C26: 1st Client Assigned | E26: Director | F26: - | G26: - | K26: 3 | L26: =K26/F26 -> #VALUE!
B27: 4 | C27: Development | F27: =SUM(F28:F35) -> 0 | K27: =SUM(K28:K35) -> 49
B28: 4.1 | C28: Complete Directive Pillars | E28: L&D | F28: - | K28: 18 | L28: 0
B29: 4.1.1 | C29: Complete All Identified Training | E29: L&D
B30: 4.1.2 | C30: Signed Off on All Products/Platforms | E30: L&D
B31: 4.1.3 | C31: Signed Off on All Processes | E31: L&D
B32: 4.2 | C32: 30% BUR | E32: AsD
B33: 4.3 | C33: 60% BUR | E33: AsD | F33: - | K33: 14 | L33: 0
B34: 4.4 | C34: 90% BUR | E34: AsD | K34: 14
B35: 4.5 | C35: Get 2nd Client | E35: AsD | F35: - | K35: 3 | L35: 0

Sheet Creative
B1: Labor Supply Model for Creative @ Directive | CY1: https://goo.gl/4UV8Cz
M2: =C5 -> Sales | BC2: Hiring | CS2: Learning
B3: TASK ID | C3: Function | D3: Triggers | E3: TASK OWNER | F3: Historical Days | G3: March | H3: April | I3: May | J3: June | K3: Target Days | L3: PCT TO TARGET | M3: WEEK 1 | T3: WEEK 2 | AA3: WEEK 3 | AH3: WEEK 4 | AO3: WEEK 5 | AV3: WEEK 6 | BC3: WEEK 7 | BJ3: WEEK 8 | BQ3: WEEK 9 | BX3: WEEK 10 | CE3: WEEK 11 | CL3: WEEK 12 | CS3: WEEK 13 | CZ3: WEEK 14 | DG3: WEEK 15
M4: 1 | N4: =M4+1 -> 2 | O4: =N4+1 -> 3 | P4: =O4+1 -> 4 | Q4: =P4+1 -> 5 | R4: =Q4+1 -> 6 | S4: =R4+1 -> 7 | T4: =S4+1 -> 8 | U4: =T4+1 -> 9 | ... CR4: =CQ4+1 -> 84 | CS4: =BW4+1 -> 64 | CT4: =CS4+1 -> 65 | CU4: =CT4+1 -> 66 | CV4: =CU4+1 -> 67 | CW4: =CV4+1 -> 68 | CX4: =CW4+1 -> 69 | CY4: =CX4+1 -> 70 | CZ4: =CY4+1 -> 71 | DA4: =CZ4+1 -> 72 | ... DM4: =DL4+1 -> 84
B5: 1 | C5: Sales | F5: =SUM(F6:F11) -> 66.3 | G5: =SUM(G6:G11) -> 63 | K5: =SUM(K6:K11) -> 50
B6: 1.1 | C6: Intro Call Held (22 > 1) | D6: Leading (req created) | F6: 6.7 | G6: 5 | H6: 6 | K6: 5 | L6: =K6/F6 -> 0.74626866
B7: 1.1.1 | C7: Strategy Call Held | F7: 7.6 | G7: 6 | H7: 5 | K7: 4 | L7: =K7/F7 -> 0.52631579
B8: 1.2 | C8: Proposal Held | F8: 11.4 | G8: 9 | H8: 8 | K8: 5 | L8: =K8/F8 -> 0.43859649
B9: 1.3 | C9: SOW Held (6 > 1) | D9: Closing (offer out) | F9: 10.1 | G9: 6 | H9: 5.4 | K9: 5 | L9: =K9/F9 -> 0.49504951
B10: 1.4 | C10: Closed Won | F10: 14.5 | G10: 24 | H10: 31.5 | K10: 21 | L10: =K10/F10 -> 1.4482759
B11: 1.5 | C11: Kickoff Call | F11: 16 | G11: 13 | K11: 10 | L11: =K11/F11 -> 0.625
B12: 2 | C12: Hiring | F12: =SUM(F13:F19) -> 47 | G12: 38 | H12: 38 | K12: 25
B13: 2.1 | C13: Req Created | E13: Haley | F13: 1 | G13: 1 | H13: 1 | K13: 1 | L13: =K13/F13 -> 1
B14: 2.2 | C14: Screen Interview (32 > 1) "want 22>1" | E14: Haley | F14: 21 | G14: 14 | H14: 15 | K14: 1 | L14: =K14/F14 -> 0.047619048
B15: 2.3 | C15: Who Interview | E15: Director/AD | F15: 4 | G15: 3 | H15: - | K15: 3 | L15: =K15/F15 -> 0.75
B16: 2.4 | C16: Presentation/Focused | E16: Jesse/Director | F16: 5 | G16: 4 | H16: 12 | K16: 4 | L16: =K16/F16 -> 0.8
B17: 2.5 | C17: Offer Letter Sent | E17: Recruiter | F17: 1 | G17: 1 | H17: 1 | K17: 1 | L17: =K17/F17 -> 1
B18: 2.6 | C18: Omnipresent Onboarding | E18: Candidate | F18: 1 | G18: 1 | H18: 14 | K18: 14 | L18: =K18/F18 -> 14
B19: 2.7 | C19: Start Date | E19: Candidate | F19: 14 | G19: 14 | H19: 1 | K19: 1 | L19: =K19/F19 -> 0.071428571
B20: 3 | C20: Learning | F20: =SUM(F21:F26) -> 28 | G20: =SUM(G21:G26) -> 0 | K20: =SUM(K21:K26) -> 15
B21: 3.1 | C21: Who Presentation | E21: L&D | F21: 7 | J21: 3 | K21: 3 | L21: =K21/F21 -> 0.42857143
B22: 3.2 | C22: Account Audit | E22: L&D | F22: 4 | J22: 0 | K22: 2 | L22: =K22/F22 -> 0.5
B23: 3.3 | C23: Brand Messaging + Positioning | E23: L&D | K23: 3 | L23: =K23/F23 -> #DIV/0!
B24: 3.4 | C24: Design Mockup Presentation | E24: L&D | F24: 10 | K24: 1 | L24: =K24/F24 -> 0.1
B25: 3.5 | C25: Mock Strategy Presentation | E25: L&D | F25: 7 | K25: 3 | L25: =K25/F25 -> 0.42857143
B26: 3.6 | C26: 1st Client Assigned | E26: Director | K26: 3 | L26: =K26/F26 -> #DIV/0!
B27: 4 | C27: Development | F27: =SUM(F28:F35) -> 0 | K27: =SUM(K28:K35) -> 49
B28: 4.1 | C28: Complete Directive Pillars | E28: L&D | F28: - | K28: 18 | L28: 0
B29: 4.1.1 | C29: Complete All Identified Training | E29: L&D
B30: 4.1.2 | C30: Signed Off on All Products/Platforms | E30: L&D
B31: 4.1.3 | C31: Signed Off on All Processes | E31: L&D
B32: 4.2 | C32: 30% BUR | E32: AsD
B33: 4.3 | C33: 60% BUR | E33: AsD | F33: - | K33: 14 | L33: 0
B34: 4.4 | C34: 90% BUR | E34: AsD | K34: 14
B35: 4.5 | C35: Get 2nd Client | E35: AsD | F35: - | K35: 3 | L35: 0

Sheet Video
B1: Labor Supply Model for Video @ Directive | CW1: https://goo.gl/4UV8Cz
K2: =C5 -> Sales | BA2: Hiring | CQ2: Learning
B3: TASK ID | C3: Function | D3: Triggers | E3: TASK OWNER | F3: Historical Days | G3: March | H3: April | I3: Target Days | J3: PCT TO TARGET | K3: WEEK 1 | R3: WEEK 2 | Y3: WEEK 3 | AF3: WEEK 4 | AM3: WEEK 5 | AT3: WEEK 6 | BA3: WEEK 7 | BH3: WEEK 8 | BO3: WEEK 9 | BV3: WEEK 10 | CC3: WEEK 11 | CJ3: WEEK 12 | CQ3: WEEK 13 | CX3: WEEK 14 | DE3: WEEK 15
K4: 1 | L4: =K4+1 -> 2 | M4: =L4+1 -> 3 | N4: =M4+1 -> 4 | O4: =N4+1 -> 5 | P4: =O4+1 -> 6 | Q4: =P4+1 -> 7 | R4: =Q4+1 -> 8 | S4: =R4+1 -> 9 | ... CP4: =CO4+1 -> 84 | CQ4: =BU4+1 -> 64 | CR4: =CQ4+1 -> 65 | CS4: =CR4+1 -> 66 | CT4: =CS4+1 -> 67 | CU4: =CT4+1 -> 68 | CV4: =CU4+1 -> 69 | CW4: =CV4+1 -> 70 | CX4: =CW4+1 -> 71 | CY4: =CX4+1 -> 72 | ... DK4: =DJ4+1 -> 84
B5: 1 | C5: Sales | F5: =SUM(F6:F11) -> 67 | G5: =SUM(G6:G11) -> 70 | I5: =SUM(I6:I11) -> 50
B6: 1.1 | C6: Intro Call Held (22 > 1) | D6: Leading (req created) | F6: 8 | G6: 11 | H6: 3 | I6: 5 | J6: =I6/F6 -> 0.625
B7: 1.1.1 | C7: Strategy Call Held | F7: 14 | G7: 7 | H7: 11 | I7: 4 | J7: =I7/F7 -> 0.28571429
B8: 1.2 | C8: Proposal Held | F8: 12 | G8: 9 | H8: 18 | I8: 5 | J8: =I8/F8 -> 0.41666667
B9: 1.3 | C9: SOW Held (6 > 1) | D9: Closing (offer out) | F9: 8 | G9: 8 | H9: 6 | I9: 5 | J9: =I9/F9 -> 0.625
B10: 1.5 | C10: Closed Won | F10: 9 | G10: 22 | H10: 9 | I10: 21 | J10: =I10/F10 -> 2.3333333
B11: 1.6 | C11: Kickoff Call | F11: 16 | G11: 13 | I11: 10 | J11: =I11/F11 -> 0.625
B12: 2 | C12: Hiring | F12: =SUM(F13:F19) -> 47 | H12: 49 | I12: 25
B13: 2.1 | C13: Req Created | E13: Haley | F13: 1 | G13: 1 | H13: 1 | I13: 1 | J13: =I13/F13 -> 1
B14: 2.2 | C14: Screen Interview (32 > 1) "want 22>1" | E14: Haley | F14: 21 | G14: 14 | H14: 3 | I14: 1 | J14: =I14/F14 -> 0.047619048
B15: 2.3 | C15: Who Interview | E15: Director/AD | F15: 4 | G15: 3 | H15: - | I15: 3 | J15: =I15/F15 -> 0.75
B16: 2.4 | C16: Presentation/Focused | E16: Jesse/Director | F16: 5 | G16: 4 | H16: 9 | I16: 4 | J16: =I16/F16 -> 0.8
B17: 2.5 | C17: Offer Letter Sent | E17: Recruiter | F17: 1 | G17: 1 | H17: 1 | I17: 1 | J17: =I17/F17 -> 1
B18: 2.6 | C18: Omnipresent Onboarding | E18: Candidate | F18: 1 | G18: 1 | H18: 15 | I18: 14 | J18: =I18/F18 -> 14
B19: 2.7 | C19: Start Date | E19: Candidate | F19: 14 | G19: 14 | H19: 14 | I19: 1 | J19: =I19/F19 -> 0.071428571
B20: 3 | C20: Learning | F20: =SUM(F21:F26) -> 28 | G20: =SUM(G21:G26) -> 23 | I20: =SUM(I21:I26) -> 15
B21: 3.1 | C21: Who Presentation | E21: L&D | F21: 16 | G21: 11 | I21: 3 | J21: =I21/F21 -> 0.1875
B22: 3.2 | C22: Account Audit | E22: L&D | F22: 4 | G22: 3 | I22: 2 | J22: =I22/F22 -> 0.5
B23: 3.3 | C23: LTV:CAC | E23: L&D | F23: 5 | G23: 5 | I23: 3 | J23: =I23/F23 -> 0.6
B24: 3.4 | C24: NSM Setting | E24: L&D | F24: - | G24: - | I24: 1 | J24: =I24/F24 -> #VALUE!
B25: 3.5 | C25: Mock Strategy Presentation | E25: L&D | F25: 3 | G25: 4 | I25: 3 | J25: =I25/F25 -> 1
B26: 3.6 | C26: 1st Client Assigned | E26: Director | F26: - | G26: - | I26: 3 | J26: =I26/F26 -> #VALUE!
B27: 4 | C27: Development | F27: =SUM(F28:F35) -> 0 | I27: =SUM(I28:I35) -> 49
B28: 4.1 | C28: Complete Directive Pillars | E28: L&D | F28: - | I28: 18 | J28: 0
B29: 4.1.1 | C29: Complete All Identified Training | E29: L&D
B30: 4.1.2 | C30: Signed Off on All Products/Platforms | E30: L&D
B31: 4.1.3 | C31: Signed Off on All Processes | E31: L&D
B32: 4.2 | C32: 30% BUR | E32: AsD
B33: 4.3 | C33: 60% BUR | E33: AsD | F33: - | I33: 14 | J33: 0
B34: 4.4 | C34: 90% BUR | E34: AsD | I34: 14
B35: 4.5 | C35: Get 2nd Client | E35: AsD | F35: - | I35: 3 | J35: 0

Sheet RevOps
B1: Labor Supply Model for RevOps @ Directive | CW1: https://goo.gl/4UV8Cz
K2: =C5 -> Sales | BA2: Hiring | CQ2: Learning
B3: TASK ID | C3: Function | D3: Triggers | E3: TASK OWNER | F3: Historical Days | G3: March | H3: April | I3: Target Days | J3: PCT TO TARGET | K3: WEEK 1 | R3: WEEK 2 | Y3: WEEK 3 | AF3: WEEK 4 | AM3: WEEK 5 | AT3: WEEK 6 | BA3: WEEK 7 | BH3: WEEK 8 | BO3: WEEK 9 | BV3: WEEK 10 | CC3: WEEK 11 | CJ3: WEEK 12 | CQ3: WEEK 13 | CX3: WEEK 14 | DE3: WEEK 15
K4: 1 | L4: =K4+1 -> 2 | M4: =L4+1 -> 3 | N4: =M4+1 -> 4 | O4: =N4+1 -> 5 | P4: =O4+1 -> 6 | Q4: =P4+1 -> 7 | R4: =Q4+1 -> 8 | S4: =R4+1 -> 9 | ... CP4: =CO4+1 -> 84 | CQ4: =BU4+1 -> 64 | CR4: =CQ4+1 -> 65 | CS4: =CR4+1 -> 66 | CT4: =CS4+1 -> 67 | CU4: =CT4+1 -> 68 | CV4: =CU4+1 -> 69 | CW4: =CV4+1 -> 70 | CX4: =CW4+1 -> 71 | CY4: =CX4+1 -> 72 | ... DK4: =DJ4+1 -> 84
B5: 1 | C5: Sales | F5: =SUM(F6:F11) -> 61 | G5: =SUM(G6:G11) -> 72 | I5: =SUM(I6:I11) -> 50
B6: 1.1 | C6: Intro Call Held (22 > 1) | D6: Leading (req created) | F6: 7 | G6: 8 | H6: 4 | I6: 5 | J6: =I6/F6 -> 0.71428571
B7: 1.1.1 | C7: Strategy Call Held | F7: 10 | G7: 9 | H7: 8 | I7: 4 | J7: =I7/F7 -> 0.4
B8: 1.2 | C8: Proposal Held | F8: 11 | G8: 10 | H8: 8 | I8: 5 | J8: =I8/F8 -> 0.45454545
B9: 1.3 | C9: SOW Held (6 > 1) | D9: Closing (offer out) | F9: 10 | G9: 8 | H9: 5.8 | I9: 5 | J9: =I9/F9 -> 0.5
B10: 1.5 | C10: Closed Won | F10: 7 | G10: 24 | H10: 35.5 | I10: 21 | J10: =I10/F10 -> 3
B11: 1.6 | C11: Kickoff Call | F11: 16 | G11: 13 | I11: 10 | J11: =I11/F11 -> 0.625
B12: 2 | C12: Hiring | F12: =SUM(F13:F19) -> 47 | H12: 68 | I12: 25
B13: 2.1 | C13: Req Created | E13: Haley | F13: 1 | G13: 1 | H13: 1 | I13: 1 | J13: =I13/F13 -> 1
B14: 2.2 | C14: Screen Interview (32 > 1) "want 22>1" | E14: Haley | F14: 21 | G14: 14 | H14: 4 | I14: 1 | J14: =I14/F14 -> 0.047619048
B15: 2.3 | C15: Who Interview | E15: Director/AD | F15: 4 | G15: 3 | H15: 6 | I15: 3 | J15: =I15/F15 -> 0.75
B16: 2.4 | C16: Presentation/Focused | E16: Jesse/Director | F16: 5 | G16: 4 | H16: 8 | I16: 4 | J16: =I16/F16 -> 0.8
B17: 2.5 | C17: Offer Letter Sent | E17: Recruiter | F17: 1 | G17: 1 | H17: 6 | I17: 1 | J17: =I17/F17 -> 1
B18: 2.6 | C18: Omnipresent Onboarding | E18: Candidate | F18: 1 | G18: 1 | H18: 10 | I18: 14 | J18: =I18/F18 -> 14
B19: 2.7 | C19: Start Date | E19: Candidate | F19: 14 | G19: 14 | H19: 20 | I19: 1 | J19: =I19/F19 -> 0.071428571
B20: 3 | C20: Learning | F20: =SUM(F21:F26) -> 28 | G20: =SUM(G21:G26) -> 23 | I20: =SUM(I21:I26) -> 15
B21: 3.1 | C21: Who Presentation | E21: L&D | F21: 16 | G21: 11 | I21: 3 | J21: =I21/F21 -> 0.1875
B22: 3.2 | C22: Account Audit | E22: L&D | F22: 4 | G22: 3 | I22: 2 | J22: =I22/F22 -> 0.5
B23: 3.3 | C23: LTV:CAC | E23: L&D | F23: 5 | G23: 5 | I23: 3 | J23: =I23/F23 -> 0.6
B24: 3.4 | C24: NSM Setting | E24: L&D | F24: - | G24: - | I24: 1 | J24: =I24/F24 -> #VALUE!
B25: 3.5 | C25: Mock Strategy Presentation | E25: L&D | F25: 3 | G25: 4 | I25: 3 | J25: =I25/F25 -> 1
B26: 3.6 | C26: 1st Client Assigned | E26: Director | F26: - | G26: - | I26: 3 | J26: =I26/F26 -> #VALUE!
B27: 4 | C27: Development | F27: =SUM(F28:F35) -> 0 | I27: =SUM(I28:I35) -> 49
B28: 4.1 | C28: Complete Directive Pillars | E28: L&D | F28: - | I28: 18 | J28: 0
B29: 4.1.1 | C29: Complete All Identified Training | E29: L&D
B30: 4.1.2 | C30: Signed Off on All Products/Platforms | E30: L&D
B31: 4.1.3 | C31: Signed Off on All Processes | E31: L&D
B32: 4.2 | C32: 30% BUR | E32: AsD
B33: 4.3 | C33: 60% BUR | E33: AsD | F33: - | I33: 14 | J33: 0
B34: 4.4 | C34: 90% BUR | E34: AsD | I34: 14
B35: 4.5 | C35: Get 2nd Client | E35: AsD | F35: - | I35: 3 | J35: 0

Sheet Basic Gantt Chart BLANK
B1: BASIC GANTT CHART
B2: PROJECT TITLE | I2: COMPANY NAME
B3: PROJECT MANAGER | I3: DATE
I5: PHASE ONE | X5: PHASE TWO | AM5: PHASE THREE | BB5: PHASE FOUR
B6: TASK ID | C6: TASK TITLE | D6: TASK OWNER | E6: START DATE | F6: DUE DATE | G6: DURATION | H6: PCT OF TASK COMPLETE | I6: WEEK 1 | N6: WEEK 2 | S6: WEEK 3 | X6: WEEK 4 | AC6: WEEK 5 | AH6: WEEK 6 | AM6: WEEK 7 | AR6: WEEK 8 | AW6: WEEK 9 | BB6: WEEK 10 | BG6: WEEK 11 | BL6: WEEK 12
I7: M | J7: T | K7: W | L7: R | M7: F | N7: M | O7: T | P7: W | Q7: R | R7: F | S7: M | T7: T | U7: W | V7: R | W7: F | X7: M | Y7: T | Z7: W | AA7: R | AB7: F | AC7: M | AD7: T | AE7: W | AF7: R | AG7: F | AH7: M | AI7: T | AJ7: W | AK7: R | AL7: F | AM7: M | AN7: T | AO7: W | AP7: R | AQ7: F | AR7: M | AS7: T | AT7: W | AU7: R | AV7: F | AW7: M | AX7: T | AY7: W | AZ7: R | BA7: F | BB7: M | BC7: T | BD7: W | BE7: R | BF7: F | BG7: M | BH7: T | BI7: W | BJ7: R | BK7: F | BL7: M | BM7: T | BN7: W | BO7: R | BP7: F
B8: 1
B9: 1.1 | H9: 1
H10: 1
H11: 0.9
H12: 0.4
H13: 0.7
H14: 0.6
H15: 0.5
H17: 0.05
H18: 0.3
H19: 0
H20: 0
H22: 0.4
H23: 0
... H32: 0

Sheet HR Inputs
A1: TASK ID- Paid | B1: Function | C1: Triggers | D1: TASK OWNER | E1: Current Days in Lever | F1: Ideal Days in Lever | G1: Target Days (Sean)
A3: 2 | B3: Hiring | K3: Resumes | L3: 5956
A4: 2.1 | B4: Req Created | C4: Lever | D4: Haley | E4: 1 | F4: 1 | G4: 1 | K4: Opps | L4: 17
A5: 2.2 | B5: Screen Interview | C5: Lever | D5: Haley | E5: 7 | F5: 21 | G5: 14 | H5: 3 weeks to find strong fit from applicants | K5: Resume/Hire | L5: =L3/L4 -> 350.35294
A6: 2.3 | B6: Who Interview | C6: Lever | D6: Director/AD | E6: 13 | F6: 4 | G6: 3
A7: 2.4 | B7: Presentation/Focused | C7: Lever | D7: Jesse/Director | E7: 16 | F7: 5 | G7: 4
A8: 2.5 | B8: Offer Letter Sent | C8: Zenefits | D8: Lindsay/Tara | E8: 7 | F8: 1 | G8: 1
A9: 2.6 | B9: Signature | C9: Zenefits | D9: Candidate | E9: 3 | F9: 1 | G9: 1
A10: 2.7 | B10: Start Date | C10: Zenefits | D10: Candidate | E10: 14 | F10: 14 | G10: 14 | H10: 2 weeks notice
E11: 70 | F11: =SUM(F4:F10) -> 47 | G11: =SUM(G4:G10) -> 38
A13: TASK ID- SEO | B13: Function | C13: Triggers | D13: TASK OWNER | E13: Current Days in Lever | F13: Ideal Days in Lever | G13: Target Days (Sean)
A15: 2 | B15: Hiring
A16: 2.1 | B16: Req Created | C16: Lever | D16: Haley | E16: 1 | F16: 1 | G16: 1 | K16: Resumes | L16: 1178
A17: 2.2 | B17: Screen Interview | C17: Lever | D17: Haley | E17: 16 | F17: 14 | G17: 7 | H17: 2 weeks to find strong fit from applicants | K17: Opps | L17: 2
A18: 2.3 | B18: Who Interview | C18: Lever | D18: Director/AD | E18: 6 | F18: 4 | G18: 3 | K18: Resume/Hire | L18: =L16/L17 -> 589
A19: 2.4 | B19: Presentation/Focused | C19: Lever | D19: Jesse/Director | E19: 26 | F19: 5 | G19: 4
A20: 2.5 | B20: Offer Letter Sent | C20: Zenefits | D20: Lindsay/Tara | E20: 5 | F20: 1 | G20: 1
A21: 2.6 | B21: Signature | C21: Zenefits | D21: Candidate | E21: 3 | F21: 1 | G21: 1
A22: 2.7 | B22: Start Date | C22: Zenefits | D22: Candidate | E22: 14 | F22: 14 | G22: 14 | H22: 2 weeks notice
E23: 38 | F23: =SUM(F16:F22) -> 40 | G23: =SUM(G16:G22) -> 31
A25: TASK ID- Design | B25: Function | C25: Triggers | D25: TASK OWNER | E25: Current Days in Lever | F25: Ideal Days in Lever | G25: Target Days (Sean)
A27: 2 | B27: Hiring
A28: 2.1 | B28: Req Created | C28: Lever | D28: Haley | E28: 1 | G28: 1
A29: 2.2 | B29: Screen Interview | C29: Lever | D29: Haley | E29: 6 | G29: 7
A30: 2.3 | B30: Who Interview | C30: Lever | D30: Director/AD | E30: 8 | G30: 3
A31: 2.4 | B31: Presentation/Focused | C31: Lever | D31: Jesse/Director | E31: 16 | G31: 4
A32: 2.5 | B32: Offer Letter Sent | C32: Zenefits | D32: Lindsay/Tara | E32: 1 | G32: 1
A33: 2.6 | B33: Signature | C33: Zenefits | D33: Candidate | E33: 3 | G33: 1
A34: 2.7 | B34: Start Date | C34: Zenefits | D34: Candidate | E34: 14 | G34: 14
E35: 38 | F35: =SUM(F28:F34) -> 0 | G35: =SUM(G28:G34) -> 31
A37: TASK ID- Video | B37: Function | C37: Triggers | D37: TASK OWNER | E37: Current Days in Lever | F37: Ideal Days in Lever | G37: Target Days (Sean)
A39: 2 | B39: Hiring
A40: 2.1 | B40: Req Created | C40: Lever | D40: Haley | E40: 1 | G40: 1
A41: 2.2 | B41: Screen Interview | C41: Lever | D41: Haley | E41: 5 | G41: 7
A42: 2.3 | B42: Who Interview | C42: Lever | D42: Director/AD | E42: 15 | G42: 3
A43: 2.4 | B43: Presentation/Focused | C43: Lever | D43: Jesse/Director | E43: 15 | G43: 4
A44: 2.5 | B44: Offer Letter Sent | C44: Zenefits | D44: Lindsay/Tara | E44: 1 | G44: 1
A45: 2.6 | B45: Signature | C45: Zenefits | D45: Candidate | E45: 3 | G45: 1
A46: 2.7 | B46: Start Date | C46: Zenefits | D46: Candidate | E46: 14 | G46: 14
E47: 49 | F47: =SUM(F40:F46) -> 0 | G47: =SUM(G40:G46) -> 31
...

Sheet Sheet2
A1: Stage | C1: Where? | D1: Type | E1: Now | F1: 30 days | G1: 60 Days | J1: 90 Days | K1: 120 Days
A2: Resourcing Meeting
A3: - Place recent closed won deals. - Forecast upcoming renewals for the next 90 days. - Map out transitions. | C3: Mavenlink/ Resource Meeting | D3: Strategist Hours | E3: 150 | F3: 170 | G3: 120 | J3: 80 | K3: 80
A4: - Map out vacation support. - Cover PiP's and predictable employee churn. - Cover progress of new onboarding team member capacity. * POp's gives regrettable churn rate and Catie applies to current numbers. | C4: Mavenlink/ Resource Meeting | D4: Senior Hours | E4: 50 | F4: 70 | G4: 50 | J4: 20 | K4: 20
A7: Sales Forecast
E8: Commit Stage | G8: Strategy & Proposal | J8: N/A
A9: - Directors commit to what opportunities they think will close. * Strategy calls held prospects get their tier updated based off of information gathered. | C9: Salesforce / ? | D9: Midsize Hours | E9: 30 | F9: 140 | G9: 100 | J9: 0 | K9: 0
A10: - Strategy calls held hours get projected in Clari 50 days out. Proposals 45 days and SOW now. * Caitie matches the hours by type into Clari (Strategist -> Midsize, Enterprise -> Senior.) * Caitie applies the close rate by deliverable by stage to the hours & Caitie meets with AE's to get context on strategy pipeline. | C10: Clari / Resource Meeting | D10: Enterpise Hours | E10: 50 | F10: 50 | G10: 30 | J10: 0 | K10: 0
A13: Difference
C14: Clari / Resource Meeting | D14: Strategist Hours | E14: =E3-E9 -> 120 | F14: =F3-F9 -> 30 | G14: =G3-G9 -> 20 | J14: =J3-J9 -> 80 | K14: =K3-K9 -> 80
C15: Clari / Resource Meeting | D15: Seniors Hours | E15: =E4-E10 -> 0 | F15: =F4-F10 -> 20 | G15: =G4-G10 -> 20 | J15: =J4-J10 -> 20 | K15: =K4-K10 -> 20
A17: Hiring & L&D Timelines
A18: - Hiring has a 38 days to start date timeline. * L&D has a 15 days until 1st client & 64 days until 2nd client timeline. - | C18: Spreadsheet / Mavenlink / ? | D18: Strategist
D19: Reqs: | E19: 1
D20: Offer Signed | E20: Day 24
D21: Prospect Starts | E21: Day 38
D22: Approved for 1st Client | E22: Day 53 | I22: =40*E19 -> 40
D23: Ramped to 2nd Client | E23: Day 102 | K23: =40*E19 -> 40
D25: Senior
D26: Reqs: | E26: 1
D27: Offer Signed | E27: Day 24
D28: Prospect Starts | E28: Day 38
D29: Approved for 1st Client | E29: Day 45 | H29: =40*E26 -> 40
D30: Ramped to 2nd Client | E30: Day 90 | J30: =40*E26 -> 40
D31: Ramped to 3rd Client | E31: Day 120 | K31: =40*E26 -> 40
A33: Req's Needed
A34: * How much open capacity should we have at all times to cover for people quitting or getting promoted? | C34: Clari / Resource Meeting | D34: Strategist Hours | E34: =E14 -> 120 | F34: =F14 -> 30 | G34: =G14 -> 20 | H34: =G34 -> 20 | I34: =I22+G14 -> 60 | J34: =I34 -> 60 | K34: =K23+J34 -> 100
C35: Clari / Resource Meeting | D35: Seniors Hours | E35: =E15 -> 0 | F35: =F15 -> 20 | G35: =G15 -> 20 | H35: =H29+G15 -> 60 | I35: =H35 -> 60 | J35: =I35+J30 -> 100 | K35: =J35+K31 -> 140

Sheet Sheet3
A1: Regrettable (unforeseeable) Employee Churn
A2: - There is repeatable churn that happens within our departments that is not foreseeable. These are strategist that put in their 2 weeks and we have to have staff ready to go to service those clients. | C2: Zenefits / ? | D2: Regrettable Churn Rate | E2: 0.02
D3: Total Strategist Hours | E3: 1800
D4: Total Senior Hours | E4: 800
D5: Churned Strategist Hrs. | E5: =$E$3*$E$2 -> 36 | F5: =$E$3*$E$2 -> 36 | G5: =$E$3*$E$2 -> 36 | H5: =$E$3*$E$2 -> 36
D6: Churned Senior Hrs. | E6: =$E$4*$E$2 -> 16 | F6: =$E$4*$E$2 -> 16 | G6: =$E$4*$E$2 -> 16 | H6: =$E$4*$E$2 -> 16
D7: Strategist Remaining Hrs. | E7: =Sheet2!E3-E5 -> 114 | F7: =Sheet2!F3-F5 -> 134 | G7: =Sheet2!G3-G5 -> 84 | H7: =Sheet2!J3-H5 -> 44
D8: Senior Remaining Hrs. | E8: =Sheet2!E4-E6 -> 34 | F8: =Sheet2!F4-F6 -> 54 | G8: =Sheet2!G4-G6 -> 34 | H8: =Sheet2!J4-H6 -> 4
