Workbook

Sheet Qx Example
C1: This Quarter Actuals | J1: Cell Color Legend
A2: Current Details | B2: Model | C2: Google | D2: LinkedIn | E2: Microsoft | F2: Facebook | G2: Directories | H2: Total | J2: Input Raw Data
A3: Total Spend | B3: 60000 | C3: 30000 | D3: 30000 | E3: 30000 | F3: 40000 | G3: 60000 | H3: =SUM(C3:G3) -> 190000 | J3: Totals
A4: Leads | B4: 18000 | C4: 160 | D4: 160 | E4: 160 | F4: 160 | G4: 160 | H4: =SUM(C4:G4) -> 800 | J4: Formulas
A5: MQLs | B5: 8000 | C5: 100 | D5: 100 | E5: 100 | F5: 100 | G5: 100 | H5: =SUM(C5:G5) -> 500
A6: SALs | B6: 2700 | C6: 80 | D6: 80 | E6: 80 | F6: 80 | G6: 80 | H6: =SUM(C6:G6) -> 400
A7: SQLs | B7: 1300 | C7: 60 | D7: 60 | E7: 60 | F7: 60 | G7: 60 | H7: =SUM(C7:G7) -> 300
A8: Opps | B8: 600 | C8: 20 | D8: 20 | E8: 20 | F8: 20 | G8: 20 | H8: =SUM(C8:G8) -> 100
A9: Customers | B9: 60 | C9: 10 | D9: 10 | E9: 10 | F9: 10 | G9: 10 | H9: =SUM(C9:G9) -> 50
A10: Est. Bookings (Annual) | B10: =iferror((B9*B29)*12,"") -> 360000 | C10: =iferror((C9*C29)*12,"") -> 60000 | D10: =iferror((D9*D29)*12,"") -> 60000 | E10: =iferror((E9*E29)*12,"") -> 60000 | F10: =iferror((F9*F29)*12,"") -> 60000 | G10: =iferror((G9*G29)*12,"") -> 60000 | H10: =sum(B10:G10) -> 660000
A11: Cost-Per-Lead | B11: =iferror(B3/B4,"") -> 3.3333333 | C11: =iferror(C3/C4,"") -> 187.5 | D11: =iferror(D3/D4,"") -> 187.5 | E11: =iferror(E3/E4,"") -> 187.5 | F11: =iferror(F3/F4,"") -> 250 | G11: =iferror(G3/G4,"") -> 375 | H11: =iferror(H3/H4,"") -> 237.5
A12: Cost-Per-MQL | B12: =iferror(B3/B5,"") -> 7.5 | C12: =iferror(C3/C5,"") -> 300 | D12: =iferror(D3/D5,"") -> 300 | E12: =iferror(E3/E5,"") -> 300 | F12: =iferror(F3/F5,"") -> 400 | G12: =iferror(G3/G5,"") -> 600 | H12: =iferror(H3/H5,"") -> 380
A13: Cost-Per-SAL | B13: =iferror(B3/B6,"") -> 22.222222 | C13: =iferror(C3/C6,"") -> 375 | D13: =iferror(D3/D6,"") -> 375 | E13: =iferror(E3/E6,"") -> 375 | F13: =iferror(F3/F6,"") -> 500 | G13: =iferror(G3/G6,"") -> 750 | H13: =iferror(H3/H6,"") -> 475
A14: Cost-Per-SQL | B14: =iferror(B3/B7,"") -> 46.153846 | C14: =iferror(C3/C7,"") -> 500 | D14: =iferror(D3/D7,"") -> 500 | E14: =iferror(E3/E7,"") -> 500 | F14: =iferror(F3/F7,"") -> 666.66667 | G14: =iferror(G3/G7,"") -> 1000 | H14: =iferror(H3/H7,"") -> 633.33333
A15: Cost-Per-Opp | B15: =iferror(B3/B8,"") -> 100 | C15: =iferror(C3/C8,"") -> 1500 | D15: =iferror(D3/D8,"") -> 1500 | E15: =iferror(E3/E8,"") -> 1500 | F15: =iferror(F3/F8,"") -> 2000 | G15: =iferror(G3/G8,"") -> 3000 | H15: =iferror(H3/H8,"") -> 1900
A16: Cost-Per-Customer | B16: =iferror(B3/B9,"") -> 1000 | C16: =iferror(C3/C9,"") -> 3000 | D16: =iferror(D3/D9,"") -> 3000 | E16: =iferror(E3/E9,"") -> 3000 | F16: =iferror(F3/F9,"") -> 4000 | G16: =iferror(G3/G9,"") -> 6000 | H16: =iferror(H3/H9,"") -> 3800
A18: Current Details | B18: =B2 -> Model | C18: =C2 -> Google | D18: =D2 -> LinkedIn | E18: =E2 -> Microsoft | F18: =F2 -> Facebook | G18: =G2 -> Directories | H18: =H2 -> Total
A19: Avg. Contract Value (Annual) | B19: =iferror(B10/B9,"") -> 6000 | C19: =iferror(C10/C9,"") -> 6000 | D19: =iferror(D10/D9,"") -> 6000 | E19: =iferror(E10/E9,"") -> 6000 | F19: =iferror(F10/F9,"") -> 6000 | G19: =iferror(G10/G9,"") -> 6000 | H19: =iferror(H10/H9,"") -> 13200
A20: Opp > Customer (Close Rate) | B20: =iferror(B9/B8,"") -> 0.1 | C20: =iferror(C9/C8,"") -> 0.5 | D20: =iferror(D9/D8,"") -> 0.5 | E20: =iferror(E9/E8,"") -> 0.5 | F20: =iferror(F9/F8,"") -> 0.5 | G20: =iferror(G9/G8,"") -> 0.5 | H20: =iferror(H9/H8,"") -> 0.5
A21: Lead > MQL | B21: =iferror(B5/B4,"") -> 0.44444444 | C21: =iferror(C5/C4,"") -> 0.625 | D21: =iferror(D5/D4,"") -> 0.625 | E21: =iferror(E5/E4,"") -> 0.625 | F21: =iferror(F5/F4,"") -> 0.625 | G21: =iferror(G5/G4,"") -> 0.625 | H21: =iferror(H5/H4,"") -> 0.625
A22: MQL > SAL | B22: =iferror(B6/B5,"") -> 0.3375 | C22: =iferror(C6/C5,"") -> 0.8 | D22: =iferror(D6/D5,"") -> 0.8 | E22: =iferror(E6/E5,"") -> 0.8 | F22: =iferror(F6/F5,"") -> 0.8 | G22: =iferror(G6/G5,"") -> 0.8 | H22: =iferror(H6/H5,"") -> 0.8
A23: SAL > SQL | B23: =iferror(B7/B6,"") -> 0.48148148 | C23: =iferror(C7/C6,"") -> 0.75 | D23: =iferror(D7/D6,"") -> 0.75 | E23: =iferror(E7/E6,"") -> 0.75 | F23: =iferror(F7/F6,"") -> 0.75 | G23: =iferror(G7/G6,"") -> 0.75 | H23: =iferror(H7/H6,"") -> 0.75
A24: SQL > Opp | B24: =iferror(B8/B7,"") -> 0.46153846 | C24: =iferror(C8/C7,"") -> 0.33333333 | D24: =iferror(D8/D7,"") -> 0.33333333 | E24: =iferror(E8/E7,"") -> 0.33333333 | F24: =iferror(F8/F7,"") -> 0.33333333 | G24: =iferror(G8/G7,"") -> 0.33333333 | H24: =iferror(H8/H7,"") -> 0.33333333
A26: Lifetime Value (LTV): | B26: Model | C26: =C2 -> Google | D26: =D2 -> LinkedIn | E26: =E2 -> Microsoft | F26: =F2 -> Facebook | G26: =G2 -> Directories | H26: =H18 -> Total | J26: Lifetime Value (LTV) | K26: Actuals (from client)
A27: Gross Margin (GM%): | B27: =if(ISBLANK($K$27),"enter actuals",$K$27) -> 0.55 | C27: =$B27 -> 0.55 | D27: =$B27 -> 0.55 | E27: =$B27 -> 0.55 | F27: =$B27 -> 0.55 | G27: =$B27 -> 0.55 | H27: =iferror(average(C27:G27),"") -> 0.55 | J27: Gross Margin (GM%): | K27: 0.55
A28: Lifespan of a customer (months): | B28: =if(ISBLANK($K$28),"enter actuals",$K$28) -> 12 | C28: =$B28 -> 12 | D28: =$B28 -> 12 | E28: =$B28 -> 12 | F28: =$B28 -> 12 | G28: =$B28 -> 12 | H28: =iferror(average(C28:G28),"") -> 12 | J28: Lifespan of a customer (months): | K28: 12
A29: Monthly Avg. Order Value | B29: =if(isblank($K$29),"enter actuals",$K$29) -> 500 | C29: =$B29 -> 500 | D29: =$B29 -> 500 | E29: =$B29 -> 500 | F29: =$B29 -> 500 | G29: =$B29 -> 500 | H29: =iferror(H19/12,"") -> 1100 | J29: Monthly Avg. Order Value | K29: 500
A30: Lifetime Value (LTV) | B30: =iferror(B27*B28*B29,"enter actuals") -> 3300 | C30: =$B30 -> 3300 | D30: =$B30 -> 3300 | E30: =$B30 -> 3300 | F30: =$B30 -> 3300 | G30: =$B30 -> 3300 | H30: =iferror(H27*H28*H29,"") -> 7260
A31: ROI | B31: =iferror((B30*B9)-B3,"") -> 138000 | C31: =iferror((C30*C9)-C3,"") -> 3000 | D31: =iferror((D30*D9)-D3,"") -> 3000 | E31: =iferror((E30*E9)-E3,"") -> 3000 | F31: =iferror((F30*F9)-F3,"") -> -7000 | G31: =iferror((G30*G9)-G3,"") -> -27000 | H31: =(H30*H9)-H3 -> 173000
A32: LTV:CAC Ratio | B32: =IFERROR(B30/B16,"") -> 3.3 | C32: =IFERROR(C30/C16,"") -> 1.1 | D32: =IFERROR((D9*D30)/D3,"") -> 1.1 | E32: =IFERROR((E9*E30)/E3,"") -> 1.1 | F32: =IFERROR((F9*F30)/F3,"") -> 0.825 | G32: =IFERROR((G9*G30)/G3,"") -> 0.55 | H32: =IFERROR((H9*H30)/H3,"") -> 1.9105263
J34: Quarterly Goal Type: | K34: SQL
C35: Next Quarter Projections
A36: Projections Details | B36: Model | C36: =C2 -> Google | D36: =D2 -> LinkedIn | E36: =E2 -> Microsoft | F36: =F2 -> Facebook | G36: =G2 -> Directories | H36: =H2 -> Total | J36: Channel | K36: ="Quarterly "&K34&" Goal" -> Quarterly SQL Goal | L36: =K34&" % Increase" -> SQL % Increase | M36: Spend Required | N36: Increase in Spend | O36: Incremental ROI
A37: Total Cost | C37: =if($K$34="Lead",VLOOKUP(C36,$J$36:$K$41,2,false)*if($K$44="Actuals",C11,if(L53="--",$K53,L53)),if($K$34="MQL",VLOOKUP(C36,$J$36:$K$41,2,false)*if($K$44="Actuals",C12,if(L54="--",$K54,L54)),if($K$34="SAL",VLOOKUP(C36,$J$36:$K$41,2,false)*if($K$44="Actuals",C13,if(L55="--",$K55,L55)), if($K$34="SQL",VLOOKUP(C36,$J$36:$K$41,2,false)*if($K$44="Actuals",C14,if(L56="--",$K56,L56)),if($K$34="Opp",VLOOKUP(C36,$J$36:$K$41,2,false)*if($K$44="Actuals",C15,if(L57="--",$K57,L57)),""))))) -> 222300 | D37: =if($K$34="Lead",VLOOKUP(D36,$J$36:$K$41,2,false)*if($K$44="Actuals",D11,if(M53="--",$K53,M53)),if($K$34="MQL",VLOOKUP(D36,$J$36:$K$41,2,false)*if($K$44="Actuals",D12,if(M54="--",$K54,M54)),if($K$34="SAL",VLOOKUP(D36,$J$36:$K$41,2,false)*if($K$44="Actuals",D13,if(M55="--",$K55,M55)), if($K$34="SQL",VLOOKUP(D36,$J$36:$K$41,2,false)*if($K$44="Actuals",D14,if(M56="--",$K56,M56)),if($K$34="Opp",VLOOKUP(D36,$J$36:$K$41,2,false)*if($K$44="Actuals",D15,if(M57="--",$K57,M57)),""))))) -> 741250 | E37: =if($K$34="Lead",VLOOKUP(E36,$J$36:$K$41,2,false)*if($K$44="Actuals",E11,if(N53="--",$K53,N53)),if($K$34="MQL",VLOOKUP(E36,$J$36:$K$41,2,false)*if($K$44="Actuals",E12,if(N54="--",$K54,N54)),if($K$34="SAL",VLOOKUP(E36,$J$36:$K$41,2,false)*if($K$44="Actuals",E13,if(N55="--",$K55,N55)), if($K$34="SQL",VLOOKUP(E36,$J$36:$K$41,2,false)*if($K$44="Actuals",E14,if(N56="--",$K56,N56)),if($K$34="Opp",VLOOKUP(E36,$J$36:$K$41,2,false)*if($K$44="Actuals",E15,if(N57="--",$K57,N57)),""))))) -> 86700 | F37: =if($K$34="Lead",VLOOKUP(F36,$J$36:$K$41,2,false)*if($K$44="Actuals",F11,if(O53="--",$K53,O53)),if($K$34="MQL",VLOOKUP(F36,$J$36:$K$41,2,false)*if($K$44="Actuals",F12,if(O54="--",$K54,O54)),if($K$34="SAL",VLOOKUP(F36,$J$36:$K$41,2,false)*if($K$44="Actuals",F13,if(O55="--",$K55,O55)), if($K$34="SQL",VLOOKUP(F36,$J$36:$K$41,2,false)*if($K$44="Actuals",F14,if(O56="--",$K56,O56)),if($K$34="Opp",VLOOKUP(F36,$J$36:$K$41,2,false)*if($K$44="Actuals",F15,if(O57="--",$K57,O57)),""))))) -> 531800 | G37: =if($K$34="Lead",VLOOKUP(G36,$J$36:$K$41,2,false)*if($K$44="Actuals",G11,if(P53="--",$K53,P53)),if($K$34="MQL",VLOOKUP(G36,$J$36:$K$41,2,false)*if($K$44="Actuals",G12,if(P54="--",$K54,P54)),if($K$34="SAL",VLOOKUP(G36,$J$36:$K$41,2,false)*if($K$44="Actuals",G13,if(P55="--",$K55,P55)), if($K$34="SQL",VLOOKUP(G36,$J$36:$K$41,2,false)*if($K$44="Actuals",G14,if(P56="--",$K56,P56)),if($K$34="Opp",VLOOKUP(G36,$J$36:$K$41,2,false)*if($K$44="Actuals",G15,if(P57="--",$K57,P57)),""))))) -> 581600 | H37: =SUM(C37:G37) -> 2163650 | J37: =C2 -> Google | K37: 50 | L37: =iferror((K37-(INDEX($A$1:$H$9,(INDEX(MATCH(($K$34&"s"),$A:$A,0),0)),(INDEX(MATCH(J37,$2:$2,0),0)))))/((INDEX($A$1:$H$9,(INDEX(MATCH(($K$34&"s"),$A:$A,0),0)),(INDEX(MATCH(J37,$2:$2,0),0))))),"") -> -0.16666667 | M37: =C37 -> 222300 | N37: =iferror(M37-C3,0) -> 192300 | O37: =iferror((((K37*C55)*C30)-M37)-C31,0) -> -164250
A38: Leads | C38: =if(($K$34&"s")=$A38,VLOOKUP(C36,$J$36:$K$41,2,false),if($K$44="Actuals",C37/C11,C37/if(L53="--",K53,L53))) -> 377.41935 | D38: =if(($K$34&"s")=$A38,VLOOKUP(D36,$J$36:$K$41,2,false),if($K$44="Actuals",D37/D11,D37/if(M53="--",K53,M53))) -> 1041.0815 | E38: =if(($K$34&"s")=$A38,VLOOKUP(E36,$J$36:$K$41,2,false),if($K$44="Actuals",E37/E11,E37/if(N53="--",K53,N53))) -> 274.36709 | F38: =if(($K$34&"s")=$A38,VLOOKUP(F36,$J$36:$K$41,2,false),if($K$44="Actuals",F37/F11,F37/if(O53="--",K53,O53))) -> 666.41604 | G38: =if(($K$34&"s")=$A38,VLOOKUP(G36,$J$36:$K$41,2,false),if($K$44="Actuals",G37/G11,G37/if(P53="--",K53,P53))) -> 499.22747 | H38: =SUM(C38:G38) -> 2858.5114 | J38: =D2 -> LinkedIn | K38: 50 | L38: =iferror((K38-(INDEX($A$1:$H$9,(INDEX(MATCH(($K$34&"s"),$A:$A,0),0)),(INDEX(MATCH(J38,$2:$2,0),0)))))/((INDEX($A$1:$H$9,(INDEX(MATCH(($K$34&"s"),$A:$A,0),0)),(INDEX(MATCH(J38,$2:$2,0),0))))),"") -> -0.16666667 | M38: =D37 -> 741250 | N38: =iferror(M38-D3,0) -> 711250 | O38: =iferror((((K38*D55)*D30)-M38)-D31,"") -> -719500
A39: MQLs | C39: =if(($K$34&"s")=$A39,VLOOKUP(C36,$J$36:$K$41,2,false),C38*C56) -> 181.16129 | D39: =if(($K$34&"s")=$A39,VLOOKUP(D36,$J$36:$K$41,2,false),D38*D56) -> 301.91362 | E39: =if(($K$34&"s")=$A39,VLOOKUP(E36,$J$36:$K$41,2,false),E38*E56) -> 200.28797 | F39: =if(($K$34&"s")=$A39,VLOOKUP(F36,$J$36:$K$41,2,false),F38*F56) -> 39.984962 | G39: =if(($K$34&"s")=$A39,VLOOKUP(G36,$J$36:$K$41,2,false),G38*G56) -> 399.38197 | H39: =SUM(C39:G39) -> 1122.7298 | J39: =E2 -> Microsoft | K39: 50 | L39: =iferror((K39-(INDEX($A$1:$H$9,(INDEX(MATCH(($K$34&"s"),$A:$A,0),0)),(INDEX(MATCH(J39,$2:$2,0),0)))))/((INDEX($A$1:$H$9,(INDEX(MATCH(($K$34&"s"),$A:$A,0),0)),(INDEX(MATCH(J39,$2:$2,0),0))))),"") -> -0.16666667 | M39: =E37 -> 86700 | N39: =iferror(M39-E3,0) -> 56700 | O39: =iferror((((K39*E55)*E30)-M39)-E31,"") -> 42300
A40: SALs | C40: =if(($K$34&"s")=$A40,VLOOKUP(C36,$J$36:$K$41,2,false),C39*C57) -> 54.348387 | D40: =if(($K$34&"s")=$A40,VLOOKUP(D36,$J$36:$K$41,2,false),D39*D57) -> 24.15309 | E40: =if(($K$34&"s")=$A40,VLOOKUP(E36,$J$36:$K$41,2,false),E39*E57) -> 104.14975 | F40: =if(($K$34&"s")=$A40,VLOOKUP(F36,$J$36:$K$41,2,false),F39*F57) -> 4.7981955 | G40: =if(($K$34&"s")=$A40,VLOOKUP(G36,$J$36:$K$41,2,false),G39*G57) -> 47.925837 | H40: =SUM(C40:G40) -> 235.37526 | J40: =F2 -> Facebook | K40: 50 | L40: =iferror((K40-(INDEX($A$1:$H$9,(INDEX(MATCH(($K$34&"s"),$A:$A,0),0)),(INDEX(MATCH(J40,$2:$2,0),0)))))/((INDEX($A$1:$H$9,(INDEX(MATCH(($K$34&"s"),$A:$A,0),0)),(INDEX(MATCH(J40,$2:$2,0),0))))),"") -> -0.16666667 | M40: =F37 -> 531800 | N40: =iferror(M40-F3,0) -> 491800 | O40: =iferror((((K40*F55)*F30)-M40)-F31,"") -> -463750
A41: SQLs | C41: =if(($K$34&"s")=$A41,VLOOKUP(C36,$J$36:$K$41,2,false),C40*C58) -> 50 | D41: =if(($K$34&"s")=$A41,VLOOKUP(D36,$J$36:$K$41,2,false),D40*D58) -> 50 | E41: =if(($K$34&"s")=$A41,VLOOKUP(E36,$J$36:$K$41,2,false),E40*E58) -> 50 | F41: =if(($K$34&"s")=$A41,VLOOKUP(F36,$J$36:$K$41,2,false),F40*F58) -> 50 | G41: =if(($K$34&"s")=$A41,VLOOKUP(G36,$J$36:$K$41,2,false),G40*G58) -> 50 | H41: =SUM(C41:G41) -> 250 | J41: =G2 -> Directories | K41: 50 | L41: =iferror((K41-(INDEX($A$1:$H$9,(INDEX(MATCH(($K$34&"s"),$A:$A,0),0)),(INDEX(MATCH(J41,$2:$2,0),0)))))/((INDEX($A$1:$H$9,(INDEX(MATCH(($K$34&"s"),$A:$A,0),0)),(INDEX(MATCH(J41,$2:$2,0),0))))),"") -> -0.16666667 | M41: =G37 -> 581600 | N41: =iferror(M41-G3,0) -> 521600 | O41: =iferror((((K41*G55)*G30)-M41)-G31,0) -> -513350
A42: Opps | C42: =if(($K$34&"s")=$A42,VLOOKUP(C36,$J$36:$K$41,2,false),C41*C59) -> 26 | D42: =if(($K$34&"s")=$A42,VLOOKUP(D36,$J$36:$K$41,2,false),D41*D59) -> 5 | E42: =if(($K$34&"s")=$A42,VLOOKUP(E36,$J$36:$K$41,2,false),E41*E59) -> 43 | F42: =if(($K$34&"s")=$A42,VLOOKUP(F36,$J$36:$K$41,2,false),F41*F59) -> 5 | G42: =if(($K$34&"s")=$A42,VLOOKUP(G36,$J$36:$K$41,2,false),G41*G59) -> 27.5 | H42: =SUM(C42:G42) -> 106.5 | J42: Total | K42: =SUM(K37:K41) -> 250 | L42: =iferror((K42-(INDEX($A$1:$H$9,(INDEX(MATCH(($K$34&"s"),$A:$A,0),0)),(INDEX(MATCH(J42,$2:$2,0),0)))))/((INDEX($A$1:$H$9,(INDEX(MATCH(($K$34&"s"),$A:$A,0),0)),(INDEX(MATCH(J42,$2:$2,0),0))))),"") -> -0.16666667 | M42: =SUM(M37:M41) -> 2163650 | N42: =SUM(N37:N41) -> 1973650 | O42: =SUM(O37:O41) -> -1818550
A43: Customers | C43: =C42*C55 -> 9.62 | D43: =D42*D55 -> 0.75 | E43: =E42*E55 -> 34.4 | F43: =F42*F55 -> 1.85 | G43: =G42*G55 -> 6.875 | H43: =SUM(C43:G43) -> 53.495
...

Sheet LTVCAC Analysis
B2: GET STARTED | BF2: NOTE
B3: Enter the values needed for calculating LTV in cells T14:T17, then customize your channels and funnel stages in the 'Current Quarter Actuals' table below. | BF3: Only edit highlighted cells.
BF4: Try not to alter cells that contain a formula.
B5: As you enter data in the 'Current Quarter Actuals' tab, this sheet will automatically update to show a summary of the quarter.
B10: Sept-Oct Summary
T12: Lifetime Value (LTV) | AC12: Lifetime Value (LTV)
T13: Gross Margin (%) | X13: 0.6 | AC13: Company Gross Margin (%) | AG13: 0.52
D14: =IFERROR(__xludf.DUMMYFUNCTION("iferror(SPARKLINE(C22,{""charttype"",""column"";""ymin"", 0; ""ymax"",MAX(C22:H22);""firstcolor"",""#304458""}),"""")"),"") | F14: =IFERROR(__xludf.DUMMYFUNCTION("iferror(SPARKLINE(F22,{""charttype"",""column"";""ymin"", 0; ""ymax"",MAX(C22:H22);""firstcolor"",""#f46524""}),"""")"),"") | T14: Lifespan of Customer (months) | X14: 12 | AC14: Retention % | AG14: 0.424
T15: Monthly Avg. Order Value | X15: 15293 | Z15: =X15*12 -> 183516
T16: Channel-level AOV's? | X16: Yes
T17: Lifetime Value (LTV) | X17: =if(X16="No",if(isblank(X13),"Enter GM%",if(isblank(X14),"Enter Lifespan",if(ISBLANK(X15),"Enter AOV",X13*X14*X15))),"See Below") -> See Below
M20: =F65 -> Form Fills | N20: =H65 -> 689 | S20: =IFERROR(__xludf.DUMMYFUNCTION("iferror(SPARKLINE(G65:H65,{""charttype"",""bar"";""max"",MAX($H$65:$H$70);""color1"",""#ebedef"";""color2"",""#073763""}),"""")"),"")
C21: Total Spend | F21: Total Est. Bookings | M21: =F66 -> Intro Held | N21: =H66 -> 373 | S21: =IFERROR(__xludf.DUMMYFUNCTION("iferror(SPARKLINE(G66:H66,{""charttype"",""bar"";""max"",MAX($H$65:$H$70);""color1"",""#ebedef"";""color2"",""#0b5394""}),"""")"),"") | W21: =iferror(if(J65="","","🔽 "&(ROUND(J65,2)*100)&"%"),"--") -> 🔽 54% | X21: =if(I65="","",I65) -> Form Fill > Intro Held
C22: =E36 -> 951168.5 | F22: =E47 -> 1317030 | M22: =F67 -> Strat Call Held | N22: =H67 -> 156 | S22: =IFERROR(__xludf.DUMMYFUNCTION("iferror(SPARKLINE(G67:H67,{""charttype"",""bar"";""max"",MAX(H65:H70);""color1"",""#ebedef"";""color2"",""#3d85c6""}),"""")"),"") | W22: =iferror(if(J66="","","🔽 "&(ROUND(J66,2)*100)&"%"),"--") -> 🔽 42% | X22: =if(I66="","",I66) -> Intro Held > Strat Call Held
M23: =F68 -> Proposals | N23: =H68 -> 104 | S23: =IFERROR(__xludf.DUMMYFUNCTION("iferror(SPARKLINE(G68:H68,{""charttype"",""bar"";""max"",MAX($H$65:$H$70);""color1"",""#ebedef"";""color2"",""#6fa8dc""}),"""")"),"") | W23: =iferror(if(J67="","","🔽 "&(ROUND(J67,2)*100)&"%"),"--") -> 🔽 67% | X23: =if(I67="","",I67) -> Strat Call Held > Proposal
M24: =F69 -> Customers | N24: =H69 -> 23 | S24: =IFERROR(__xludf.DUMMYFUNCTION("iferror(SPARKLINE(G69:H69,{""charttype"",""bar"";""max"",MAX($H$65:$H$70);""color1"",""#ebedef"";""color2"",""#9fc5e8""}),"""")"),"") | W24: =iferror(if(J68="","","🔽 "&(ROUND(J68,2)*100)&"%"),"--") -> 🔽 22% | X24: =if(I68="","",I68) -> Proposal > Customer
C25: LTV:CAC Ratio | F25: =E31 -> 1.13 | M25: =F70 | N25: =H70 | S25: {=iferror(SPARKLINE(G70:H70,{"charttype","bar";"max",MAX($H$65:$H$70);"color1","#ebedef";"color2","#cfe2f3"}),"")} | W25: =iferror(if(J69="","","🔽 "&(ROUND(J69,2)*100)&"%"),"--") | X25: =if(I69="","",I69)
C26: Net Return | F26: =E48 -> 1012798.2
B28: Sept-Oct Actuals
I29: 25000 | AM29: 35000 | AO29: 5000 | AQ29: 30000 | AS29: 60000 | AW29: 40000
E30: Total | G30: Google - Brand | I30: Google - Non-Brand: Demand Gen | K30: Google - Non-Brand: Marketing | M30: Google - Non-Brand: MOPs | O30: Google - Non-Brand: Paid Media | Q30: Google - Non-Brand: Social | S30: Google - Non-Brand: Creative | U30: Google - Non-Brand: Performance Marketing | W30: Google - Non-Brand: SEO | Y30: Google - Non-Brand: Strategy | AA30: Google - Non-Brand: Video | AC30: Google - YouTube | AE30: Google - Display | AG30: Google - Non-Brand: Events Support | AI30: Google - Non-Brand: RLSA | AK30: LinkedIn - Brand Ads | AM30: LinkedIn - Convo Ads GC | AO30: LinkedIn - Line Specific GC | AQ30: LinkedIn - Strategy GC | AS30: LinkedIn - SPC GC | AU30: Facebook/IG - Brand Ads | AW30: Facebook - SPC GC | AY30: Instagram - SPC GC | BA30: StackAdapt | BC30: Clutch.io | BE30: Manifest | BG30: Twitter - Brand | BI30: TikTok | BK30: Events | BM30: Organic | BO30: Non-Paid Media | BQ30: Total
B31: LTV:CAC Ratio | E31: =if(E36="--","--",if(istext(E46),"No LTV",if(or(isblank(E42),E42=0),0,Round(E46/E54,2)))) -> 1.13 | G31: =if(isblank(G36),"--",if(istext(G46),"No LTV",if(or(isblank(G42),G42=0),0,Round(G46/G54,2)))) -> No LTV | I31: =if(isblank(I36),"--",if(istext(I46),"No LTV",if(or(isblank(I42),I42=0),0,Round(I46/I54,2)))) -> No LTV | K31: =if(isblank(K36),"--",if(istext(K46),"No LTV",if(or(isblank(K42),K42=0),0,Round(K46/K54,2)))) -> No LTV | M31: =if(isblank(M36),"--",if(istext(M46),"No LTV",if(or(isblank(M42),M42=0),0,Round(M46/M54,2)))) -> No LTV | O31: =if(isblank(O36),"--",if(istext(O46),"No LTV",if(or(isblank(O42),O42=0),0,Round(O46/O54,2)))) -> No LTV | Q31: =if(isblank(Q36),"--",if(istext(Q46),"No LTV",if(or(isblank(Q42),Q42=0),0,Round(Q46/Q54,2)))) -> No LTV | S31: =if(isblank(S36),"--",if(istext(S46),"No LTV",if(or(isblank(S42),S42=0),0,Round(S46/S54,2)))) -> No LTV | U31: =if(isblank(U36),"--",if(istext(U46),"No LTV",if(or(isblank(U42),U42=0),0,Round(U46/U54,2)))) -> No LTV | W31: =if(isblank(W36),"--",if(istext(W46),"No LTV",if(or(isblank(W42),W42=0),0,Round(W46/W54,2)))) -> No LTV | Y31: =if(isblank(Y36),"--",if(istext(Y46),"No LTV",if(or(isblank(Y42),Y42=0),0,Round(Y46/Y54,2)))) -> No LTV | AA31: =if(isblank(AA36),"--",if(istext(AA46),"No LTV",if(or(isblank(AA42),AA42=0),0,Round(AA46/AA54,2)))) -> 0.83 | AC31: =if(isblank(AC36),"--",if(istext(AC46),"No LTV",if(or(isblank(AC42),AC42=0),0,Round(AC46/AC54,2)))) -> No LTV | AE31: =if(isblank(AE36),"--",if(istext(AE46),"No LTV",if(or(isblank(AE42),AE42=0),0,Round(AE46/AE54,2)))) -> No LTV | AG31: =if(isblank(AG36),"--",if(istext(AG46),"No LTV",if(or(isblank(AG42),AG42=0),0,Round(AG46/AG54,2)))) -> No LTV | AI31: =if(isblank(AI36),"--",if(istext(AI46),"No LTV",if(or(isblank(AI42),AI42=0),0,Round(AI46/AI54,2)))) -> No LTV | AK31: =if(isblank(AK36),"--",if(istext(AK46),"No LTV",if(or(isblank(AK42),AK42=0),0,Round(AK46/AK54,2)))) -> No LTV | AM31: =if(isblank(AM36),"--",if(istext(AM46),"No LTV",if(or(isblank(AM42),AM42=0),0,Round(AM46/AM54,2)))) -> 1.33 | AO31: =if(isblank(AO36),"--",if(istext(AO46),"No LTV",if(or(isblank(AO42),AO42=0),0,Round(AO46/AO54,2)))) -> No LTV | AQ31: =if(isblank(AQ36),"--",if(istext(AQ46),"No LTV",if(or(isblank(AQ42),AQ42=0),0,Round(AQ46/AQ54,2)))) -> No LTV | AS31: =if(isblank(AS36),"--",if(istext(AS46),"No LTV",if(or(isblank(AS42),AS42=0),0,Round(AS46/AS54,2)))) -> 2.74 | AU31: =if(isblank(AU36),"--",if(istext(AU46),"No LTV",if(or(isblank(AU42),AU42=0),0,Round(AU46/AU54,2)))) -> No LTV | AW31: =if(isblank(AW36),"--",if(istext(AW46),"No LTV",if(or(isblank(AW42),AW42=0),0,Round(AW46/AW54,2)))) -> No LTV | BA31: =if(isblank(BA36),"--",if(istext(BA46),"No LTV",if(or(isblank(BA42),BA42=0),0,Round(BA46/BA54,2)))) -> No LTV | BC31: =if(isblank(BC36),"--",if(istext(BC46),"No LTV",if(or(isblank(BC42),BC42=0),0,Round(BC46/BC54,2)))) -> No LTV | BE31: =if(isblank(BE36),"--",if(istext(BE46),"No LTV",if(or(isblank(BE42),BE42=0),0,Round(BE46/BE54,2)))) -> No LTV | BG31: =if(isblank(BG36),"--",if(istext(BG46),"No LTV",if(or(isblank(BG42),BG42=0),0,Round(BG46/BG54,2)))) -> No LTV | BI31: =if(isblank(BI36),"--",if(istext(BI46),"No LTV",if(or(isblank(BI42),BI42=0),0,Round(BI46/BI54,2)))) -> No LTV | BK31: =if(isblank(BK36),"--",if(istext(BK46),"No LTV",if(or(isblank(BK42),BK42=0),0,Round(BK46/BK54,2)))) -> No LTV | BM31: =if(isblank(BM36),"--",if(istext(BM46),"No LTV",if(or(isblank(BM42),BM42=0),0,Round(BM46/BM54,2)))) -> No LTV | BO31: =if(isblank(BO36),"--",if(istext(BO46),"No LTV",if(or(isblank(BO42),BO42=0),0,Round(BO46/BO54,2)))) -> 32.67
B32: Total Ad Spend | E32: =if(sum(G32:BS32)=0,"--",sum(G32:BS32)) -> 340478.51 | G32: 1566.34 | I32: 790.57 | K32: 10320.12 | M32: 9662.2 | O32: 182.38 | Q32: 2426.92 | S32: 8162.96 | U32: 18167.75 | W32: 6440.66 | Y32: 12024.18 | AA32: 6191.84 | AC32: 3039.35 | AE32: 0 | AG32: 795.72 | AI32: 1852.71 | AK32: 11823.74 | AM32: 65931.99 | AO32: 11401.43 | AQ32: 43631.78 | AS32: 26875.87 | AU32: 12100.79 | AW32: 21266.237 | AY32: 13327.613 | BA32: 4775.86 | BC32: =2650+2650 -> 5300 | BE32: =650+650 -> 1300 | BG32: 3901.5 | BI32: 4218 | BK32: 33000 | BM32: 0 | BO32: 0
B33: Resource Cost | E33: 567941 | G33: =(G32/$E$32)*$E$33 -> 2612.7602 | I33: =(I32/$E$32)*$E$33 -> 1318.7238 | K33: =(K32/$E$32)*$E$33 -> 17214.653 | M33: =(M32/$E$32)*$E$33 -> 16117.198 | O33: =(O32/$E$32)*$E$33 -> 304.22208 | Q33: =(Q32/$E$32)*$E$33 -> 4048.2654 | S33: =(S32/$E$32)*$E$33 -> 13616.365 | U33: =(U32/$E$32)*$E$33 -> 30305.026 | W33: =(W32/$E$32)*$E$33 -> 10743.453 | Y33: =(Y32/$E$32)*$E$33 -> 20057.139 | AA33: =(AA32/$E$32)*$E$33 -> 10328.405 | AC33: =(AC32/$E$32)*$E$33 -> 5069.8397 | AE33: =(AE32/$E$32)*$E$33 -> 0 | AG33: =(AG32/$E$32)*$E$33 -> 1327.3144 | AI33: =(AI32/$E$32)*$E$33 -> 3090.4446 | AK33: =(AK32/$E$32)*$E$33 -> 19722.792 | AM33: =(AM32/$E$32)*$E$33 -> 109978.98 | AO33: =(AO32/$E$32)*$E$33 -> 19018.35 | AQ33: =(AQ32/$E$32)*$E$33 -> 72780.737 | AS33: =(AS32/$E$32)*$E$33 -> 44830.754 | AU33: =(AU32/$E$32)*$E$33 -> 20184.93 | AW33: =(AW32/$E$32)*$E$33 -> 35473.51 | AY33: =(AY32/$E$32)*$E$33 -> 22231.353 | BA33: =(BA32/$E$32)*$E$33 -> 7966.4549 | BC33: =(BC32/$E$32)*$E$33 -> 8840.7556 | BE33: =(BE32/$E$32)*$E$33 -> 2168.4872 | BG33: =(BG32/$E$32)*$E$33 -> 6507.9638 | BI33: =(BI32/$E$32)*$E$33 -> 7035.907 | BK33: =(BK32/$E$32)*$E$33 -> 55046.214 | BM33: =(BM32/$E$32)*$E$33 -> 0 | BO33: =(BO32/$E$32)*$E$33 -> 0 | BQ33: =SUM(G33:BP33) -> 567941
G34: =G36/$E$36 -> 0.0043936487 | I34: =I36/$E$36 -> 0.0022175816 | K34: =K36/$E$36 -> 0.028948365 | M34: =M36/$E$36 -> 0.027102872 | O34: =O36/$E$36 -> 0.00051158347 | Q34: =Q36/$E$36 -> 0.0068076113 | S34: =S36/$E$36 -> 0.022897441 | U34: =U36/$E$36 -> 0.050961292 | W34: =W36/$E$36 -> 0.018066318 | Y34: =Y36/$E$36 -> 0.033728324 | AA34: =AA36/$E$36 -> 0.017368368 | AC34: =AC36/$E$36 -> 0.0085255028 | AE34: =AE36/$E$36 -> 0 | AG34: =AG36/$E$36 -> 0.0022320276 | AI34: =AI36/$E$36 -> 0.0051969284 | AK34: =AK36/$E$36 -> 0.033166081 | AM34: =AM36/$E$36 -> 0.19959237 | AO34: =AO36/$E$36 -> 0.031981484 | AQ34: =AQ36/$E$36 -> 0.12238895 | AS34: =AS36/$E$36 -> 0.07538793 | AU34: =AU36/$E$36 -> 0.033943218 | AW34: =AW36/$E$36 -> 0.062443981 | AY34: =AY36/$E$36 -> 0.037384507 | BA34: =BA36/$E$36 -> 0.013396485 | BC34: =BC36/$E$36 -> 0.01486672 | BE34: =BE36/$E$36 -> 0.0036465539 | BG34: =BG36/$E$36 -> 0.010943869 | BI34: =BI36/$E$36 -> 0.011831665 | BK34: =BK36/$E$36 -> 0.092566369 | BM34: =BM36/$E$36 -> 0 | BO34: =BO36/$E$36 -> 0.027501952
B35: Incentive Cost | E35: =if(sum(G35:BS35)=0,"--",sum(G35:BS35)) -> 42748.99 | AM35: 13935 | AW35: 2655 | BO35: 26158.99
B36: Total Spend | E36: =sum(E32:F33,E35) -> 951168.5 | G36: =sum(G32:H33,G35) -> 4179.1002 | I36: =sum(I32:J33,I35) -> 2109.2938 | K36: =sum(K32:L33,K35) -> 27534.773 | M36: =sum(M32:N33,M35) -> 25779.398 | O36: =sum(O32:P33,O35) -> 486.60208 | Q36: =sum(Q32:R33,Q35) -> 6475.1854 | S36: =sum(S32:T33,S35) -> 21779.325 | U36: =sum(U32:V33,U35) -> 48472.776 | W36: =sum(W32:X33,W35) -> 17184.113 | Y36: =sum(Y32:Z33,Y35) -> 32081.319 | AA36: =sum(AA32:AB33,AA35) -> 16520.245 | AC36: =sum(AC32:AD33,AC35) -> 8109.1897 | AE36: =sum(AE32:AF33,AE35) -> 0 | AG36: =sum(AG32:AH33,AG35) -> 2123.0344 | AI36: =sum(AI32:AJ33,AI35) -> 4943.1546 | AK36: =sum(AK32:AL33,AK35) -> 31546.532 | AM36: =sum(AM32:AN33,AM35) -> 189845.97 | AO36: =sum(AO32:AP33,AO35) -> 30419.78 | AQ36: =sum(AQ32:AR33,AQ35) -> 116412.52 | AS36: =sum(AS32:AT33,AS35) -> 71706.624 | AU36: =sum(AU32:AV33,AU35) -> 32285.72 | AW36: =sum(AW32:AX33,AW35) -> 59394.748 | AY36: =sum(AY32:AZ33,AY35) -> 35558.965 | BA36: =sum(BA32:BB33,BA35) -> 12742.315 | BC36: =sum(BC32:BD33,BC35) -> 14140.756 | BE36: =sum(BE32:BF33,BE35) -> 3468.4872 | BG36: =sum(BG32:BH33,BG35) -> 10409.464 | BI36: =sum(BI32:BJ33,BI35) -> 11253.907 | BK36: =sum(BK32:BL33,BK35) -> 88046.214 | BM36: =sum(BM32:BN33,BM35) -> 0 | BO36: =sum(BO32:BP33,BO35) -> 26158.99
B37: Form Fills | E37: =if(isblank(B37),,if($E$36="--","--",sum(G37:BS37))) -> 689 | G37: 9 | I37: 1 | K37: 3 | M37: 4 | O37: 0 | Q37: 3 | S37: 3 | U37: 7 | W37: 8 | Y37: 0 | AA37: 9 | AC37: 0 | AE37: 0 | AG37: 0 | AI37: 1 | AK37: 0 | AM37: 164 | AO37: 54 | AQ37: 111 | AS37: 41 | AU37: 0 | AW37: 84 | BA37: 1 | BC37: 12 | BE37: 0 | BG37: 0 | BI37: 0 | BK37: 0 | BM37: 48 | BO37: 126
B38: Intro Held | E38: =if(isblank(B38),,if($E$36="--","--",sum(G38:BS38))) -> 373 | G38: 6 | I38: 0 | K38: 4 | M38: 0 | O38: 0 | Q38: 0 | S38: 2 | U38: 3 | W38: 8 | Y38: 0 | AA38: 4 | AC38: 0 | AE38: 0 | AG38: 0 | AI38: 0 | AK38: 0 | AM38: 86 | AO38: 18 | AQ38: 73 | AS38: 12 | AU38: 0 | AW38: 44 | BA38: 0 | BC38: 3 | BE38: 0 | BG38: 0 | BI38: 0 | BK38: 0 | BM38: 22 | BO38: 88
B39: Strat Call Held | E39: =if(isblank(B39),,if($E$36="--","--",sum(G39:BS39))) -> 156 | G39: 2 | I39: 0 | K39: 0 | M39: 0 | O39: 0 | Q39: 0 | S39: 0 | U39: 3 | W39: 0 | Y39: 0 | AA39: 1 | AC39: 0 | AE39: 0 | AG39: 0 | AI39: 0 | AK39: 0 | AM39: 25 | AO39: 7 | AQ39: 13 | AS39: 9 | AU39: 0 | AW39: 10 | BA39: 0 | BC39: 2 | BE39: 0 | BG39: 0 | BI39: 0 | BK39: 0 | BM39: 15 | BO39: 69
B40: Proposals | E40: =if(isblank(B40),,if($E$36="--","--",sum(G40:BS40))) -> 104 | G40: 4 | I40: 0 | K40: 0 | M40: 0 | O40: 0 | Q40: 0 | S40: 0 | U40: 1 | W40: 0 | Y40: 0 | AA40: 2 | AC40: 0 | AE40: 0 | AG40: 0 | AI40: 0 | AK40: 0 | AM40: 9 | AO40: 1 | AQ40: 13 | AS40: 3 | AU40: 0 | AW40: 9 | BA40: 0 | BC40: 0 | BE40: 0 | BG40: 0 | BI40: 0 | BK40: 0 | BM40: 0 | BO40: 62
E41: =if(isblank(B41),,if($E$36="--","--",sum(G41:BS41)))
B42: Customers | E42: =if(isblank(B42),,if($E$36="--","--",sum(G42:BS42))) -> 23 | G42: 0 | I42: 0 | K42: 0 | M42: 0 | O42: 0 | Q42: 0 | S42: 0 | U42: 0 | W42: 0 | Y42: 0 | AA42: 1 | AC42: 0 | AE42: 0 | AG42: 0 | AI42: 0 | AK42: 0 | AM42: 6 | AO42: 0 | AQ42: 0 | AS42: 3 | AU42: 0 | AW42: 0 | BA42: 0 | BC42: 0 | BE42: 0 | BG42: 0 | BI42: 0 | BK42: 0 | BM42: 0 | BO42: 13
B43: AAAa | E43: =if(X16="Yes",iferror(average(G43:BS43),""),X15) -> 6490.398 | AA43: 1895.8333 | AM43: 5836.8056 | AS43: 9097.2222 | BO43: 9131.7308
B44: Total AOV | AA44: 22750 | AM44: 420250 | AS44: 327500
G45: =(G44*$AG$13)/(1-$AG$14) -> 0 | I45: =(I44*$AG$13)/(1-$AG$14) -> 0 | K45: =(K44*$AG$13)/(1-$AG$14) -> 0 | M45: =(M44*$AG$13)/(1-$AG$14) -> 0 | O45: =(O44*$AG$13)/(1-$AG$14) -> 0 | Q45: =(Q44*$AG$13)/(1-$AG$14) -> 0 | S45: =(S44*$AG$13)/(1-$AG$14) -> 0 | U45: =(U44*$AG$13)/(1-$AG$14) -> 0 | W45: =(W44*$AG$13)/(1-$AG$14) -> 0 | Y45: =(Y44*$AG$13)/(1-$AG$14) -> 0 | AA45: =(AA44*$AG$13)/(1-$AG$14) -> 20538.194 | AC45: =(AC44*$AG$13)/(1-$AG$14) -> 0 | AE45: =(AE44*$AG$13)/(1-$AG$14) -> 0 | AG45: =(AG44*$AG$13)/(1-$AG$14) -> 0 | AI45: =(AI44*$AG$13)/(1-$AG$14) -> 0 | AK45: =(AK44*$AG$13)/(1-$AG$14) -> 0 | AM45: =(AM44*$AG$13)/(1-$AG$14) -> 379392.36 | AO45: =(AO44*$AG$13)/(1-$AG$14) -> 0 | AQ45: =(AQ44*$AG$13)/(1-$AG$14) -> 0 | AS45: =(AS44*$AG$13)/(1-$AG$14) -> 295659.72 | AU45: =(AU44*$AG$13)/(1-$AG$14) -> 0 | AW45: =(AW44*$AG$13)/(1-$AG$14) -> 0 | AY45: =(AY44*$AG$13)/(1-$AG$14) -> 0 | BA45: =(BA44*$AG$13)/(1-$AG$14) -> 0 | BC45: =(BC44*$AG$13)/(1-$AG$14) -> 0 | BE45: =(BE44*$AG$13)/(1-$AG$14) -> 0 | BG45: =(BG44*$AG$13)/(1-$AG$14) -> 0 | BI45: =(BI44*$AG$13)/(1-$AG$14) -> 0 | BK45: =(BK44*$AG$13)/(1-$AG$14) -> 0 | BM45: =(BM44*$AG$13)/(1-$AG$14) -> 0 | BO45: =(BO44*$AG$13)/(1-$AG$14) -> 0
B46: Lifetime Value (LTV) | E46: =if(E36="--","--", if(X16="No",$X$17,iferror(average(G46:BS46),""))) -> 46730.865 | G46: =if($X$16="Yes",if(isblank(G36),"--",if(isblank($X$13),"Enter GM%",if(isblank($X$14),"Enter Lifespan",if(ISBLANK(G43),"Enter AOV",$X$13*$X$14*G43)))),if(isblank(G36),"--",$X$17)) -> Enter AOV | I46: =if($X$16="Yes",if(isblank(I36),"--",if(isblank($X$13),"Enter GM%",if(isblank($X$14),"Enter Lifespan",if(ISBLANK(I43),"Enter AOV",$X$13*$X$14*I43)))),if(isblank(I36),"--",$X$17)) -> Enter AOV | K46: =if($X$16="Yes",if(isblank(K36),"--",if(isblank($X$13),"Enter GM%",if(isblank($X$14),"Enter Lifespan",if(ISBLANK(K43),"Enter AOV",$X$13*$X$14*K43)))),if(isblank(K36),"--",$X$17)) -> Enter AOV | M46: =if($X$16="Yes",if(isblank(M36),"--",if(isblank($X$13),"Enter GM%",if(isblank($X$14),"Enter Lifespan",if(ISBLANK(M43),"Enter AOV",$X$13*$X$14*M43)))),if(isblank(M36),"--",$X$17)) -> Enter AOV | O46: =if($X$16="Yes",if(isblank(O36),"--",if(isblank($X$13),"Enter GM%",if(isblank($X$14),"Enter Lifespan",if(ISBLANK(O43),"Enter AOV",$X$13*$X$14*O43)))),if(isblank(O36),"--",$X$17)) -> Enter AOV | Q46: =if($X$16="Yes",if(isblank(Q36),"--",if(isblank($X$13),"Enter GM%",if(isblank($X$14),"Enter Lifespan",if(ISBLANK(Q43),"Enter AOV",$X$13*$X$14*Q43)))),if(isblank(Q36),"--",$X$17)) -> Enter AOV | S46: =if($X$16="Yes",if(isblank(S36),"--",if(isblank($X$13),"Enter GM%",if(isblank($X$14),"Enter Lifespan",if(ISBLANK(S43),"Enter AOV",$X$13*$X$14*S43)))),if(isblank(S36),"--",$X$17)) -> Enter AOV | U46: =if($X$16="Yes",if(isblank(U36),"--",if(isblank($X$13),"Enter GM%",if(isblank($X$14),"Enter Lifespan",if(ISBLANK(U43),"Enter AOV",$X$13*$X$14*U43)))),if(isblank(U36),"--",$X$17)) -> Enter AOV | W46: =if($X$16="Yes",if(isblank(W36),"--",if(isblank($X$13),"Enter GM%",if(isblank($X$14),"Enter Lifespan",if(ISBLANK(W43),"Enter AOV",$X$13*$X$14*W43)))),if(isblank(W36),"--",$X$17)) -> Enter AOV | Y46: =if($X$16="Yes",if(isblank(Y36),"--",if(isblank($X$13),"Enter GM%",if(isblank($X$14),"Enter Lifespan",if(ISBLANK(Y43),"Enter AOV",$X$13*$X$14*Y43)))),if(isblank(Y36),"--",$X$17)) -> Enter AOV | AA46: =if($X$16="Yes",if(isblank(AA36),"--",if(isblank($X$13),"Enter GM%",if(isblank($X$14),"Enter Lifespan",if(ISBLANK(AA43),"Enter AOV",$X$13*$X$14*AA43)))),if(isblank(AA36),"--",$X$17)) -> 13650 | AC46: =if($X$16="Yes",if(isblank(AC36),"--",if(isblank($X$13),"Enter GM%",if(isblank($X$14),"Enter Lifespan",if(ISBLANK(AC43),"Enter AOV",$X$13*$X$14*AC43)))),if(isblank(AC36),"--",$X$17)) -> Enter AOV | AE46: =if($X$16="Yes",if(isblank(AE36),"--",if(isblank($X$13),"Enter GM%",if(isblank($X$14),"Enter Lifespan",if(ISBLANK(AE43),"Enter AOV",$X$13*$X$14*AE43)))),if(isblank(AE36),"--",$X$17)) -> Enter AOV | AG46: =if($X$16="Yes",if(isblank(AG36),"--",if(isblank($X$13),"Enter GM%",if(isblank($X$14),"Enter Lifespan",if(ISBLANK(AG43),"Enter AOV",$X$13*$X$14*AG43)))),if(isblank(AG36),"--",$X$17)) -> Enter AOV | AI46: =if($X$16="Yes",if(isblank(AI36),"--",if(isblank($X$13),"Enter GM%",if(isblank($X$14),"Enter Lifespan",if(ISBLANK(AI43),"Enter AOV",$X$13*$X$14*AI43)))),if(isblank(AI36),"--",$X$17)) -> Enter AOV | AK46: =if($X$16="Yes",if(isblank(AK36),"--",if(isblank($X$13),"Enter GM%",if(isblank($X$14),"Enter Lifespan",if(ISBLANK(AK43),"Enter AOV",$X$13*$X$14*AK43)))),if(isblank(AK36),"--",$X$17)) -> Enter AOV | AM46: =if($X$16="Yes",if(isblank(AM36),"--",if(isblank($X$13),"Enter GM%",if(isblank($X$14),"Enter Lifespan",if(ISBLANK(AM43),"Enter AOV",$X$13*$X$14*AM43)))),if(isblank(AM36),"--",$X$17)) -> 42025 | AO46: =if($X$16="Yes",if(isblank(AO36),"--",if(isblank($X$13),"Enter GM%",if(isblank($X$14),"Enter Lifespan",if(ISBLANK(AO43),"Enter AOV",$X$13*$X$14*AO43)))),if(isblank(AO36),"--",$X$17)) -> Enter AOV | AQ46: =if($X$16="Yes",if(isblank(AQ36),"--",if(isblank($X$13),"Enter GM%",if(isblank($X$14),"Enter Lifespan",if(ISBLANK(AQ43),"Enter AOV",$X$13*$X$14*AQ43)))),if(isblank(AQ36),"--",$X$17)) -> Enter AOV | AS46: =if($X$16="Yes",if(isblank(AS36),"--",if(isblank($X$13),"Enter GM%",if(isblank($X$14),"Enter Lifespan",if(ISBLANK(AS43),"Enter AOV",$X$13*$X$14*AS43)))),if(isblank(AS36),"--",$X$17)) -> 65500 | AU46: =if($X$16="Yes",if(isblank(AU36),"--",if(isblank($X$13),"Enter GM%",if(isblank($X$14),"Enter Lifespan",if(ISBLANK(AU43),"Enter AOV",$X$13*$X$14*AU43)))),if(isblank(AU36),"--",$X$17)) -> Enter AOV | AW46: =if($X$16="Yes",if(isblank(AW36),"--",if(isblank($X$13),"Enter GM%",if(isblank($X$14),"Enter Lifespan",if(ISBLANK(AW43),"Enter AOV",$X$13*$X$14*AW43)))),if(isblank(AW36),"--",$X$17)) -> Enter AOV | AY46: =if($X$16="Yes",if(isblank(AY36),"--",if(isblank($X$13),"Enter GM%",if(isblank($X$14),"Enter Lifespan",if(ISBLANK(AY43),"Enter AOV",$X$13*$X$14*AY43)))),if(isblank(AY36),"--",$X$17)) -> Enter AOV | BA46: =if($X$16="Yes",if(isblank(BA36),"--",if(isblank($X$13),"Enter GM%",if(isblank($X$14),"Enter Lifespan",if(ISBLANK(BA43),"Enter AOV",$X$13*$X$14*BA43)))),if(isblank(BA36),"--",$X$17)) -> Enter AOV | BC46: =if($X$16="Yes",if(isblank(BC36),"--",if(isblank($X$13),"Enter GM%",if(isblank($X$14),"Enter Lifespan",if(ISBLANK(BC43),"Enter AOV",$X$13*$X$14*BC43)))),if(isblank(BC36),"--",$X$17)) -> Enter AOV | BE46: =if($X$16="Yes",if(isblank(BE36),"--",if(isblank($X$13),"Enter GM%",if(isblank($X$14),"Enter Lifespan",if(ISBLANK(BE43),"Enter AOV",$X$13*$X$14*BE43)))),if(isblank(BE36),"--",$X$17)) -> Enter AOV | BG46: =if($X$16="Yes",if(isblank(BG36),"--",if(isblank($X$13),"Enter GM%",if(isblank($X$14),"Enter Lifespan",if(ISBLANK(BG43),"Enter AOV",$X$13*$X$14*BG43)))),if(isblank(BG36),"--",$X$17)) -> Enter AOV | BI46: =if($X$16="Yes",if(isblank(BI36),"--",if(isblank($X$13),"Enter GM%",if(isblank($X$14),"Enter Lifespan",if(ISBLANK(BI43),"Enter AOV",$X$13*$X$14*BI43)))),if(isblank(BI36),"--",$X$17)) -> Enter AOV | BK46: =if($X$16="Yes",if(isblank(BK36),"--",if(isblank($X$13),"Enter GM%",if(isblank($X$14),"Enter Lifespan",if(ISBLANK(BK43),"Enter AOV",$X$13*$X$14*BK43)))),if(isblank(BK36),"--",$X$17)) -> Enter AOV | BM46: =if($X$16="Yes",if(isblank(BM36),"--",if(isblank($X$13),"Enter GM%",if(isblank($X$14),"Enter Lifespan",if(ISBLANK(BM43),"Enter AOV",$X$13*$X$14*BM43)))),if(isblank(BM36),"--",$X$17)) -> Enter AOV | BO46: =if($X$16="Yes",if(isblank(BO36),"--",if(isblank($X$13),"Enter GM%",if(isblank($X$14),"Enter Lifespan",if(ISBLANK(BO43),"Enter AOV",$X$13*$X$14*BO43)))),if(isblank(BO36),"--",$X$17)) -> 65748.462
B47: Total Est. Bookings | E47: =if(E36="--","--",sum(G47:BS47)) -> 1317030 | G47: =if(isblank(G36),"--",if(or(isblank(G42),G42=0),"No Customers",if(isnumber(G46),G46*G42,"No LTV"))) -> No Customers | I47: =if(isblank(I36),"--",if(or(isblank(I42),I42=0),"No Customers",if(isnumber(I46),I46*I42,"No LTV"))) -> No Customers | K47: =if(isblank(K36),"--",if(or(isblank(K42),K42=0),"No Customers",if(isnumber(K46),K46*K42,"No LTV"))) -> No Customers | M47: =if(isblank(M36),"--",if(or(isblank(M42),M42=0),"No Customers",if(isnumber(M46),M46*M42,"No LTV"))) -> No Customers | O47: =if(isblank(O36),"--",if(or(isblank(O42),O42=0),"No Customers",if(isnumber(O46),O46*O42,"No LTV"))) -> No Customers | Q47: =if(isblank(Q36),"--",if(or(isblank(Q42),Q42=0),"No Customers",if(isnumber(Q46),Q46*Q42,"No LTV"))) -> No Customers | S47: =if(isblank(S36),"--",if(or(isblank(S42),S42=0),"No Customers",if(isnumber(S46),S46*S42,"No LTV"))) -> No Customers | U47: =if(isblank(U36),"--",if(or(isblank(U42),U42=0),"No Customers",if(isnumber(U46),U46*U42,"No LTV"))) -> No Customers | W47: =if(isblank(W36),"--",if(or(isblank(W42),W42=0),"No Customers",if(isnumber(W46),W46*W42,"No LTV"))) -> No Customers | Y47: =if(isblank(Y36),"--",if(or(isblank(Y42),Y42=0),"No Customers",if(isnumber(Y46),Y46*Y42,"No LTV"))) -> No Customers | AA47: =if(isblank(AA36),"--",if(or(isblank(AA42),AA42=0),"No Customers",if(isnumber(AA46),AA46*AA42,"No LTV"))) -> 13650 | AC47: =if(isblank(AC36),"--",if(or(isblank(AC42),AC42=0),"No Customers",if(isnumber(AC46),AC46*AC42,"No LTV"))) -> No Customers | AE47: =if(isblank(AE36),"--",if(or(isblank(AE42),AE42=0),"No Customers",if(isnumber(AE46),AE46*AE42,"No LTV"))) -> No Customers | AG47: =if(isblank(AG36),"--",if(or(isblank(AG42),AG42=0),"No Customers",if(isnumber(AG46),AG46*AG42,"No LTV"))) -> No Customers | AI47: =if(isblank(AI36),"--",if(or(isblank(AI42),AI42=0),"No Customers",if(isnumber(AI46),AI46*AI42,"No LTV"))) -> No Customers | AK47: =if(isblank(AK36),"--",if(or(isblank(AK42),AK42=0),"No Customers",if(isnumber(AK46),AK46*AK42,"No LTV"))) -> No Customers | AM47: =if(isblank(AM36),"--",if(or(isblank(AM42),AM42=0),"No Customers",if(isnumber(AM46),AM46*AM42,"No LTV"))) -> 252150 | AO47: =if(isblank(AO36),"--",if(or(isblank(AO42),AO42=0),"No Customers",if(isnumber(AO46),AO46*AO42,"No LTV"))) -> No Customers | AQ47: =if(isblank(AQ36),"--",if(or(isblank(AQ42),AQ42=0),"No Customers",if(isnumber(AQ46),AQ46*AQ42,"No LTV"))) -> No Customers | AS47: =if(isblank(AS36),"--",if(or(isblank(AS42),AS42=0),"No Customers",if(isnumber(AS46),AS46*AS42,"No LTV"))) -> 196500 | AU47: =if(isblank(AU36),"--",if(or(isblank(AU42),AU42=0),"No Customers",if(isnumber(AU46),AU46*AU42,"No LTV"))) -> No Customers | AW47: =if(isblank(AW36),"--",if(or(isblank(AW42),AW42=0),"No Customers",if(isnumber(AW46),AW46*AW42,"No LTV"))) -> No Customers | AY47: =if(isblank(AY36),"--",if(or(isblank(AY42),AY42=0),"No Customers",if(isnumber(AY46),AY46*AY42,"No LTV"))) -> No Customers | BA47: =if(isblank(BA36),"--",if(or(isblank(BA42),BA42=0),"No Customers",if(isnumber(BA46),BA46*BA42,"No LTV"))) -> No Customers | BC47: =if(isblank(BC36),"--",if(or(isblank(BC42),BC42=0),"No Customers",if(isnumber(BC46),BC46*BC42,"No LTV"))) -> No Customers | BE47: =if(isblank(BE36),"--",if(or(isblank(BE42),BE42=0),"No Customers",if(isnumber(BE46),BE46*BE42,"No LTV"))) -> No Customers | BG47: =if(isblank(BG36),"--",if(or(isblank(BG42),BG42=0),"No Customers",if(isnumber(BG46),BG46*BG42,"No LTV"))) -> No Customers | BI47: =if(isblank(BI36),"--",if(or(isblank(BI42),BI42=0),"No Customers",if(isnumber(BI46),BI46*BI42,"No LTV"))) -> No Customers | BK47: =if(isblank(BK36),"--",if(or(isblank(BK42),BK42=0),"No Customers",if(isnumber(BK46),BK46*BK42,"No LTV"))) -> No Customers | BM47: =if(isblank(BM36),"--",if(or(isblank(BM42),BM42=0),"No Customers",if(isnumber(BM46),BM46*BM42,"No LTV"))) -> No Customers | BO47: =if(isblank(BO36),"--",if(or(isblank(BO42),BO42=0),"No Customers",if(isnumber(BO46),BO46*BO42,"No LTV"))) -> 854730
B48: Net Return | E48: =if(E36="--","--",sum(G48:BS48)) -> 1012798.2 | G48: =if(isblank(G36),"--",if(istext(G47),G47,G47-G36)) -> No Customers | I48: =if(isblank(I36),"--",if(istext(I47),I47,I47-I36)) -> No Customers | K48: =if(isblank(K36),"--",if(istext(K47),K47,K47-K36)) -> No Customers | M48: =if(isblank(M36),"--",if(istext(M47),M47,M47-M36)) -> No Customers | O48: =if(isblank(O36),"--",if(istext(O47),O47,O47-O36)) -> No Customers | Q48: =if(isblank(Q36),"--",if(istext(Q47),Q47,Q47-Q36)) -> No Customers | S48: =if(isblank(S36),"--",if(istext(S47),S47,S47-S36)) -> No Customers | U48: =if(isblank(U36),"--",if(istext(U47),U47,U47-U36)) -> No Customers | W48: =if(isblank(W36),"--",if(istext(W47),W47,W47-W36)) -> No Customers | Y48: =if(isblank(Y36),"--",if(istext(Y47),Y47,Y47-Y36)) -> No Customers | AA48: =if(isblank(AA36),"--",if(istext(AA47),AA47,AA47-AA36)) -> -2870.2446 | AC48: =if(isblank(AC36),"--",if(istext(AC47),AC47,AC47-AC36)) -> No Customers | AE48: =if(isblank(AE36),"--",if(istext(AE47),AE47,AE47-AE36)) -> No Customers | AG48: =if(isblank(AG36),"--",if(istext(AG47),AG47,AG47-AG36)) -> No Customers | AI48: =if(isblank(AI36),"--",if(istext(AI47),AI47,AI47-AI36)) -> No Customers | AK48: =if(isblank(AK36),"--",if(istext(AK47),AK47,AK47-AK36)) -> No Customers | AM48: =if(isblank(AM36),"--",if(istext(AM47),AM47,AM47-AM36)) -> 62304.027 | AO48: =if(isblank(AO36),"--",if(istext(AO47),AO47,AO47-AO36)) -> No Customers | AQ48: =if(isblank(AQ36),"--",if(istext(AQ47),AQ47,AQ47-AQ36)) -> No Customers | AS48: =if(isblank(AS36),"--",if(istext(AS47),AS47,AS47-AS36)) -> 124793.38 | AU48: =if(isblank(AU36),"--",if(istext(AU47),AU47,AU47-AU36)) -> No Customers | AW48: =if(isblank(AW36),"--",if(istext(AW47),AW47,AW47-AW36)) -> No Customers | AY48: =if(isblank(AY36),"--",if(istext(AY47),AY47,AY47-AY36)) -> No Customers | BA48: =if(isblank(BA36),"--",if(istext(BA47),BA47,BA47-BA36)) -> No Customers | BC48: =if(isblank(BC36),"--",if(istext(BC47),BC47,BC47-BC36)) -> No Customers | BE48: =if(isblank(BE36),"--",if(istext(BE47),BE47,BE47-BE36)) -> No Customers | BG48: =if(isblank(BG36),"--",if(istext(BG47),BG47,BG47-BG36)) -> No Customers | BI48: =if(isblank(BI36),"--",if(istext(BI47),BI47,BI47-BI36)) -> No Customers | BK48: =if(isblank(BK36),"--",if(istext(BK47),BK47,BK47-BK36)) -> No Customers | BM48: =if(isblank(BM36),"--",if(istext(BM47),BM47,BM47-BM36)) -> No Customers | BO48: =if(isblank(BO36),"--",if(istext(BO47),BO47,BO47-BO36)) -> 828571.01
B49: =if(ISBLANK(B37),"--","Cost-per-"&LEFT(B37,LEN(B37)-1)) -> Cost-per-Form Fill | E49: =iferror($E$36/E37,"--") -> 1380.5058 | G49: =iferror(G$36/G37,"--") -> 464.34447 | I49: =iferror(I$36/I37,"--") -> 2109.2938 | K49: =iferror(K$36/K37,"--") -> 9178.2575 | M49: =iferror(M$36/M37,"--") -> 6444.8495 | O49: =iferror(O$36/O37,"--") -> -- | Q49: =iferror(Q$36/Q37,"--") -> 2158.3951 | S49: =iferror(S$36/S37,"--") -> 7259.775 | U49: =iferror(U$36/U37,"--") -> 6924.6823 | W49: =iferror(W$36/W37,"--") -> 2148.0141 | Y49: =iferror(Y$36/Y37,"--") -> -- | AA49: =iferror(AA$36/AA37,"--") -> 1835.5827 | AC49: =iferror(AC$36/AC37,"--") -> -- | AE49: =iferror(AE$36/AE37,"--") -> -- | AG49: =iferror(AG$36/AG37,"--") -> -- | AI49: =iferror(AI$36/AI37,"--") -> 4943.1546 | AK49: =iferror(AK$36/AK37,"--") -> -- | AM49: =iferror(AM$36/AM37,"--") -> 1157.5974 | AO49: =iferror(AO$36/AO37,"--") -> 563.32926 | AQ49: =iferror(AQ$36/AQ37,"--") -> 1048.7614 | AS49: =iferror(AS$36/AS37,"--") -> 1748.9421 | AU49: =iferror(AU$36/AU37,"--") -> -- | AW49: =iferror(AW$36/AW37,"--") -> 707.08033 | AY49: =iferror(AY$36/AY37,"--") -> -- | BA49: =iferror(BA$36/BA37,"--") -> 12742.315 | BC49: =iferror(BC$36/BC37,"--") -> 1178.3963 | BE49: =iferror(BE$36/BE37,"--") -> -- | BG49: =iferror(BG$36/BG37,"--") -> -- | BI49: =iferror(BI$36/BI37,"--") -> -- | BK49: =iferror(BK$36/BK37,"--") -> -- | BM49: =iferror(BM$36/BM37,"--") -> 0 | BO49: =iferror(BO$36/BO37,"--") -> 207.61103
...

Sheet Removing spend from underperfor
B2: GET STARTED | BF2: NOTE
B3: Enter the values needed for calculating LTV in cells T14:T17, then customize your channels and funnel stages in the 'Current Quarter Actuals' table below. | BF3: Only edit highlighted cells.
BF4: Try not to alter cells that contain a formula.
B5: As you enter data in the 'Current Quarter Actuals' tab, this sheet will automatically update to show a summary of the quarter.
B10: Current Quarter Summary
T12: Lifetime Value (LTV)
T13: Gross Margin (%) | X13: 0.6
D14: =IFERROR(__xludf.DUMMYFUNCTION("iferror(SPARKLINE(C22,{""charttype"",""column"";""ymin"", 0; ""ymax"",MAX(C22:H22);""firstcolor"",""#304458""}),"""")"),"") | F14: =IFERROR(__xludf.DUMMYFUNCTION("iferror(SPARKLINE(F22,{""charttype"",""column"";""ymin"", 0; ""ymax"",MAX(C22:H22);""firstcolor"",""#f46524""}),"""")"),"") | T14: Lifespan of Customer (months) | X14: 12
T15: Monthly Avg. Order Value | X15: 15293 | Z15: =X15*12 -> 183516
T16: Channel-level AOV's? | X16: No
T17: Lifetime Value (LTV) | X17: =if(X16="No",if(isblank(X13),"Enter GM%",if(isblank(X14),"Enter Lifespan",if(ISBLANK(X15),"Enter AOV",X13*X14*X15))),"See Below") -> 110109.6
M20: =F62 -> Form Fills | N20: =H62 -> 815 | S20: =IFERROR(__xludf.DUMMYFUNCTION("iferror(SPARKLINE(G62:H62,{""charttype"",""bar"";""max"",MAX($H$62:$H$67);""color1"",""#ebedef"";""color2"",""#073763""}),"""")"),"")
C21: Total Spend | F21: Total Est. Bookings | M21: =F63 -> Intro Held | N21: =H63 -> 430 | S21: =IFERROR(__xludf.DUMMYFUNCTION("iferror(SPARKLINE(G63:H63,{""charttype"",""bar"";""max"",MAX($H$62:$H$67);""color1"",""#ebedef"";""color2"",""#0b5394""}),"""")"),"") | W21: =iferror(if(J62="","","🔽 "&(ROUND(J62,2)*100)&"%"),"--") -> 🔽 53% | X21: =if(I62="","",I62) -> Form Fill > Intro Held
C22: =E35 -> 234963.85 | F22: =E44 -> 2532520.8 | M22: =F64 -> Strat Call Held | N22: =H64 -> 173 | S22: =IFERROR(__xludf.DUMMYFUNCTION("iferror(SPARKLINE(G64:H64,{""charttype"",""bar"";""max"",MAX(H62:H67);""color1"",""#ebedef"";""color2"",""#3d85c6""}),"""")"),"") | W22: =iferror(if(J63="","","🔽 "&(ROUND(J63,2)*100)&"%"),"--") -> 🔽 40% | X22: =if(I63="","",I63) -> Intro Held > Strat Call Held
M23: =F65 -> Proposals | N23: =H65 -> 122 | S23: =IFERROR(__xludf.DUMMYFUNCTION("iferror(SPARKLINE(G65:H65,{""charttype"",""bar"";""max"",MAX($H$62:$H$67);""color1"",""#ebedef"";""color2"",""#6fa8dc""}),"""")"),"") | W23: =iferror(if(J64="","","🔽 "&(ROUND(J64,2)*100)&"%"),"--") -> 🔽 71% | X23: =if(I64="","",I64) -> Strat Call Held > Proposal | AD23: 44805
M24: =F66 -> Customers | N24: =H66 -> 23 | S24: =IFERROR(__xludf.DUMMYFUNCTION("iferror(SPARKLINE(G66:H66,{""charttype"",""bar"";""max"",MAX($H$62:$H$67);""color1"",""#ebedef"";""color2"",""#9fc5e8""}),"""")"),"") | W24: =iferror(if(J65="","","🔽 "&(ROUND(J65,2)*100)&"%"),"--") -> 🔽 19% | X24: =if(I65="","",I65) -> Proposal > Customer | AD24: 44876
C25: LTV:CAC Ratio | F25: =E31 -> 10.78 | M25: =F67 | N25: =H67 | S25: {=iferror(SPARKLINE(G67:H67,{"charttype","bar";"max",MAX($H$62:$H$67);"color1","#ebedef";"color2","#cfe2f3"}),"")} | W25: =iferror(if(J66="","","🔽 "&(ROUND(J66,2)*100)&"%"),"--") | X25: =if(I66="","",I66) | AD25: =days(AD24,AD23) -> 71
C26: Net Return | F26: =E45 -> 2369381.2 | AD26: 44926
AD27: =days(AD26,AD23) -> 121
B28: Current Quarter Actuals
I29: 25000 | AM29: 35000 | AO29: 5000 | AQ29: 30000 | AS29: 60000 | AW29: 40000
E30: Total | G30: Google - Brand | I30: Google - Non-Brand: Demand Gen | K30: Google - Non-Brand: Marketing | M30: Google - Non-Brand: MOPs | O30: Google - Non-Brand: Paid Media | Q30: Google - Non-Brand: Social | S30: Google - Non-Brand: Creative | U30: Google - Non-Brand: Performance Marketing | W30: Google - Non-Brand: SEO | Y30: Google - Non-Brand: Strategy | AA30: Google - Non-Brand: Video | AC30: Google - YouTube | AE30: Google - Display | AG30: Google - Non-Brand: Events Support | AI30: Google - Non-Brand: RLSA | AK30: LinkedIn - Brand Ads | AM30: LinkedIn - Convo Ads GC | AO30: LinkedIn - Line Specific GC | AQ30: LinkedIn - Strategy GC | AS30: LinkedIn - SPC GC | AU30: Facebook/IG - Brand Ads | AW30: Facebook - SPC GC | AY30: Instagram - SPC GC | BA30: StackAdapt | BC30: Clutch.io | BE30: Manifest | BG30: Twitter - Brand | BI30: Organic | BK30: Non-Paid Media
B31: LTV:CAC Ratio | E31: =if(E35="--","--",if(istext(E43),"No LTV",if(or(isblank(E41),E41=0),0,Round(E43/E51,2)))) -> 10.78 | G31: =if(isblank(G35),"--",if(istext(G43),"No LTV",if(or(isblank(G41),G41=0),0,Round(G43/G51,2)))) -> 0 | I31: =if(isblank(I35),"--",if(istext(I43),"No LTV",if(or(isblank(I41),I41=0),0,Round(I43/I51,2)))) -> 0 | K31: =if(isblank(K35),"--",if(istext(K43),"No LTV",if(or(isblank(K41),K41=0),0,Round(K43/K51,2)))) -> 0 | M31: =if(isblank(M35),"--",if(istext(M43),"No LTV",if(or(isblank(M41),M41=0),0,Round(M43/M51,2)))) -> 0 | O31: =if(isblank(O35),"--",if(istext(O43),"No LTV",if(or(isblank(O41),O41=0),0,Round(O43/O51,2)))) -> 0 | Q31: =if(isblank(Q35),"--",if(istext(Q43),"No LTV",if(or(isblank(Q41),Q41=0),0,Round(Q43/Q51,2)))) -> 0 | S31: =if(isblank(S35),"--",if(istext(S43),"No LTV",if(or(isblank(S41),S41=0),0,Round(S43/S51,2)))) -> 0 | U31: =if(isblank(U35),"--",if(istext(U43),"No LTV",if(or(isblank(U41),U41=0),0,Round(U43/U51,2)))) -> 0 | W31: =if(isblank(W35),"--",if(istext(W43),"No LTV",if(or(isblank(W41),W41=0),0,Round(W43/W51,2)))) -> 0 | Y31: =if(isblank(Y35),"--",if(istext(Y43),"No LTV",if(or(isblank(Y41),Y41=0),0,Round(Y43/Y51,2)))) -> 0 | AA31: =if(isblank(AA35),"--",if(istext(AA43),"No LTV",if(or(isblank(AA41),AA41=0),0,Round(AA43/AA51,2)))) -> 15.12 | AC31: =if(isblank(AC35),"--",if(istext(AC43),"No LTV",if(or(isblank(AC41),AC41=0),0,Round(AC43/AC51,2)))) -> 0 | AE31: =if(isblank(AE35),"--",if(istext(AE43),"No LTV",if(or(isblank(AE41),AE41=0),0,Round(AE43/AE51,2)))) -> 0 | AG31: =if(isblank(AG35),"--",if(istext(AG43),"No LTV",if(or(isblank(AG41),AG41=0),0,Round(AG43/AG51,2)))) -> 0 | AI31: =if(isblank(AI35),"--",if(istext(AI43),"No LTV",if(or(isblank(AI41),AI41=0),0,Round(AI43/AI51,2)))) -> 0 | AK31: =if(isblank(AK35),"--",if(istext(AK43),"No LTV",if(or(isblank(AK41),AK41=0),0,Round(AK43/AK51,2)))) -> 0 | AM31: =if(isblank(AM35),"--",if(istext(AM43),"No LTV",if(or(isblank(AM41),AM41=0),0,Round(AM43/AM51,2)))) -> 7.08 | AO31: =if(isblank(AO35),"--",if(istext(AO43),"No LTV",if(or(isblank(AO41),AO41=0),0,Round(AO43/AO51,2)))) -> 0 | AQ31: =if(isblank(AQ35),"--",if(istext(AQ43),"No LTV",if(or(isblank(AQ41),AQ41=0),0,Round(AQ43/AQ51,2)))) -> 0 | AS31: =if(isblank(AS35),"--",if(istext(AS43),"No LTV",if(or(isblank(AS41),AS41=0),0,Round(AS43/AS51,2)))) -> 9.73 | AU31: =if(isblank(AU35),"--",if(istext(AU43),"No LTV",if(or(isblank(AU41),AU41=0),0,Round(AU43/AU51,2)))) -> 0 | AW31: =if(isblank(AW35),"--",if(istext(AW43),"No LTV",if(or(isblank(AW41),AW41=0),0,Round(AW43/AW51,2)))) -> 0 | BA31: =if(isblank(BA35),"--",if(istext(BA43),"No LTV",if(or(isblank(BA41),BA41=0),0,Round(BA43/BA51,2)))) -> 0 | BC31: =if(isblank(BC35),"--",if(istext(BC43),"No LTV",if(or(isblank(BC41),BC41=0),0,Round(BC43/BC51,2)))) -> 0 | BE31: =if(isblank(BE35),"--",if(istext(BE43),"No LTV",if(or(isblank(BE41),BE41=0),0,Round(BE43/BE51,2)))) -> 0 | BG31: =if(isblank(BG35),"--",if(istext(BG43),"No LTV",if(or(isblank(BG41),BG41=0),0,Round(BG43/BG51,2)))) -> 0 | BK31: =if(isblank(BK35),"--",if(istext(BK43),"No LTV",if(or(isblank(BK41),BK41=0),0,Round(BK43/BK51,2)))) -> 50.02
B32: Total Ad Spend | E32: =if(sum(G32:BL32)=0,"--",sum(G32:BL32)) -> 373616.6 | G32: 2155.39 | I32: 790.57 | K32: 11873.54 | M32: 10561.68 | O32: 190.35 | Q32: 2938.97 | S32: 9149.52 | U32: 19840.22 | W32: 8230.18 | Y32: 13142.76 | AA32: 7280.6 | AC32: 3545.79 | AE32: 0 | AG32: 795.72 | AI32: 2262.57 | AK32: 14064.04 | AM32: 76709.27 | AO32: 12423.41 | AQ32: 49727.22 | AS32: 33934.74 | AU32: 14028.09 | AW32: 34249.84 | AY32: 19218.96 | BA32: 16001.67 | BC32: =2650+2650 -> 5300 | BE32: =650+650 -> 1300 | BG32: 3901.5 | BI32: 0 | BK32: 0
B33: Resource Cost | E33: =if(sum(G33:BL33)=0,"--",sum(G33:BL33)) -> --
B34: Incentive Cost | E34: =if(sum(G34:BL34)=0,"--",sum(G34:BL34)) -> 47975 | AM34: 16600 | AW34: 2760 | BK34: 28615
B35: Total Spend | E35: =if(sum(G35:BL35)=0,"--",sum(G35:BL35)) -> 234963.85 | G35: =sum(G32:H34) -> 2155.39 | I35: =sum(I32:J34) -> 790.57 | K35: 0 | M35: 0 | O35: =sum(O32:P34) -> 190.35 | Q35: 0 | S35: 0 | U35: 0 | W35: 0 | Y35: 0 | AA35: =sum(AA32:AB34) -> 7280.6 | AC35: 0 | AE35: =sum(AE32:AF34) -> 0 | AG35: =sum(AG32:AH34) -> 795.72 | AI35: 0 | AK35: 0 | AM35: =sum(AM32:AN34) -> 93309.27 | AO35: =sum(AO32:AP34) -> 12423.41 | AQ35: 2000 | AS35: =sum(AS32:AT34) -> 33934.74 | AU35: 0 | AW35: 34249.84 | AY35: 19218.96 | BA35: 0 | BC35: 0 | BE35: 0 | BG35: 0 | BI35: =sum(BI32:BJ34) -> 0 | BK35: =sum(BK32:BL34) -> 28615
B36: Form Fills | E36: =if(isblank(B36),,if($E$35="--","--",sum(G36:BL36))) -> 815 | G36: 9 | I36: 1 | K36: 7 | M36: 4 | O36: 0 | Q36: 3 | S36: 5 | U36: 9 | W36: 9 | Y36: 2 | AA36: 12 | AC36: 0 | AE36: 0 | AG36: 0 | AI36: 1 | AK36: 0 | AM36: 197 | AO36: 58 | AQ36: 124 | AS36: 61 | AU36: 0 | AW36: 93 | BA36: 12 | BC36: 12 | BE36: 1 | BG36: 0 | BI36: 54 | BK36: 141
B37: Intro Held | E37: =if(isblank(B37),,if($E$35="--","--",sum(G37:BL37))) -> 430 | G37: 6 | I37: 0 | K37: 4 | M37: 0 | O37: 0 | Q37: 0 | S37: 2 | U37: 5 | W37: 8 | Y37: 1 | AA37: 6 | AC37: 0 | AE37: 0 | AG37: 0 | AI37: 0 | AK37: 0 | AM37: 97 | AO37: 19 | AQ37: 82 | AS37: 17 | AU37: 0 | AW37: 52 | BA37: 4 | BC37: 4 | BE37: 1 | BG37: 0 | BI37: 26 | BK37: 96
B38: Strat Call Held | E38: =if(isblank(B38),,if($E$35="--","--",sum(G38:BL38))) -> 173 | G38: 1 | I38: 0 | K38: 0 | M38: 0 | O38: 0 | Q38: 0 | S38: 0 | U38: 3 | W38: 0 | Y38: 0 | AA38: 1 | AC38: 0 | AE38: 0 | AG38: 0 | AI38: 0 | AK38: 0 | AM38: 29 | AO38: 8 | AQ38: 18 | AS38: 12 | AU38: 0 | AW38: 14 | BA38: 1 | BC38: 1 | BE38: 1 | BG38: 0 | BI38: 15 | BK38: 69
B39: Proposals | E39: =if(isblank(B39),,if($E$35="--","--",sum(G39:BL39))) -> 122 | G39: 3 | I39: 0 | K39: 0 | M39: 0 | O39: 0 | Q39: 0 | S39: 0 | U39: 1 | W39: 0 | Y39: 0 | AA39: 2 | AC39: 0 | AE39: 0 | AG39: 0 | AI39: 0 | AK39: 0 | AM39: 11 | AO39: 4 | AQ39: 13 | AS39: 7 | AU39: 0 | AW39: 9 | BA39: 1 | BC39: 1 | BE39: 0 | BG39: 0 | BI39: 1 | BK39: 69
E40: =if(isblank(B40),,if($E$35="--","--",sum(G40:BL40)))
B41: Customers | E41: =if(isblank(B41),,if($E$35="--","--",sum(G41:BL41))) -> 23 | G41: 0 | I41: 0 | K41: 0 | M41: 0 | O41: 0 | Q41: 0 | S41: 0 | U41: 0 | W41: 0 | Y41: 0 | AA41: 1 | AC41: 0 | AE41: 0 | AG41: 0 | AI41: 0 | AK41: 0 | AM41: 6 | AO41: 0 | AQ41: 0 | AS41: 3 | AU41: 0 | AW41: 0 | BA41: 0 | BC41: 0 | BE41: 0 | BG41: 0 | BI41: 0 | BK41: 13
B42: Average Order Value | E42: =if(X16="Yes",iferror(average(G42:BL42),""),X15) -> 15293
